Workbook

Sheet README
A1: EXOTIC & COLLECTOR AUTOMOBILE MGA — UNDERWRITING BORDEREAUX
A2: Monthly delegated authority underwriting reporting to the Lloyd's syndicate panel. Distinct from the claims bordereaux — this reports bound policies, not claims.
B4: SHEETS IN THIS WORKBOOK
B6: Header | C6: Contract identification, reporting period, binding and discount authority limits, syndicate participation table, and a live submission control summary linking to the bordereaux data.
B7: UW Bordereaux | C7: The data sheet. One row per policy per reporting period. 56 columns, 200 pre-formatted rows. Blue columns are for entry; grey columns calculate. Report every risk — new business, renewals, endorsements, cancellations.
B8: Reconciliation | C8: Premium reconciliation (GWP minus commission equals net to capacity; total due reconciles through fees and tax) plus twelve automated submission control checks. Run before every submission.
B9: Field Definitions | C9: Every column explained with its population rule and source.
B10: Lists | C10: Source of every drop-down. Amend here to change available options.
B12: HOW THIS BORDEREAUX DIFFERS FROM THE CLAIMS BORDEREAUX
B14: - The underwriting bordereaux reports POLICIES BOUND. The claims bordereaux reports CLAIMS NOTIFIED. Both go to the same syndicate panel under the same binding authority, but they are separate documents with separate submission schedules.
B15: - The underwriting bordereaux is typically submitted monthly (or quarterly for lower-volume binders) and covers every risk bound, renewed, endorsed or cancelled in the period. It is the primary document the syndicates use to monitor premium volume, rate adequacy and class mix.
B16: - Rate adequacy is the metric the lead syndicate watches most closely on a delegated motor book. The rate adequacy column and the Header summary are the underwriting bdx's equivalent of the loss ratio on the claims bdx — they tell the syndicate whether the coverholder is generating business at an adequate price.
B17: - This bordereaux does not feed the claims bdx automatically — the two documents are matched by certificate number and insured name at the syndicate level during the bureau reconciliation process.
B19: HOW TO USE
B21: - Complete the Header sheet before the first submission: UMR, coverholder name, PIN, reporting period, authority limits. These cells carry through to every calculation in the bordereaux data sheet.
B22: - Enter one row per policy. For endorsements and renewals, carry the original certificate number and set the movement type accordingly — do not create a new certificate number.
B23: - The technical premium column (AB) must be entered manually or copied from the Portfolio Register. It represents the rate-adequate price the rater produced before any UW judgement adjustment. If it is left blank, the GWP, rate adequacy and all downstream commission calculations will be blank too.
B24: - Surplus lines tax rate (column AF) must be entered for every bound risk. The formula calculates the dollar amount, but the rate itself is your responsibility — verify it with the stamping office or your filing service before the bordereaux is sent.
B25: - Run the Reconciliation sheet before every submission. Any FAIL must be resolved. A WARN on rate adequacy should be noted and explained to the lead syndicate; it does not block submission but will be questioned.
B26: - Six specimen risks are pre-loaded to show the intended level of detail. Delete them before issuing to the syndicates.
B28: IMPORTANT — This template follows the general structure and field set of Lloyd's coverholder underwriting reporting, but it is NOT a certified Lloyd's Coverholder Reporting Standards file. Before your first submission, obtain the exact required template, mandatory field list and column order from your Lloyd's broker or the lead syndicate's delegated authority team. Requirements differ by syndicate, by class and by year of account, and they change annually. The LCRS v5.2 schema (and its successors) governs the accepted electronic format.

Sheet Header
A1: UNDERWRITING BORDEREAUX — HEADER AND SUBMISSION DETAILS
A2: Complete before every submission. These fields identify the contract and reporting period.
B3: Commission stack: 25% total = 12.5% broker + 12.5% Torque Underwriters (MGA). Net to capacity 75%. | H3: Total ceding | I3: 0.25 | J3: Broker | K3: 0.125 | L3: Torque (MGA) | M3: 0.125 | N3: PC hurdle | O3: 0.6 | P3: PC share | Q3: 0.15 | R3: =IF(ROUND($K$3+$M$3-$I$3,6)=0,"Splits foot — OK","ERROR: broker + Torque <> total") -> Splits foot — OK
B4: SECTION A — CONTRACT IDENTIFICATION
B5: Unique Market Reference (UMR) | C5: B0999TQ260149 | G5: Must match exactly on every submission and on every certificate issued under the binder.
B6: Binding authority reference | C6: BA-EXO-2026-01
B7: Coverholder name | C7: Torque Underwriters LLC
B8: Lloyd's coverholder PIN | C8: TQ-COV-0000 | G8: Issued on coverholder approval. Required on every submission.
B9: Risk code | C9: MT | G9: Lloyd's risk code. MT = Motor. Confirm with your Lloyd's broker.
B10: Year of account | C10: 2025
B11: Class of business | C11: Exotic, supercar and collector automobile
B12: Reporting period start | C12: 45931
B13: Reporting period end | C13: 45961
B14: Submission date | C14: 45961 | G14: Most binders require submission within 15–30 days of period end. Verify yours.
B15: Prepared by | C15: Torque Underwriters, Delegated Authority
B16: Reporting currency | C16: USD
B17: Settlement currency | C17: USD
B18: Coverholder binding authority limit (AV) | C18: 2000000 | G18: Per Technical Premium row 16. Risks above this value require individual referral.
B19: Discount authority limit | C19: -0.15 | G19: Per Technical Premium row 19. Risks priced beyond this require senior approval.
B20: Minimum premium per policy | C20: 5000 | G20: Confirm in the binding authority wording. Applies irrespective of the formula result.
B22: SECTION B — SYNDICATE PARTICIPATION AND SHARE ALLOCATION
B23: Syndicate | C23: Managing agent | D23: Line % (share of risk) | E23: GWP at line | F23: Technical prem at line | G23: NET TO CAPACITY at line
B24: 2623 / 623 | C24: Beazley Furlonge Ltd | D24: 0.1 | E24: =(SUMIF('UW Bordereaux'!$D$5:$D$204,"Bound*",'UW Bordereaux'!$AD$5:$AD$204))*$D24 -> 4358.855 | F24: =(SUMIF('UW Bordereaux'!$D$5:$D$204,"Bound*",'UW Bordereaux'!$AB$5:$AB$204))*$D24 -> 4358.855 | G24: =(SUMIF('UW Bordereaux'!$D$5:$D$204,"Bound*",'UW Bordereaux'!$AQ$5:$AQ$204))*$D24 -> 3269.141
B25: 33 | C25: Hiscox Syndicates Ltd | D25: 0.1 | E25: =(SUMIF('UW Bordereaux'!$D$5:$D$204,"Bound*",'UW Bordereaux'!$AD$5:$AD$204))*$D25 -> 4358.855 | F25: =(SUMIF('UW Bordereaux'!$D$5:$D$204,"Bound*",'UW Bordereaux'!$AB$5:$AB$204))*$D25 -> 4358.855 | G25: =(SUMIF('UW Bordereaux'!$D$5:$D$204,"Bound*",'UW Bordereaux'!$AQ$5:$AQ$204))*$D25 -> 3269.141
B26: 1084 | C26: Chaucer Syndicates Ltd | D26: 0.1 | E26: =(SUMIF('UW Bordereaux'!$D$5:$D$204,"Bound*",'UW Bordereaux'!$AD$5:$AD$204))*$D26 -> 4358.855 | F26: =(SUMIF('UW Bordereaux'!$D$5:$D$204,"Bound*",'UW Bordereaux'!$AB$5:$AB$204))*$D26 -> 4358.855 | G26: =(SUMIF('UW Bordereaux'!$D$5:$D$204,"Bound*",'UW Bordereaux'!$AQ$5:$AQ$204))*$D26 -> 3269.141
B27: 4020 | C27: Ark Syndicate Management | D27: 0.1 | E27: =(SUMIF('UW Bordereaux'!$D$5:$D$204,"Bound*",'UW Bordereaux'!$AD$5:$AD$204))*$D27 -> 4358.855 | F27: =(SUMIF('UW Bordereaux'!$D$5:$D$204,"Bound*",'UW Bordereaux'!$AB$5:$AB$204))*$D27 -> 4358.855 | G27: =(SUMIF('UW Bordereaux'!$D$5:$D$204,"Bound*",'UW Bordereaux'!$AQ$5:$AQ$204))*$D27 -> 3269.141
B28: 2987 | C28: Brit Syndicates Ltd | D28: 0.1 | E28: =(SUMIF('UW Bordereaux'!$D$5:$D$204,"Bound*",'UW Bordereaux'!$AD$5:$AD$204))*$D28 -> 4358.855 | F28: =(SUMIF('UW Bordereaux'!$D$5:$D$204,"Bound*",'UW Bordereaux'!$AB$5:$AB$204))*$D28 -> 4358.855 | G28: =(SUMIF('UW Bordereaux'!$D$5:$D$204,"Bound*",'UW Bordereaux'!$AQ$5:$AQ$204))*$D28 -> 3269.141
B29: 4444 | C29: Canopius Managing Agents | D29: 0.1 | E29: =(SUMIF('UW Bordereaux'!$D$5:$D$204,"Bound*",'UW Bordereaux'!$AD$5:$AD$204))*$D29 -> 4358.855 | F29: =(SUMIF('UW Bordereaux'!$D$5:$D$204,"Bound*",'UW Bordereaux'!$AB$5:$AB$204))*$D29 -> 4358.855 | G29: =(SUMIF('UW Bordereaux'!$D$5:$D$204,"Bound*",'UW Bordereaux'!$AQ$5:$AQ$204))*$D29 -> 3269.141
B30: 1969 | C30: Apollo Syndicate Management | D30: 0.1 | E30: =(SUMIF('UW Bordereaux'!$D$5:$D$204,"Bound*",'UW Bordereaux'!$AD$5:$AD$204))*$D30 -> 4358.855 | F30: =(SUMIF('UW Bordereaux'!$D$5:$D$204,"Bound*",'UW Bordereaux'!$AB$5:$AB$204))*$D30 -> 4358.855 | G30: =(SUMIF('UW Bordereaux'!$D$5:$D$204,"Bound*",'UW Bordereaux'!$AQ$5:$AQ$204))*$D30 -> 3269.141
B31: 1274 | C31: Antares Managing Agency | D31: 0.1 | E31: =(SUMIF('UW Bordereaux'!$D$5:$D$204,"Bound*",'UW Bordereaux'!$AD$5:$AD$204))*$D31 -> 4358.855 | F31: =(SUMIF('UW Bordereaux'!$D$5:$D$204,"Bound*",'UW Bordereaux'!$AB$5:$AB$204))*$D31 -> 4358.855 | G31: =(SUMIF('UW Bordereaux'!$D$5:$D$204,"Bound*",'UW Bordereaux'!$AQ$5:$AQ$204))*$D31 -> 3269.141
B32: 2001 | C32: MS Amlin Underwriting | D32: 0.1 | E32: =(SUMIF('UW Bordereaux'!$D$5:$D$204,"Bound*",'UW Bordereaux'!$AD$5:$AD$204))*$D32 -> 4358.855 | F32: =(SUMIF('UW Bordereaux'!$D$5:$D$204,"Bound*",'UW Bordereaux'!$AB$5:$AB$204))*$D32 -> 4358.855 | G32: =(SUMIF('UW Bordereaux'!$D$5:$D$204,"Bound*",'UW Bordereaux'!$AQ$5:$AQ$204))*$D32 -> 3269.141
B33: 1414 | C33: Ascot Underwriting Ltd | D33: 0.1 | E33: =(SUMIF('UW Bordereaux'!$D$5:$D$204,"Bound*",'UW Bordereaux'!$AD$5:$AD$204))*$D33 -> 4358.855 | F33: =(SUMIF('UW Bordereaux'!$D$5:$D$204,"Bound*",'UW Bordereaux'!$AB$5:$AB$204))*$D33 -> 4358.855 | G33: =(SUMIF('UW Bordereaux'!$D$5:$D$204,"Bound*",'UW Bordereaux'!$AQ$5:$AQ$204))*$D33 -> 3269.141
C34: PANEL TOTAL | D34: =SUM(D24:D33) -> 1 | E34: =SUMIF('UW Bordereaux'!$D$5:$D$204,"Bound*",'UW Bordereaux'!$AD$5:$AD$204) -> 43588.55 | F34: =SUMIF('UW Bordereaux'!$D$5:$D$204,"Bound*",'UW Bordereaux'!$AB$5:$AB$204) -> 43588.55 | G34: =SUMIF('UW Bordereaux'!$D$5:$D$204,"Bound*",'UW Bordereaux'!$AQ$5:$AQ$204) -> 32691.41
D35: =IF(ROUND(D34,6)=1,"Panel signs 100% — OK","ERROR: panel signs "&TEXT(D34,"0.00%")) -> Panel signs 100% — OK
B37: SECTION C — SUBMISSION CONTROL SUMMARY (live from UW Bordereaux)
B38: Policies reported this period | C38: =COUNTA('UW Bordereaux'!$A$5:$A$204) -> 4
B39: of which bound | C39: =COUNTIF('UW Bordereaux'!$D$5:$D$204,"Bound*") -> 4
B40: of which declined / lapsed | C40: =COUNTIF('UW Bordereaux'!$D$5:$D$204,"Declined")+COUNTIF('UW Bordereaux'!$D$5:$D$204,"Cancelled")+COUNTIF('UW Bordereaux'!$D$5:$D$204,"Lapsed") -> 0
B41: TOTAL GWP BOUND | C41: =SUMIF('UW Bordereaux'!$D$5:$D$204,"Bound*",'UW Bordereaux'!$AD$5:$AD$204) -> 43588.55
B42: TOTAL TECHNICAL PREMIUM | C42: =SUMIF('UW Bordereaux'!$D$5:$D$204,"Bound*",'UW Bordereaux'!$AB$5:$AB$204) -> 43588.55
...

Sheet UW Bordereaux
A1: UNDERWRITING BORDEREAUX
A2: One row per policy per reporting period. Blue columns are for entry; grey columns calculate from the Portfolio Register or from other inputs. Report every bound risk — new business, renewals and endorsements.
A3: POLICY IDENTIFICATION | H3: RISK DATA | R3: GARAGING & CAT | W3: COVERAGE TERMS | AC3: PREMIUM — 100% GROSS | AO3: COMMISSION & NET | AT3: RATING METRICS | AZ3: CONTROLS | BE3: DATA QUALITY
A4: Certificate / policy ref | B4: Named insured | C4: Effective date | D4: Binding status | E4: Movement type | F4: UMR | G4: Year of account | H4: Vehicle year | I4: Make | J4: Model | K4: VIN / chassis | L4: Vehicle class | M4: Agreed value (USD) | N4: Policy type | O4: Usage description | P4: Annual mileage band | Q4: Garaging state | R4: Garaging ZIP | S4: Catastrophe zone | T4: Zone multiplier | U4: Cat deductible | V4: Valuation basis | W4: PD deductible | X4: Liability limit (CSL) | Y4: Endorsements / special terms | Z4: Conditions | AA4: Surplus lines / admitted | AB4: Technical premium (100%) | AC4: UW judgement adj % | AD4: GROSS WRITTEN PREMIUM (100%) | AE4: Policy fee (100%) | AF4: Inspection / appraisal fee | AG4: Surplus lines tax % | AH4: Surplus lines tax $ | AI4: Stamping fee $ | AJ4: TOTAL DUE FROM INSURED (100%) | AK4: Rate adequacy check | AL4: Bind band | AM4: Total ceding commission % | AN4: Commission $ (100%) | AO4: Broker commission $ 12.5% (100%) | AP4: Torque (MGA) commission $ 12.5% (100%) | AQ4: NET TO CAPACITY 75% (100%) | AR4: GWP at signed line | AS4: Tech prem at signed line | AT4: Technical rate per $100 | AU4: Charged rate per $100 | AV4: Portfolio rate adequacy | AW4: Profit commission accrual | AX4: MANDATORY FIELD CHECK | AY4: Above auto-bind limit? | AZ4: Min premium met? | BA4: Surplus lines tax verified? | BB4: Signed by approver? | BC4: Notes | BE4: Class / year consistency | BF4: Row foots to GWP
A5: TQ-C-2026-0149 | B5: Lorenzo Harrington | C5: 45956 | D5: Bound - within authority | E5: New business | F5: B0999TQ260149 | G5: =IF($A5="","",IF($C5="","",YEAR($C5))) -> 2025 | H5: 2024 | I5: McLaren | J5: 750S | K5: JFB2K6KWK4WRLCXF9 | L5: 03 - Supercar | M5: 665000 | N5: Personal | O5: Personal - regular use | P5: 1,000 - 2,500 | Q5: Massachusetts | R5: 02493 | S5: Tier 3 - Coastal wind (25-100 miles) | T5: =IF($A5="","",IF($S5="","",IFERROR(INDEX(Lists!$N$5:$N$16,MATCH($S5,Lists!$M$5:$M$16,0)),"?"))) -> ? | U5: 2% of agreed value, minimum $10,000 | V5: Agreed Value | W5: $5,000 | X5: $1,000,000 CSL | Y5: EX-14 OEM parts guarantee | AA5: Surplus Lines | AB5: 14412.62 | AC5: 0 | AD5: =IF(ISNUMBER($AB5),$AB5*(1+N($AC5)),"") -> 14412.62 | AE5: 250 | AF5: 150 | AG5: 0.04 | AH5: =IF(ISNUMBER($AD5),($AD5+$AE5+$AF5)*$AG5,"") -> 592.5048 | AJ5: =IF(ISNUMBER($AD5),SUM($AD5:$AH5),"") -> 15405.165 | AK5: =IF(AND(ISNUMBER($AB5),ISNUMBER($AD5)),IF($AB5>0,$AD5/$AB5,""),"") -> 1 | AL5: At technical | AM5: =IF(ISNUMBER($AD5),Header!$I$3,"") -> 0.25 | AN5: =IF(ISNUMBER($AD5),$AO5+$AP5,"") -> 3603.16 | AO5: =IF(ISNUMBER($AD5),ROUND($AD5*Header!$K$3,2),"") -> 1801.58 | AP5: =IF(ISNUMBER($AD5),ROUND($AD5*Header!$M$3,2),"") -> 1801.58 | AQ5: =IF(ISNUMBER($AD5),ROUND($AD5,2)-$AO5-$AP5,"") -> 10809.46 | AR5: =IF(ISNUMBER($AD5),IF(Header!$D$34="","?",$AD5*Header!$D$34),"") -> 14412.62 | AS5: =IF(ISNUMBER($AB5),IF(Header!$D$34="","?",$AB5*Header!$D$34),"") -> 14412.62 | AT5: =IF(AND(ISNUMBER($AB5),$M5>0),$AB5/$M5*100,"") -> 2.1673113 | AU5: =IF(AND(ISNUMBER($AD5),$M5>0),$AD5/$M5*100,"") -> 2.1673113 | AV5: =IF(AND(ISNUMBER($AB5),ISNUMBER($AD5),ABS($AB5)>0),$AD5/$AB5,"") -> 1 | AW5: =IF(ISNUMBER($AD5),MAX(0,(1-0.55-Header!$O$3)*Header!$Q$3*$AQ5),"") -> 0 | AX5: =IF($A5="","",IF(TRIM(IF($A5="","Missing certificate ref. ","") & IF($C5="","Missing effective date. ","") & IF($D5="","Missing binding status. ","") & IF($E5="","Missing movement type. ","") & IF($I5="","Missing make. ","") & IF($L5="","Missing vehicle class. ","") & IF($M5="","Missing agreed value. ","") & IF($N5="","Missing policy type. ","") & IF($Q5="","Missing garaging state. ","") & IF($R5="","Missing garaging ZIP. ","") & IF($S5="","Missing cat zone. ","") & IF($V5="","Missing valuation basis. ","") & IF($W5="","Missing PD deductible. ","") & IF($X5="","Missing liability limit. ","") & IF($AB5="","Missing technical premium. ","") & IF($AF5="","Missing surplus lines tax %. ",""))="","PASS","FAIL: "&TRIM(IF($A5="","Missing certificate ref. ","") & IF($C5="","Missing effective date. ","") & IF($D5="","Missing binding status. ","") & IF($E5="","Missing movement type. ","") & IF($I5="","Missing make. ","") & IF($L5="","Missing vehicle class. ","") & IF($M5="","Missing agreed value. ","") & IF($N5="","Missing policy type. ","") & IF($Q5="","Missing garaging state. ","") & IF($R5="","Missing garaging ZIP. ","") & IF($S5="","Missing cat zone. ","") & IF($V5="","Missing valuation basis. ","") & IF($W5="","Missing PD deductible. ","") & IF($X5="","Missing liability limit. ","") & IF($AB5="","Missing technical premium. ","") & IF($AF5="","Missing surplus lines tax %. ","")))) -> PASS | AY5: =IF($M5="","",IF(ISNUMBER($M5),IF($M5>=Header!$C$18,"YES — refer","No"),"")) -> No | AZ5: =IF($AD5="","",IF(ISNUMBER($AD5),IF($AD5<Header!$C$20,"BELOW MIN PREMIUM","OK"),"")) -> OK | BA5: Yes | BC5: Register ref CANON-202510-001366. Bound within delegated authority. Schedule cert under master UMR B0999TQ260149. SL tax rate verified Massachusetts. | BE5: =IF(OR($A5="",$L5="",$H5=""),"",IF(AND(LEFT($L5,2)="06",$H5>1945),"FAIL - pre-war class, year "&$H5,IF(AND(LEFT($L5,2)="07",OR($H5<1946,$H5>1972)),"FAIL - 1946-72 class, year "&$H5,IF(AND(LEFT($L5,2)="08",OR($H5<1973,$H5>1999)),"FAIL - 1973-99 class, year "&$H5,IF(AND(LEFT($L5,2)="09",OR($H5<2000,$H5>2010)),"FAIL - 2000-10 class, year "&$H5,"OK"))))) -> OK | BF5: =IF($AD5="","",IF(ROUND($AO5+$AP5+$AQ5-$AD5,2)=0,"OK","FAIL - out by "&TEXT($AO5+$AP5+$AQ5-$AD5,"$0.00"))) -> OK
A6: TQ-C-2026-0175 | B6: Lorenzo Harrington | C6: 45956 | D6: Bound - within authority | E6: New business | F6: B0999TQ260175 | G6: =IF($A6="","",IF($C6="","",YEAR($C6))) -> 2025 | H6: 1967 | I6: Ferrari | J6: 275 GTB/4 | K6: PR39BTFUPC2MT96F5 | L6: 07 - Post-War Classic (1946-1972) | M6: 445000 | N6: Personal | O6: Personal - regular use | P6: 1,000 - 2,500 | Q6: Massachusetts | R6: 02493 | S6: Tier 3 - Coastal wind (25-100 miles) | T6: =IF($A6="","",IF($S6="","",IFERROR(INDEX(Lists!$N$5:$N$16,MATCH($S6,Lists!$M$5:$M$16,0)),"?"))) -> ? | U6: 2% of agreed value, minimum $10,000 | V6: Agreed Value | W6: $2,500 | X6: $1,000,000 CSL | Y6: EX-04 Appreciation; EX-05 DIV; EX-09 Worldwide 90 days | AA6: Surplus Lines | AB6: 6932.58 | AC6: 0 | AD6: =IF(ISNUMBER($AB6),$AB6*(1+N($AC6)),"") -> 6932.58 | AE6: 250 | AF6: 150 | AG6: 0.04 | AH6: =IF(ISNUMBER($AD6),($AD6+$AE6+$AF6)*$AG6,"") -> 293.3032 | AJ6: =IF(ISNUMBER($AD6),SUM($AD6:$AH6),"") -> 7625.9232 | AK6: =IF(AND(ISNUMBER($AB6),ISNUMBER($AD6)),IF($AB6>0,$AD6/$AB6,""),"") -> 1 | AL6: At technical | AM6: =IF(ISNUMBER($AD6),Header!$I$3,"") -> 0.25 | AN6: =IF(ISNUMBER($AD6),$AO6+$AP6,"") -> 1733.14 | AO6: =IF(ISNUMBER($AD6),ROUND($AD6*Header!$K$3,2),"") -> 866.57 | AP6: =IF(ISNUMBER($AD6),ROUND($AD6*Header!$M$3,2),"") -> 866.57 | AQ6: =IF(ISNUMBER($AD6),ROUND($AD6,2)-$AO6-$AP6,"") -> 5199.44 | AR6: =IF(ISNUMBER($AD6),IF(Header!$D$34="","?",$AD6*Header!$D$34),"") -> 6932.58 | AS6: =IF(ISNUMBER($AB6),IF(Header!$D$34="","?",$AB6*Header!$D$34),"") -> 6932.58 | AT6: =IF(AND(ISNUMBER($AB6),$M6>0),$AB6/$M6*100,"") -> 1.5578831 | AU6: =IF(AND(ISNUMBER($AD6),$M6>0),$AD6/$M6*100,"") -> 1.5578831 | AV6: =IF(AND(ISNUMBER($AB6),ISNUMBER($AD6),ABS($AB6)>0),$AD6/$AB6,"") -> 1 | AW6: =IF(ISNUMBER($AD6),MAX(0,(1-0.55-Header!$O$3)*Header!$Q$3*$AQ6),"") -> 0 | AX6: =IF($A6="","",IF(TRIM(IF($A6="","Missing certificate ref. ","") & IF($C6="","Missing effective date. ","") & IF($D6="","Missing binding status. ","") & IF($E6="","Missing movement type. ","") & IF($I6="","Missing make. ","") & IF($L6="","Missing vehicle class. ","") & IF($M6="","Missing agreed value. ","") & IF($N6="","Missing policy type. ","") & IF($Q6="","Missing garaging state. ","") & IF($R6="","Missing garaging ZIP. ","") & IF($S6="","Missing cat zone. ","") & IF($V6="","Missing valuation basis. ","") & IF($W6="","Missing PD deductible. ","") & IF($X6="","Missing liability limit. ","") & IF($AB6="","Missing technical premium. ","") & IF($AF6="","Missing surplus lines tax %. ",""))="","PASS","FAIL: "&TRIM(IF($A6="","Missing certificate ref. ","") & IF($C6="","Missing effective date. ","") & IF($D6="","Missing binding status. ","") & IF($E6="","Missing movement type. ","") & IF($I6="","Missing make. ","") & IF($L6="","Missing vehicle class. ","") & IF($M6="","Missing agreed value. ","") & IF($N6="","Missing policy type. ","") & IF($Q6="","Missing garaging state. ","") & IF($R6="","Missing garaging ZIP. ","") & IF($S6="","Missing cat zone. ","") & IF($V6="","Missing valuation basis. ","") & IF($W6="","Missing PD deductible. ","") & IF($X6="","Missing liability limit. ","") & IF($AB6="","Missing technical premium. ","") & IF($AF6="","Missing surplus lines tax %. ","")))) -> PASS | AY6: =IF($M6="","",IF(ISNUMBER($M6),IF($M6>=Header!$C$18,"YES — refer","No"),"")) -> No | AZ6: =IF($AD6="","",IF(ISNUMBER($AD6),IF($AD6<Header!$C$20,"BELOW MIN PREMIUM","OK"),"")) -> OK | BA6: Yes | BC6: Register ref CANON-202508-000059. Bound within delegated authority. Schedule cert under master UMR B0999TQ260149. SL tax rate verified Massachusetts. | BE6: =IF(OR($A6="",$L6="",$H6=""),"",IF(AND(LEFT($L6,2)="06",$H6>1945),"FAIL - pre-war class, year "&$H6,IF(AND(LEFT($L6,2)="07",OR($H6<1946,$H6>1972)),"FAIL - 1946-72 class, year "&$H6,IF(AND(LEFT($L6,2)="08",OR($H6<1973,$H6>1999)),"FAIL - 1973-99 class, year "&$H6,IF(AND(LEFT($L6,2)="09",OR($H6<2000,$H6>2010)),"FAIL - 2000-10 class, year "&$H6,"OK"))))) -> OK | BF6: =IF($AD6="","",IF(ROUND($AO6+$AP6+$AQ6-$AD6,2)=0,"OK","FAIL - out by "&TEXT($AO6+$AP6+$AQ6-$AD6,"$0.00"))) -> OK
A7: TQ-C-2026-0176 | B7: Lorenzo Harrington | C7: 45956 | D7: Bound - within authority | E7: New business | F7: B0999TQ260176 | G7: =IF($A7="","",IF($C7="","",YEAR($C7))) -> 2025 | H7: 1967 | I7: Other / Bespoke | J7: 280SL Pagoda | K7: B8BCYPCFBN1T568FK | L7: 07 - Post-War Classic (1946-1972) | M7: 1090000 | N7: Personal | O7: Personal - regular use | P7: 1,000 - 2,500 | Q7: Massachusetts | R7: 02493 | S7: Tier 3 - Coastal wind (25-100 miles) | T7: =IF($A7="","",IF($S7="","",IFERROR(INDEX(Lists!$N$5:$N$16,MATCH($S7,Lists!$M$5:$M$16,0)),"?"))) -> ? | U7: 2% of agreed value, minimum $10,000 | V7: Agreed Value | W7: $2,500 | X7: $1,000,000 CSL | Y7: EX-17 Pair & Set | AA7: Surplus Lines | AB7: 11138.86 | AC7: 0 | AD7: =IF(ISNUMBER($AB7),$AB7*(1+N($AC7)),"") -> 11138.86 | AE7: 250 | AF7: 150 | AG7: 0.04 | AH7: =IF(ISNUMBER($AD7),($AD7+$AE7+$AF7)*$AG7,"") -> 461.5544 | AJ7: =IF(ISNUMBER($AD7),SUM($AD7:$AH7),"") -> 12000.454 | AK7: =IF(AND(ISNUMBER($AB7),ISNUMBER($AD7)),IF($AB7>0,$AD7/$AB7,""),"") -> 1 | AL7: At technical | AM7: =IF(ISNUMBER($AD7),Header!$I$3,"") -> 0.25 | AN7: =IF(ISNUMBER($AD7),$AO7+$AP7,"") -> 2784.72 | AO7: =IF(ISNUMBER($AD7),ROUND($AD7*Header!$K$3,2),"") -> 1392.36 | AP7: =IF(ISNUMBER($AD7),ROUND($AD7*Header!$M$3,2),"") -> 1392.36 | AQ7: =IF(ISNUMBER($AD7),ROUND($AD7,2)-$AO7-$AP7,"") -> 8354.14 | AR7: =IF(ISNUMBER($AD7),IF(Header!$D$34="","?",$AD7*Header!$D$34),"") -> 11138.86 | AS7: =IF(ISNUMBER($AB7),IF(Header!$D$34="","?",$AB7*Header!$D$34),"") -> 11138.86 | AT7: =IF(AND(ISNUMBER($AB7),$M7>0),$AB7/$M7*100,"") -> 1.0219138 | AU7: =IF(AND(ISNUMBER($AD7),$M7>0),$AD7/$M7*100,"") -> 1.0219138 | AV7: =IF(AND(ISNUMBER($AB7),ISNUMBER($AD7),ABS($AB7)>0),$AD7/$AB7,"") -> 1 | AW7: =IF(ISNUMBER($AD7),MAX(0,(1-0.55-Header!$O$3)*Header!$Q$3*$AQ7),"") -> 0 | AX7: =IF($A7="","",IF(TRIM(IF($A7="","Missing certificate ref. ","") & IF($C7="","Missing effective date. ","") & IF($D7="","Missing binding status. ","") & IF($E7="","Missing movement type. ","") & IF($I7="","Missing make. ","") & IF($L7="","Missing vehicle class. ","") & IF($M7="","Missing agreed value. ","") & IF($N7="","Missing policy type. ","") & IF($Q7="","Missing garaging state. ","") & IF($R7="","Missing garaging ZIP. ","") & IF($S7="","Missing cat zone. ","") & IF($V7="","Missing valuation basis. ","") & IF($W7="","Missing PD deductible. ","") & IF($X7="","Missing liability limit. ","") & IF($AB7="","Missing technical premium. ","") & IF($AF7="","Missing surplus lines tax %. ",""))="","PASS","FAIL: "&TRIM(IF($A7="","Missing certificate ref. ","") & IF($C7="","Missing effective date. ","") & IF($D7="","Missing binding status. ","") & IF($E7="","Missing movement type. ","") & IF($I7="","Missing make. ","") & IF($L7="","Missing vehicle class. ","") & IF($M7="","Missing agreed value. ","") & IF($N7="","Missing policy type. ","") & IF($Q7="","Missing garaging state. ","") & IF($R7="","Missing garaging ZIP. ","") & IF($S7="","Missing cat zone. ","") & IF($V7="","Missing valuation basis. ","") & IF($W7="","Missing PD deductible. ","") & IF($X7="","Missing liability limit. ","") & IF($AB7="","Missing technical premium. ","") & IF($AF7="","Missing surplus lines tax %. ","")))) -> PASS | AY7: =IF($M7="","",IF(ISNUMBER($M7),IF($M7>=Header!$C$18,"YES — refer","No"),"")) -> No | AZ7: =IF($AD7="","",IF(ISNUMBER($AD7),IF($AD7<Header!$C$20,"BELOW MIN PREMIUM","OK"),"")) -> OK | BA7: Yes | BC7: Register ref CANON-202509-000795. Bound within delegated authority. Schedule cert under master UMR B0999TQ260149. SL tax rate verified Massachusetts. | BE7: =IF(OR($A7="",$L7="",$H7=""),"",IF(AND(LEFT($L7,2)="06",$H7>1945),"FAIL - pre-war class, year "&$H7,IF(AND(LEFT($L7,2)="07",OR($H7<1946,$H7>1972)),"FAIL - 1946-72 class, year "&$H7,IF(AND(LEFT($L7,2)="08",OR($H7<1973,$H7>1999)),"FAIL - 1973-99 class, year "&$H7,IF(AND(LEFT($L7,2)="09",OR($H7<2000,$H7>2010)),"FAIL - 2000-10 class, year "&$H7,"OK"))))) -> OK | BF7: =IF($AD7="","",IF(ROUND($AO7+$AP7+$AQ7-$AD7,2)=0,"OK","FAIL - out by "&TEXT($AO7+$AP7+$AQ7-$AD7,"$0.00"))) -> OK
A8: TQ-C-2026-0177 | B8: Lorenzo Harrington | C8: 45956 | D8: Bound - within authority | E8: New business | F8: B0999TQ260177 | G8: =IF($A8="","",IF($C8="","",YEAR($C8))) -> 2025 | H8: 2021 | I8: Lamborghini | J8: Huracan EVO | K8: UL6R2X0KYJWNJ50RW | L8: 03 - Supercar | M8: 560000 | N8: Personal | O8: Personal - regular use | P8: 1,000 - 2,500 | Q8: Massachusetts | R8: 02493 | S8: Tier 3 - Coastal wind (25-100 miles) | T8: =IF($A8="","",IF($S8="","",IFERROR(INDEX(Lists!$N$5:$N$16,MATCH($S8,Lists!$M$5:$M$16,0)),"?"))) -> ? | U8: 2% of agreed value, minimum $10,000 | V8: Agreed Value | W8: $5,000 | X8: $1,000,000 CSL | Y8: Renter agreement; GPS active | AA8: Surplus Lines | AB8: 11104.49 | AC8: 0 | AD8: =IF(ISNUMBER($AB8),$AB8*(1+N($AC8)),"") -> 11104.49 | AE8: 250 | AF8: 150 | AG8: 0.04 | AH8: =IF(ISNUMBER($AD8),($AD8+$AE8+$AF8)*$AG8,"") -> 460.1796 | AJ8: =IF(ISNUMBER($AD8),SUM($AD8:$AH8),"") -> 11964.71 | AK8: =IF(AND(ISNUMBER($AB8),ISNUMBER($AD8)),IF($AB8>0,$AD8/$AB8,""),"") -> 1 | AL8: At technical | AM8: =IF(ISNUMBER($AD8),Header!$I$3,"") -> 0.25 | AN8: =IF(ISNUMBER($AD8),$AO8+$AP8,"") -> 2776.12 | AO8: =IF(ISNUMBER($AD8),ROUND($AD8*Header!$K$3,2),"") -> 1388.06 | AP8: =IF(ISNUMBER($AD8),ROUND($AD8*Header!$M$3,2),"") -> 1388.06 | AQ8: =IF(ISNUMBER($AD8),ROUND($AD8,2)-$AO8-$AP8,"") -> 8328.37 | AR8: =IF(ISNUMBER($AD8),IF(Header!$D$34="","?",$AD8*Header!$D$34),"") -> 11104.49 | AS8: =IF(ISNUMBER($AB8),IF(Header!$D$34="","?",$AB8*Header!$D$34),"") -> 11104.49 | AT8: =IF(AND(ISNUMBER($AB8),$M8>0),$AB8/$M8*100,"") -> 1.9829446 | AU8: =IF(AND(ISNUMBER($AD8),$M8>0),$AD8/$M8*100,"") -> 1.9829446 | AV8: =IF(AND(ISNUMBER($AB8),ISNUMBER($AD8),ABS($AB8)>0),$AD8/$AB8,"") -> 1 | AW8: =IF(ISNUMBER($AD8),MAX(0,(1-0.55-Header!$O$3)*Header!$Q$3*$AQ8),"") -> 0 | AX8: =IF($A8="","",IF(TRIM(IF($A8="","Missing certificate ref. ","") & IF($C8="","Missing effective date. ","") & IF($D8="","Missing binding status. ","") & IF($E8="","Missing movement type. ","") & IF($I8="","Missing make. ","") & IF($L8="","Missing vehicle class. ","") & IF($M8="","Missing agreed value. ","") & IF($N8="","Missing policy type. ","") & IF($Q8="","Missing garaging state. ","") & IF($R8="","Missing garaging ZIP. ","") & IF($S8="","Missing cat zone. ","") & IF($V8="","Missing valuation basis. ","") & IF($W8="","Missing PD deductible. ","") & IF($X8="","Missing liability limit. ","") & IF($AB8="","Missing technical premium. ","") & IF($AF8="","Missing surplus lines tax %. ",""))="","PASS","FAIL: "&TRIM(IF($A8="","Missing certificate ref. ","") & IF($C8="","Missing effective date. ","") & IF($D8="","Missing binding status. ","") & IF($E8="","Missing movement type. ","") & IF($I8="","Missing make. ","") & IF($L8="","Missing vehicle class. ","") & IF($M8="","Missing agreed value. ","") & IF($N8="","Missing policy type. ","") & IF($Q8="","Missing garaging state. ","") & IF($R8="","Missing garaging ZIP. ","") & IF($S8="","Missing cat zone. ","") & IF($V8="","Missing valuation basis. ","") & IF($W8="","Missing PD deductible. ","") & IF($X8="","Missing liability limit. ","") & IF($AB8="","Missing technical premium. ","") & IF($AF8="","Missing surplus lines tax %. ","")))) -> PASS | AY8: =IF($M8="","",IF(ISNUMBER($M8),IF($M8>=Header!$C$18,"YES — refer","No"),"")) -> No | AZ8: =IF($AD8="","",IF(ISNUMBER($AD8),IF($AD8<Header!$C$20,"BELOW MIN PREMIUM","OK"),"")) -> OK | BA8: Yes | BC8: Register ref CANON-202510-001368. Bound within delegated authority. Schedule cert under master UMR B0999TQ260149. SL tax rate verified Massachusetts. | BE8: =IF(OR($A8="",$L8="",$H8=""),"",IF(AND(LEFT($L8,2)="06",$H8>1945),"FAIL - pre-war class, year "&$H8,IF(AND(LEFT($L8,2)="07",OR($H8<1946,$H8>1972)),"FAIL - 1946-72 class, year "&$H8,IF(AND(LEFT($L8,2)="08",OR($H8<1973,$H8>1999)),"FAIL - 1973-99 class, year "&$H8,IF(AND(LEFT($L8,2)="09",OR($H8<2000,$H8>2010)),"FAIL - 2000-10 class, year "&$H8,"OK"))))) -> OK | BF8: =IF($AD8="","",IF(ROUND($AO8+$AP8+$AQ8-$AD8,2)=0,"OK","FAIL - out by "&TEXT($AO8+$AP8+$AQ8-$AD8,"$0.00"))) -> OK
G9: =IF($A9="","",IF($C9="","",YEAR($C9))) | T9: =IF($A9="","",IF($S9="","",IFERROR(INDEX(Lists!$N$5:$N$16,MATCH($S9,Lists!$M$5:$M$16,0)),"?"))) | Y9: HPDE certificate on file | AD9: =IF(ISNUMBER($AB9),$AB9*(1+N($AC9)),"") | AH9: =IF(ISNUMBER($AD9),($AD9+$AE9+$AF9)*$AG9,"") | AJ9: =IF(ISNUMBER($AD9),SUM($AD9:$AH9),"") | AK9: =IF(AND(ISNUMBER($AB9),ISNUMBER($AD9)),IF($AB9>0,$AD9/$AB9,""),"") | AM9: =IF(ISNUMBER($AD9),Header!$I$3,"") | AN9: =IF(ISNUMBER($AD9),$AO9+$AP9,"") | AO9: =IF(ISNUMBER($AD9),ROUND($AD9*Header!$K$3,2),"") | AP9: =IF(ISNUMBER($AD9),ROUND($AD9*Header!$M$3,2),"") | AQ9: =IF(ISNUMBER($AD9),ROUND($AD9,2)-$AO9-$AP9,"") | AR9: =IF(ISNUMBER($AD9),IF(Header!$D$34="","?",$AD9*Header!$D$34),"") | AS9: =IF(ISNUMBER($AB9),IF(Header!$D$34="","?",$AB9*Header!$D$34),"") | AT9: =IF(AND(ISNUMBER($AB9),$M9>0),$AB9/$M9*100,"") | AU9: =IF(AND(ISNUMBER($AD9),$M9>0),$AD9/$M9*100,"") | AV9: =IF(AND(ISNUMBER($AB9),ISNUMBER($AD9),ABS($AB9)>0),$AD9/$AB9,"") | AW9: =IF(ISNUMBER($AD9),MAX(0,(1-0.55-Header!$O$3)*Header!$Q$3*$AQ9),"") | AX9: =IF($A9="","",IF(TRIM(IF($A9="","Missing certificate ref. ","") & IF($C9="","Missing effective date. ","") & IF($D9="","Missing binding status. ","") & IF($E9="","Missing movement type. ","") & IF($I9="","Missing make. ","") & IF($L9="","Missing vehicle class. ","") & IF($M9="","Missing agreed value. ","") & IF($N9="","Missing policy type. ","") & IF($Q9="","Missing garaging state. ","") & IF($R9="","Missing garaging ZIP. ","") & IF($S9="","Missing cat zone. ","") & IF($V9="","Missing valuation basis. ","") & IF($W9="","Missing PD deductible. ","") & IF($X9="","Missing liability limit. ","") & IF($AB9="","Missing technical premium. ","") & IF($AF9="","Missing surplus lines tax %. ",""))="","PASS","FAIL: "&TRIM(IF($A9="","Missing certificate ref. ","") & IF($C9="","Missing effective date. ","") & IF($D9="","Missing binding status. ","") & IF($E9="","Missing movement type. ","") & IF($I9="","Missing make. ","") & IF($L9="","Missing vehicle class. ","") & IF($M9="","Missing agreed value. ","") & IF($N9="","Missing policy type. ","") & IF($Q9="","Missing garaging state. ","") & IF($R9="","Missing garaging ZIP. ","") & IF($S9="","Missing cat zone. ","") & IF($V9="","Missing valuation basis. ","") & IF($W9="","Missing PD deductible. ","") & IF($X9="","Missing liability limit. ","") & IF($AB9="","Missing technical premium. ","") & IF($AF9="","Missing surplus lines tax %. ","")))) | AY9: =IF($M9="","",IF(ISNUMBER($M9),IF($M9>=Header!$C$18,"YES — refer","No"),"")) | AZ9: =IF($AD9="","",IF(ISNUMBER($AD9),IF($AD9<Header!$C$20,"BELOW MIN PREMIUM","OK"),"")) | BE9: =IF(OR($A9="",$L9="",$H9=""),"",IF(AND(LEFT($L9,2)="06",$H9>1945),"FAIL - pre-war class, year "&$H9,IF(AND(LEFT($L9,2)="07",OR($H9<1946,$H9>1972)),"FAIL - 1946-72 class, year "&$H9,IF(AND(LEFT($L9,2)="08",OR($H9<1973,$H9>1999)),"FAIL - 1973-99 class, year "&$H9,IF(AND(LEFT($L9,2)="09",OR($H9<2000,$H9>2010)),"FAIL - 2000-10 class, year "&$H9,"OK"))))) | BF9: =IF($AD9="","",IF(ROUND($AO9+$AP9+$AQ9-$AD9,2)=0,"OK","FAIL - out by "&TEXT($AO9+$AP9+$AQ9-$AD9,"$0.00")))
G10: =IF($A10="","",IF($C10="","",YEAR($C10))) | T10: =IF($A10="","",IF($S10="","",IFERROR(INDEX(Lists!$N$5:$N$16,MATCH($S10,Lists!$M$5:$M$16,0)),"?"))) | Y10: EX-05 DIV; EX-16 full glass | AD10: =IF(ISNUMBER($AB10),$AB10*(1+N($AC10)),"") | AH10: =IF(ISNUMBER($AD10),($AD10+$AE10+$AF10)*$AG10,"") | AJ10: =IF(ISNUMBER($AD10),SUM($AD10:$AH10),"") | AK10: =IF(AND(ISNUMBER($AB10),ISNUMBER($AD10)),IF($AB10>0,$AD10/$AB10,""),"") | AM10: =IF(ISNUMBER($AD10),Header!$I$3,"") | AN10: =IF(ISNUMBER($AD10),$AO10+$AP10,"") | AO10: =IF(ISNUMBER($AD10),ROUND($AD10*Header!$K$3,2),"") | AP10: =IF(ISNUMBER($AD10),ROUND($AD10*Header!$M$3,2),"") | AQ10: =IF(ISNUMBER($AD10),ROUND($AD10,2)-$AO10-$AP10,"") | AR10: =IF(ISNUMBER($AD10),IF(Header!$D$34="","?",$AD10*Header!$D$34),"") | AS10: =IF(ISNUMBER($AB10),IF(Header!$D$34="","?",$AB10*Header!$D$34),"") | AT10: =IF(AND(ISNUMBER($AB10),$M10>0),$AB10/$M10*100,"") | AU10: =IF(AND(ISNUMBER($AD10),$M10>0),$AD10/$M10*100,"") | AV10: =IF(AND(ISNUMBER($AB10),ISNUMBER($AD10),ABS($AB10)>0),$AD10/$AB10,"") | AW10: =IF(ISNUMBER($AD10),MAX(0,(1-0.55-Header!$O$3)*Header!$Q$3*$AQ10),"") | AX10: =IF($A10="","",IF(TRIM(IF($A10="","Missing certificate ref. ","") & IF($C10="","Missing effective date. ","") & IF($D10="","Missing binding status. ","") & IF($E10="","Missing movement type. ","") & IF($I10="","Missing make. ","") & IF($L10="","Missing vehicle class. ","") & IF($M10="","Missing agreed value. ","") & IF($N10="","Missing policy type. ","") & IF($Q10="","Missing garaging state. ","") & IF($R10="","Missing garaging ZIP. ","") & IF($S10="","Missing cat zone. ","") & IF($V10="","Missing valuation basis. ","") & IF($W10="","Missing PD deductible. ","") & IF($X10="","Missing liability limit. ","") & IF($AB10="","Missing technical premium. ","") & IF($AF10="","Missing surplus lines tax %. ",""))="","PASS","FAIL: "&TRIM(IF($A10="","Missing certificate ref. ","") & IF($C10="","Missing effective date. ","") & IF($D10="","Missing binding status. ","") & IF($E10="","Missing movement type. ","") & IF($I10="","Missing make. ","") & IF($L10="","Missing vehicle class. ","") & IF($M10="","Missing agreed value. ","") & IF($N10="","Missing policy type. ","") & IF($Q10="","Missing garaging state. ","") & IF($R10="","Missing garaging ZIP. ","") & IF($S10="","Missing cat zone. ","") & IF($V10="","Missing valuation basis. ","") & IF($W10="","Missing PD deductible. ","") & IF($X10="","Missing liability limit. ","") & IF($AB10="","Missing technical premium. ","") & IF($AF10="","Missing surplus lines tax %. ","")))) | AY10: =IF($M10="","",IF(ISNUMBER($M10),IF($M10>=Header!$C$18,"YES — refer","No"),"")) | AZ10: =IF($AD10="","",IF(ISNUMBER($AD10),IF($AD10<Header!$C$20,"BELOW MIN PREMIUM","OK"),"")) | BE10: =IF(OR($A10="",$L10="",$H10=""),"",IF(AND(LEFT($L10,2)="06",$H10>1945),"FAIL - pre-war class, year "&$H10,IF(AND(LEFT($L10,2)="07",OR($H10<1946,$H10>1972)),"FAIL - 1946-72 class, year "&$H10,IF(AND(LEFT($L10,2)="08",OR($H10<1973,$H10>1999)),"FAIL - 1973-99 class, year "&$H10,IF(AND(LEFT($L10,2)="09",OR($H10<2000,$H10>2010)),"FAIL - 2000-10 class, year "&$H10,"OK"))))) | BF10: =IF($AD10="","",IF(ROUND($AO10+$AP10+$AQ10-$AD10,2)=0,"OK","FAIL - out by "&TEXT($AO10+$AP10+$AQ10-$AD10,"$0.00")))
G11: =IF($A11="","",IF($C11="","",YEAR($C11))) | T11: =IF($A11="","",IF($S11="","",IFERROR(INDEX(Lists!$N$5:$N$16,MATCH($S11,Lists!$M$5:$M$16,0)),"?"))) | AD11: =IF(ISNUMBER($AB11),$AB11*(1+N($AC11)),"") | AH11: =IF(ISNUMBER($AD11),($AD11+$AE11+$AF11)*$AG11,"") | AJ11: =IF(ISNUMBER($AD11),SUM($AD11:$AH11),"") | AK11: =IF(AND(ISNUMBER($AB11),ISNUMBER($AD11)),IF($AB11>0,$AD11/$AB11,""),"") | AM11: =IF(ISNUMBER($AD11),Header!$I$3,"") | AN11: =IF(ISNUMBER($AD11),$AO11+$AP11,"") | AO11: =IF(ISNUMBER($AD11),ROUND($AD11*Header!$K$3,2),"") | AP11: =IF(ISNUMBER($AD11),ROUND($AD11*Header!$M$3,2),"") | AQ11: =IF(ISNUMBER($AD11),ROUND($AD11,2)-$AO11-$AP11,"") | AR11: =IF(ISNUMBER($AD11),IF(Header!$D$34="","?",$AD11*Header!$D$34),"") | AS11: =IF(ISNUMBER($AB11),IF(Header!$D$34="","?",$AB11*Header!$D$34),"") | AT11: =IF(AND(ISNUMBER($AB11),$M11>0),$AB11/$M11*100,"") | AU11: =IF(AND(ISNUMBER($AD11),$M11>0),$AD11/$M11*100,"") | AV11: =IF(AND(ISNUMBER($AB11),ISNUMBER($AD11),ABS($AB11)>0),$AD11/$AB11,"") | AW11: =IF(ISNUMBER($AD11),MAX(0,(1-0.55-Header!$O$3)*Header!$Q$3*$AQ11),"") | AX11: =IF($A11="","",IF(TRIM(IF($A11="","Missing certificate ref. ","") & IF($C11="","Missing effective date. ","") & IF($D11="","Missing binding status. ","") & IF($E11="","Missing movement type. ","") & IF($I11="","Missing make. ","") & IF($L11="","Missing vehicle class. ","") & IF($M11="","Missing agreed value. ","") & IF($N11="","Missing policy type. ","") & IF($Q11="","Missing garaging state. ","") & IF($R11="","Missing garaging ZIP. ","") & IF($S11="","Missing cat zone. ","") & IF($V11="","Missing valuation basis. ","") & IF($W11="","Missing PD deductible. ","") & IF($X11="","Missing liability limit. ","") & IF($AB11="","Missing technical premium. ","") & IF($AF11="","Missing surplus lines tax %. ",""))="","PASS","FAIL: "&TRIM(IF($A11="","Missing certificate ref. ","") & IF($C11="","Missing effective date. ","") & IF($D11="","Missing binding status. ","") & IF($E11="","Missing movement type. ","") & IF($I11="","Missing make. ","") & IF($L11="","Missing vehicle class. ","") & IF($M11="","Missing agreed value. ","") & IF($N11="","Missing policy type. ","") & IF($Q11="","Missing garaging state. ","") & IF($R11="","Missing garaging ZIP. ","") & IF($S11="","Missing cat zone. ","") & IF($V11="","Missing valuation basis. ","") & IF($W11="","Missing PD deductible. ","") & IF($X11="","Missing liability limit. ","") & IF($AB11="","Missing technical premium. ","") & IF($AF11="","Missing surplus lines tax %. ","")))) | AY11: =IF($M11="","",IF(ISNUMBER($M11),IF($M11>=Header!$C$18,"YES — refer","No"),"")) | AZ11: =IF($AD11="","",IF(ISNUMBER($AD11),IF($AD11<Header!$C$20,"BELOW MIN PREMIUM","OK"),"")) | BE11: =IF(OR($A11="",$L11="",$H11=""),"",IF(AND(LEFT($L11,2)="06",$H11>1945),"FAIL - pre-war class, year "&$H11,IF(AND(LEFT($L11,2)="07",OR($H11<1946,$H11>1972)),"FAIL - 1946-72 class, year "&$H11,IF(AND(LEFT($L11,2)="08",OR($H11<1973,$H11>1999)),"FAIL - 1973-99 class, year "&$H11,IF(AND(LEFT($L11,2)="09",OR($H11<2000,$H11>2010)),"FAIL - 2000-10 class, year "&$H11,"OK"))))) | BF11: =IF($AD11="","",IF(ROUND($AO11+$AP11+$AQ11-$AD11,2)=0,"OK","FAIL - out by "&TEXT($AO11+$AP11+$AQ11-$AD11,"$0.00")))
G12: =IF($A12="","",IF($C12="","",YEAR($C12))) | T12: =IF($A12="","",IF($S12="","",IFERROR(INDEX(Lists!$N$5:$N$16,MATCH($S12,Lists!$M$5:$M$16,0)),"?"))) | AD12: =IF(ISNUMBER($AB12),$AB12*(1+N($AC12)),"") | AH12: =IF(ISNUMBER($AD12),($AD12+$AE12+$AF12)*$AG12,"") | AJ12: =IF(ISNUMBER($AD12),SUM($AD12:$AH12),"") | AK12: =IF(AND(ISNUMBER($AB12),ISNUMBER($AD12)),IF($AB12>0,$AD12/$AB12,""),"") | AM12: =IF(ISNUMBER($AD12),Header!$I$3,"") | AN12: =IF(ISNUMBER($AD12),$AO12+$AP12,"") | AO12: =IF(ISNUMBER($AD12),ROUND($AD12*Header!$K$3,2),"") | AP12: =IF(ISNUMBER($AD12),ROUND($AD12*Header!$M$3,2),"") | AQ12: =IF(ISNUMBER($AD12),ROUND($AD12,2)-$AO12-$AP12,"") | AR12: =IF(ISNUMBER($AD12),IF(Header!$D$34="","?",$AD12*Header!$D$34),"") | AS12: =IF(ISNUMBER($AB12),IF(Header!$D$34="","?",$AB12*Header!$D$34),"") | AT12: =IF(AND(ISNUMBER($AB12),$M12>0),$AB12/$M12*100,"") | AU12: =IF(AND(ISNUMBER($AD12),$M12>0),$AD12/$M12*100,"") | AV12: =IF(AND(ISNUMBER($AB12),ISNUMBER($AD12),ABS($AB12)>0),$AD12/$AB12,"") | AW12: =IF(ISNUMBER($AD12),MAX(0,(1-0.55-Header!$O$3)*Header!$Q$3*$AQ12),"") | AX12: =IF($A12="","",IF(TRIM(IF($A12="","Missing certificate ref. ","") & IF($C12="","Missing effective date. ","") & IF($D12="","Missing binding status. ","") & IF($E12="","Missing movement type. ","") & IF($I12="","Missing make. ","") & IF($L12="","Missing vehicle class. ","") & IF($M12="","Missing agreed value. ","") & IF($N12="","Missing policy type. ","") & IF($Q12="","Missing garaging state. ","") & IF($R12="","Missing garaging ZIP. ","") & IF($S12="","Missing cat zone. ","") & IF($V12="","Missing valuation basis. ","") & IF($W12="","Missing PD deductible. ","") & IF($X12="","Missing liability limit. ","") & IF($AB12="","Missing technical premium. ","") & IF($AF12="","Missing surplus lines tax %. ",""))="","PASS","FAIL: "&TRIM(IF($A12="","Missing certificate ref. ","") & IF($C12="","Missing effective date. ","") & IF($D12="","Missing binding status. ","") & IF($E12="","Missing movement type. ","") & IF($I12="","Missing make. ","") & IF($L12="","Missing vehicle class. ","") & IF($M12="","Missing agreed value. ","") & IF($N12="","Missing policy type. ","") & IF($Q12="","Missing garaging state. ","") & IF($R12="","Missing garaging ZIP. ","") & IF($S12="","Missing cat zone. ","") & IF($V12="","Missing valuation basis. ","") & IF($W12="","Missing PD deductible. ","") & IF($X12="","Missing liability limit. ","") & IF($AB12="","Missing technical premium. ","") & IF($AF12="","Missing surplus lines tax %. ","")))) | AY12: =IF($M12="","",IF(ISNUMBER($M12),IF($M12>=Header!$C$18,"YES — refer","No"),"")) | AZ12: =IF($AD12="","",IF(ISNUMBER($AD12),IF($AD12<Header!$C$20,"BELOW MIN PREMIUM","OK"),"")) | BE12: =IF(OR($A12="",$L12="",$H12=""),"",IF(AND(LEFT($L12,2)="06",$H12>1945),"FAIL - pre-war class, year "&$H12,IF(AND(LEFT($L12,2)="07",OR($H12<1946,$H12>1972)),"FAIL - 1946-72 class, year "&$H12,IF(AND(LEFT($L12,2)="08",OR($H12<1973,$H12>1999)),"FAIL - 1973-99 class, year "&$H12,IF(AND(LEFT($L12,2)="09",OR($H12<2000,$H12>2010)),"FAIL - 2000-10 class, year "&$H12,"OK"))))) | BF12: =IF($AD12="","",IF(ROUND($AO12+$AP12+$AQ12-$AD12,2)=0,"OK","FAIL - out by "&TEXT($AO12+$AP12+$AQ12-$AD12,"$0.00")))
G13: =IF($A13="","",IF($C13="","",YEAR($C13))) | T13: =IF($A13="","",IF($S13="","",IFERROR(INDEX(Lists!$N$5:$N$16,MATCH($S13,Lists!$M$5:$M$16,0)),"?"))) | AD13: =IF(ISNUMBER($AB13),$AB13*(1+N($AC13)),"") | AH13: =IF(ISNUMBER($AD13),($AD13+$AE13+$AF13)*$AG13,"") | AJ13: =IF(ISNUMBER($AD13),SUM($AD13:$AH13),"") | AK13: =IF(AND(ISNUMBER($AB13),ISNUMBER($AD13)),IF($AB13>0,$AD13/$AB13,""),"") | AM13: =IF(ISNUMBER($AD13),Header!$I$3,"") | AN13: =IF(ISNUMBER($AD13),$AO13+$AP13,"") | AO13: =IF(ISNUMBER($AD13),ROUND($AD13*Header!$K$3,2),"") | AP13: =IF(ISNUMBER($AD13),ROUND($AD13*Header!$M$3,2),"") | AQ13: =IF(ISNUMBER($AD13),ROUND($AD13,2)-$AO13-$AP13,"") | AR13: =IF(ISNUMBER($AD13),IF(Header!$D$34="","?",$AD13*Header!$D$34),"") | AS13: =IF(ISNUMBER($AB13),IF(Header!$D$34="","?",$AB13*Header!$D$34),"") | AT13: =IF(AND(ISNUMBER($AB13),$M13>0),$AB13/$M13*100,"") | AU13: =IF(AND(ISNUMBER($AD13),$M13>0),$AD13/$M13*100,"") | AV13: =IF(AND(ISNUMBER($AB13),ISNUMBER($AD13),ABS($AB13)>0),$AD13/$AB13,"") | AW13: =IF(ISNUMBER($AD13),MAX(0,(1-0.55-Header!$O$3)*Header!$Q$3*$AQ13),"") | AX13: =IF($A13="","",IF(TRIM(IF($A13="","Missing certificate ref. ","") & IF($C13="","Missing effective date. ","") & IF($D13="","Missing binding status. ","") & IF($E13="","Missing movement type. ","") & IF($I13="","Missing make. ","") & IF($L13="","Missing vehicle class. ","") & IF($M13="","Missing agreed value. ","") & IF($N13="","Missing policy type. ","") & IF($Q13="","Missing garaging state. ","") & IF($R13="","Missing garaging ZIP. ","") & IF($S13="","Missing cat zone. ","") & IF($V13="","Missing valuation basis. ","") & IF($W13="","Missing PD deductible. ","") & IF($X13="","Missing liability limit. ","") & IF($AB13="","Missing technical premium. ","") & IF($AF13="","Missing surplus lines tax %. ",""))="","PASS","FAIL: "&TRIM(IF($A13="","Missing certificate ref. ","") & IF($C13="","Missing effective date. ","") & IF($D13="","Missing binding status. ","") & IF($E13="","Missing movement type. ","") & IF($I13="","Missing make. ","") & IF($L13="","Missing vehicle class. ","") & IF($M13="","Missing agreed value. ","") & IF($N13="","Missing policy type. ","") & IF($Q13="","Missing garaging state. ","") & IF($R13="","Missing garaging ZIP. ","") & IF($S13="","Missing cat zone. ","") & IF($V13="","Missing valuation basis. ","") & IF($W13="","Missing PD deductible. ","") & IF($X13="","Missing liability limit. ","") & IF($AB13="","Missing technical premium. ","") & IF($AF13="","Missing surplus lines tax %. ","")))) | AY13: =IF($M13="","",IF(ISNUMBER($M13),IF($M13>=Header!$C$18,"YES — refer","No"),"")) | AZ13: =IF($AD13="","",IF(ISNUMBER($AD13),IF($AD13<Header!$C$20,"BELOW MIN PREMIUM","OK"),"")) | BE13: =IF(OR($A13="",$L13="",$H13=""),"",IF(AND(LEFT($L13,2)="06",$H13>1945),"FAIL - pre-war class, year "&$H13,IF(AND(LEFT($L13,2)="07",OR($H13<1946,$H13>1972)),"FAIL - 1946-72 class, year "&$H13,IF(AND(LEFT($L13,2)="08",OR($H13<1973,$H13>1999)),"FAIL - 1973-99 class, year "&$H13,IF(AND(LEFT($L13,2)="09",OR($H13<2000,$H13>2010)),"FAIL - 2000-10 class, year "&$H13,"OK"))))) | BF13: =IF($AD13="","",IF(ROUND($AO13+$AP13+$AQ13-$AD13,2)=0,"OK","FAIL - out by "&TEXT($AO13+$AP13+$AQ13-$AD13,"$0.00")))
G14: =IF($A14="","",IF($C14="","",YEAR($C14))) | T14: =IF($A14="","",IF($S14="","",IFERROR(INDEX(Lists!$N$5:$N$16,MATCH($S14,Lists!$M$5:$M$16,0)),"?"))) | AD14: =IF(ISNUMBER($AB14),$AB14*(1+N($AC14)),"") | AH14: =IF(ISNUMBER($AD14),($AD14+$AE14+$AF14)*$AG14,"") | AJ14: =IF(ISNUMBER($AD14),SUM($AD14:$AH14),"") | AK14: =IF(AND(ISNUMBER($AB14),ISNUMBER($AD14)),IF($AB14>0,$AD14/$AB14,""),"") | AM14: =IF(ISNUMBER($AD14),Header!$I$3,"") | AN14: =IF(ISNUMBER($AD14),$AO14+$AP14,"") | AO14: =IF(ISNUMBER($AD14),ROUND($AD14*Header!$K$3,2),"") | AP14: =IF(ISNUMBER($AD14),ROUND($AD14*Header!$M$3,2),"") | AQ14: =IF(ISNUMBER($AD14),ROUND($AD14,2)-$AO14-$AP14,"") | AR14: =IF(ISNUMBER($AD14),IF(Header!$D$34="","?",$AD14*Header!$D$34),"") | AS14: =IF(ISNUMBER($AB14),IF(Header!$D$34="","?",$AB14*Header!$D$34),"") | AT14: =IF(AND(ISNUMBER($AB14),$M14>0),$AB14/$M14*100,"") | AU14: =IF(AND(ISNUMBER($AD14),$M14>0),$AD14/$M14*100,"") | AV14: =IF(AND(ISNUMBER($AB14),ISNUMBER($AD14),ABS($AB14)>0),$AD14/$AB14,"") | AW14: =IF(ISNUMBER($AD14),MAX(0,(1-0.55-Header!$O$3)*Header!$Q$3*$AQ14),"") | AX14: =IF($A14="","",IF(TRIM(IF($A14="","Missing certificate ref. ","") & IF($C14="","Missing effective date. ","") & IF($D14="","Missing binding status. ","") & IF($E14="","Missing movement type. ","") & IF($I14="","Missing make. ","") & IF($L14="","Missing vehicle class. ","") & IF($M14="","Missing agreed value. ","") & IF($N14="","Missing policy type. ","") & IF($Q14="","Missing garaging state. ","") & IF($R14="","Missing garaging ZIP. ","") & IF($S14="","Missing cat zone. ","") & IF($V14="","Missing valuation basis. ","") & IF($W14="","Missing PD deductible. ","") & IF($X14="","Missing liability limit. ","") & IF($AB14="","Missing technical premium. ","") & IF($AF14="","Missing surplus lines tax %. ",""))="","PASS","FAIL: "&TRIM(IF($A14="","Missing certificate ref. ","") & IF($C14="","Missing effective date. ","") & IF($D14="","Missing binding status. ","") & IF($E14="","Missing movement type. ","") & IF($I14="","Missing make. ","") & IF($L14="","Missing vehicle class. ","") & IF($M14="","Missing agreed value. ","") & IF($N14="","Missing policy type. ","") & IF($Q14="","Missing garaging state. ","") & IF($R14="","Missing garaging ZIP. ","") & IF($S14="","Missing cat zone. ","") & IF($V14="","Missing valuation basis. ","") & IF($W14="","Missing PD deductible. ","") & IF($X14="","Missing liability limit. ","") & IF($AB14="","Missing technical premium. ","") & IF($AF14="","Missing surplus lines tax %. ","")))) | AY14: =IF($M14="","",IF(ISNUMBER($M14),IF($M14>=Header!$C$18,"YES — refer","No"),"")) | AZ14: =IF($AD14="","",IF(ISNUMBER($AD14),IF($AD14<Header!$C$20,"BELOW MIN PREMIUM","OK"),"")) | BE14: =IF(OR($A14="",$L14="",$H14=""),"",IF(AND(LEFT($L14,2)="06",$H14>1945),"FAIL - pre-war class, year "&$H14,IF(AND(LEFT($L14,2)="07",OR($H14<1946,$H14>1972)),"FAIL - 1946-72 class, year "&$H14,IF(AND(LEFT($L14,2)="08",OR($H14<1973,$H14>1999)),"FAIL - 1973-99 class, year "&$H14,IF(AND(LEFT($L14,2)="09",OR($H14<2000,$H14>2010)),"FAIL - 2000-10 class, year "&$H14,"OK"))))) | BF14: =IF($AD14="","",IF(ROUND($AO14+$AP14+$AQ14-$AD14,2)=0,"OK","FAIL - out by "&TEXT($AO14+$AP14+$AQ14-$AD14,"$0.00")))
G15: =IF($A15="","",IF($C15="","",YEAR($C15))) | T15: =IF($A15="","",IF($S15="","",IFERROR(INDEX(Lists!$N$5:$N$16,MATCH($S15,Lists!$M$5:$M$16,0)),"?"))) | AD15: =IF(ISNUMBER($AB15),$AB15*(1+N($AC15)),"") | AH15: =IF(ISNUMBER($AD15),($AD15+$AE15+$AF15)*$AG15,"") | AJ15: =IF(ISNUMBER($AD15),SUM($AD15:$AH15),"") | AK15: =IF(AND(ISNUMBER($AB15),ISNUMBER($AD15)),IF($AB15>0,$AD15/$AB15,""),"") | AM15: =IF(ISNUMBER($AD15),Header!$I$3,"") | AN15: =IF(ISNUMBER($AD15),$AO15+$AP15,"") | AO15: =IF(ISNUMBER($AD15),ROUND($AD15*Header!$K$3,2),"") | AP15: =IF(ISNUMBER($AD15),ROUND($AD15*Header!$M$3,2),"") | AQ15: =IF(ISNUMBER($AD15),ROUND($AD15,2)-$AO15-$AP15,"") | AR15: =IF(ISNUMBER($AD15),IF(Header!$D$34="","?",$AD15*Header!$D$34),"") | AS15: =IF(ISNUMBER($AB15),IF(Header!$D$34="","?",$AB15*Header!$D$34),"") | AT15: =IF(AND(ISNUMBER($AB15),$M15>0),$AB15/$M15*100,"") | AU15: =IF(AND(ISNUMBER($AD15),$M15>0),$AD15/$M15*100,"") | AV15: =IF(AND(ISNUMBER($AB15),ISNUMBER($AD15),ABS($AB15)>0),$AD15/$AB15,"") | AW15: =IF(ISNUMBER($AD15),MAX(0,(1-0.55-Header!$O$3)*Header!$Q$3*$AQ15),"") | AX15: =IF($A15="","",IF(TRIM(IF($A15="","Missing certificate ref. ","") & IF($C15="","Missing effective date. ","") & IF($D15="","Missing binding status. ","") & IF($E15="","Missing movement type. ","") & IF($I15="","Missing make. ","") & IF($L15="","Missing vehicle class. ","") & IF($M15="","Missing agreed value. ","") & IF($N15="","Missing policy type. ","") & IF($Q15="","Missing garaging state. ","") & IF($R15="","Missing garaging ZIP. ","") & IF($S15="","Missing cat zone. ","") & IF($V15="","Missing valuation basis. ","") & IF($W15="","Missing PD deductible. ","") & IF($X15="","Missing liability limit. ","") & IF($AB15="","Missing technical premium. ","") & IF($AF15="","Missing surplus lines tax %. ",""))="","PASS","FAIL: "&TRIM(IF($A15="","Missing certificate ref. ","") & IF($C15="","Missing effective date. ","") & IF($D15="","Missing binding status. ","") & IF($E15="","Missing movement type. ","") & IF($I15="","Missing make. ","") & IF($L15="","Missing vehicle class. ","") & IF($M15="","Missing agreed value. ","") & IF($N15="","Missing policy type. ","") & IF($Q15="","Missing garaging state. ","") & IF($R15="","Missing garaging ZIP. ","") & IF($S15="","Missing cat zone. ","") & IF($V15="","Missing valuation basis. ","") & IF($W15="","Missing PD deductible. ","") & IF($X15="","Missing liability limit. ","") & IF($AB15="","Missing technical premium. ","") & IF($AF15="","Missing surplus lines tax %. ","")))) | AY15: =IF($M15="","",IF(ISNUMBER($M15),IF($M15>=Header!$C$18,"YES — refer","No"),"")) | AZ15: =IF($AD15="","",IF(ISNUMBER($AD15),IF($AD15<Header!$C$20,"BELOW MIN PREMIUM","OK"),"")) | BE15: =IF(OR($A15="",$L15="",$H15=""),"",IF(AND(LEFT($L15,2)="06",$H15>1945),"FAIL - pre-war class, year "&$H15,IF(AND(LEFT($L15,2)="07",OR($H15<1946,$H15>1972)),"FAIL - 1946-72 class, year "&$H15,IF(AND(LEFT($L15,2)="08",OR($H15<1973,$H15>1999)),"FAIL - 1973-99 class, year "&$H15,IF(AND(LEFT($L15,2)="09",OR($H15<2000,$H15>2010)),"FAIL - 2000-10 class, year "&$H15,"OK"))))) | BF15: =IF($AD15="","",IF(ROUND($AO15+$AP15+$AQ15-$AD15,2)=0,"OK","FAIL - out by "&TEXT($AO15+$AP15+$AQ15-$AD15,"$0.00")))
G16: =IF($A16="","",IF($C16="","",YEAR($C16))) | T16: =IF($A16="","",IF($S16="","",IFERROR(INDEX(Lists!$N$5:$N$16,MATCH($S16,Lists!$M$5:$M$16,0)),"?"))) | AD16: =IF(ISNUMBER($AB16),$AB16*(1+N($AC16)),"") | AH16: =IF(ISNUMBER($AD16),($AD16+$AE16+$AF16)*$AG16,"") | AJ16: =IF(ISNUMBER($AD16),SUM($AD16:$AH16),"") | AK16: =IF(AND(ISNUMBER($AB16),ISNUMBER($AD16)),IF($AB16>0,$AD16/$AB16,""),"") | AM16: =IF(ISNUMBER($AD16),Header!$I$3,"") | AN16: =IF(ISNUMBER($AD16),$AO16+$AP16,"") | AO16: =IF(ISNUMBER($AD16),ROUND($AD16*Header!$K$3,2),"") | AP16: =IF(ISNUMBER($AD16),ROUND($AD16*Header!$M$3,2),"") | AQ16: =IF(ISNUMBER($AD16),ROUND($AD16,2)-$AO16-$AP16,"") | AR16: =IF(ISNUMBER($AD16),IF(Header!$D$34="","?",$AD16*Header!$D$34),"") | AS16: =IF(ISNUMBER($AB16),IF(Header!$D$34="","?",$AB16*Header!$D$34),"") | AT16: =IF(AND(ISNUMBER($AB16),$M16>0),$AB16/$M16*100,"") | AU16: =IF(AND(ISNUMBER($AD16),$M16>0),$AD16/$M16*100,"") | AV16: =IF(AND(ISNUMBER($AB16),ISNUMBER($AD16),ABS($AB16)>0),$AD16/$AB16,"") | AW16: =IF(ISNUMBER($AD16),MAX(0,(1-0.55-Header!$O$3)*Header!$Q$3*$AQ16),"") | AX16: =IF($A16="","",IF(TRIM(IF($A16="","Missing certificate ref. ","") & IF($C16="","Missing effective date. ","") & IF($D16="","Missing binding status. ","") & IF($E16="","Missing movement type. ","") & IF($I16="","Missing make. ","") & IF($L16="","Missing vehicle class. ","") & IF($M16="","Missing agreed value. ","") & IF($N16="","Missing policy type. ","") & IF($Q16="","Missing garaging state. ","") & IF($R16="","Missing garaging ZIP. ","") & IF($S16="","Missing cat zone. ","") & IF($V16="","Missing valuation basis. ","") & IF($W16="","Missing PD deductible. ","") & IF($X16="","Missing liability limit. ","") & IF($AB16="","Missing technical premium. ","") & IF($AF16="","Missing surplus lines tax %. ",""))="","PASS","FAIL: "&TRIM(IF($A16="","Missing certificate ref. ","") & IF($C16="","Missing effective date. ","") & IF($D16="","Missing binding status. ","") & IF($E16="","Missing movement type. ","") & IF($I16="","Missing make. ","") & IF($L16="","Missing vehicle class. ","") & IF($M16="","Missing agreed value. ","") & IF($N16="","Missing policy type. ","") & IF($Q16="","Missing garaging state. ","") & IF($R16="","Missing garaging ZIP. ","") & IF($S16="","Missing cat zone. ","") & IF($V16="","Missing valuation basis. ","") & IF($W16="","Missing PD deductible. ","") & IF($X16="","Missing liability limit. ","") & IF($AB16="","Missing technical premium. ","") & IF($AF16="","Missing surplus lines tax %. ","")))) | AY16: =IF($M16="","",IF(ISNUMBER($M16),IF($M16>=Header!$C$18,"YES — refer","No"),"")) | AZ16: =IF($AD16="","",IF(ISNUMBER($AD16),IF($AD16<Header!$C$20,"BELOW MIN PREMIUM","OK"),"")) | BE16: =IF(OR($A16="",$L16="",$H16=""),"",IF(AND(LEFT($L16,2)="06",$H16>1945),"FAIL - pre-war class, year "&$H16,IF(AND(LEFT($L16,2)="07",OR($H16<1946,$H16>1972)),"FAIL - 1946-72 class, year "&$H16,IF(AND(LEFT($L16,2)="08",OR($H16<1973,$H16>1999)),"FAIL - 1973-99 class, year "&$H16,IF(AND(LEFT($L16,2)="09",OR($H16<2000,$H16>2010)),"FAIL - 2000-10 class, year "&$H16,"OK"))))) | BF16: =IF($AD16="","",IF(ROUND($AO16+$AP16+$AQ16-$AD16,2)=0,"OK","FAIL - out by "&TEXT($AO16+$AP16+$AQ16-$AD16,"$0.00")))
G17: =IF($A17="","",IF($C17="","",YEAR($C17))) | T17: =IF($A17="","",IF($S17="","",IFERROR(INDEX(Lists!$N$5:$N$16,MATCH($S17,Lists!$M$5:$M$16,0)),"?"))) | AD17: =IF(ISNUMBER($AB17),$AB17*(1+N($AC17)),"") | AH17: =IF(ISNUMBER($AD17),($AD17+$AE17+$AF17)*$AG17,"") | AJ17: =IF(ISNUMBER($AD17),SUM($AD17:$AH17),"") | AK17: =IF(AND(ISNUMBER($AB17),ISNUMBER($AD17)),IF($AB17>0,$AD17/$AB17,""),"") | AM17: =IF(ISNUMBER($AD17),Header!$I$3,"") | AN17: =IF(ISNUMBER($AD17),$AO17+$AP17,"") | AO17: =IF(ISNUMBER($AD17),ROUND($AD17*Header!$K$3,2),"") | AP17: =IF(ISNUMBER($AD17),ROUND($AD17*Header!$M$3,2),"") | AQ17: =IF(ISNUMBER($AD17),ROUND($AD17,2)-$AO17-$AP17,"") | AR17: =IF(ISNUMBER($AD17),IF(Header!$D$34="","?",$AD17*Header!$D$34),"") | AS17: =IF(ISNUMBER($AB17),IF(Header!$D$34="","?",$AB17*Header!$D$34),"") | AT17: =IF(AND(ISNUMBER($AB17),$M17>0),$AB17/$M17*100,"") | AU17: =IF(AND(ISNUMBER($AD17),$M17>0),$AD17/$M17*100,"") | AV17: =IF(AND(ISNUMBER($AB17),ISNUMBER($AD17),ABS($AB17)>0),$AD17/$AB17,"") | AW17: =IF(ISNUMBER($AD17),MAX(0,(1-0.55-Header!$O$3)*Header!$Q$3*$AQ17),"") | AX17: =IF($A17="","",IF(TRIM(IF($A17="","Missing certificate ref. ","") & IF($C17="","Missing effective date. ","") & IF($D17="","Missing binding status. ","") & IF($E17="","Missing movement type. ","") & IF($I17="","Missing make. ","") & IF($L17="","Missing vehicle class. ","") & IF($M17="","Missing agreed value. ","") & IF($N17="","Missing policy type. ","") & IF($Q17="","Missing garaging state. ","") & IF($R17="","Missing garaging ZIP. ","") & IF($S17="","Missing cat zone. ","") & IF($V17="","Missing valuation basis. ","") & IF($W17="","Missing PD deductible. ","") & IF($X17="","Missing liability limit. ","") & IF($AB17="","Missing technical premium. ","") & IF($AF17="","Missing surplus lines tax %. ",""))="","PASS","FAIL: "&TRIM(IF($A17="","Missing certificate ref. ","") & IF($C17="","Missing effective date. ","") & IF($D17="","Missing binding status. ","") & IF($E17="","Missing movement type. ","") & IF($I17="","Missing make. ","") & IF($L17="","Missing vehicle class. ","") & IF($M17="","Missing agreed value. ","") & IF($N17="","Missing policy type. ","") & IF($Q17="","Missing garaging state. ","") & IF($R17="","Missing garaging ZIP. ","") & IF($S17="","Missing cat zone. ","") & IF($V17="","Missing valuation basis. ","") & IF($W17="","Missing PD deductible. ","") & IF($X17="","Missing liability limit. ","") & IF($AB17="","Missing technical premium. ","") & IF($AF17="","Missing surplus lines tax %. ","")))) | AY17: =IF($M17="","",IF(ISNUMBER($M17),IF($M17>=Header!$C$18,"YES — refer","No"),"")) | AZ17: =IF($AD17="","",IF(ISNUMBER($AD17),IF($AD17<Header!$C$20,"BELOW MIN PREMIUM","OK"),"")) | BE17: =IF(OR($A17="",$L17="",$H17=""),"",IF(AND(LEFT($L17,2)="06",$H17>1945),"FAIL - pre-war class, year "&$H17,IF(AND(LEFT($L17,2)="07",OR($H17<1946,$H17>1972)),"FAIL - 1946-72 class, year "&$H17,IF(AND(LEFT($L17,2)="08",OR($H17<1973,$H17>1999)),"FAIL - 1973-99 class, year "&$H17,IF(AND(LEFT($L17,2)="09",OR($H17<2000,$H17>2010)),"FAIL - 2000-10 class, year "&$H17,"OK"))))) | BF17: =IF($AD17="","",IF(ROUND($AO17+$AP17+$AQ17-$AD17,2)=0,"OK","FAIL - out by "&TEXT($AO17+$AP17+$AQ17-$AD17,"$0.00")))
