Workbook

Sheet README
A1: 03 · Underwriting BDX
A2: Source: canonical_dataset.json (ADR 0043), sha256 0a3d67e8774e8cd1… — verified against canonical_manifest.json. All figures derive read-only from that frozen artifact; no new numbers generated. Styling follows the MGA Program Master conventions (Arial; navy title banners; blue section headers; semantic tab colours; 1-dp percentages).
A8: Scope | C8: BOUND book only (6,089 policies). Indicative/declined excluded.
A9: Split | C9: 12.5% Broker + 12.5% Torque + 75% Markets; Markets = Σ ten syndicates (7.5% each).
A10: Fees | C10: $350 policy fee/policy; $250 inspection for AV ≥ $1M.
A11: Reconciliation | C11: See 'Annual Summary' — Δ rows foot to 0; premium = GWP $56,932,078.70.
A12: Rounding residual | C12: Explicit column; standard bordereau practice so the row foots exactly.

Sheet Annual Summary
A1: Underwriting BDX — Annual Summary
A2: Each row pulls that month tab's TOTAL row. Grand total ties to artifact GWP $56,932,078.70.
A4: Month | B4: Bound Premium | C4: Broker 12.5% | D4: Torque 12.5% | E4: Markets 75% | F4: Rounding Residual | G4: Beazley | H4: Hiscox | I4: Chaucer | J4: Ark | K4: Brit | L4: Canopius | M4: Apollo | N4: Antares | O4: MS Amlin | P4: Ascot | Q4: Policy Fee | R4: Inspection Fee | S4: Fee Total
A5: 2025-08 | B5: ='2025-08'!F412 | C5: ='2025-08'!G412 | D5: ='2025-08'!H412 | E5: ='2025-08'!I412 | F5: ='2025-08'!J412 | G5: ='2025-08'!K412 | H5: ='2025-08'!L412 | I5: ='2025-08'!M412 | ... S5: ='2025-08'!W412
A6: 2025-09 | B6: ='2025-09'!F382 | C6: ='2025-09'!G382 | D6: ='2025-09'!H382 | E6: ='2025-09'!I382 | F6: ='2025-09'!J382 | G6: ='2025-09'!K382 | H6: ='2025-09'!L382 | I6: ='2025-09'!M382 | ... S6: ='2025-09'!W382
A7: 2025-10 | B7: ='2025-10'!F482 | C7: ='2025-10'!G482 | D7: ='2025-10'!H482 | E7: ='2025-10'!I482 | F7: ='2025-10'!J482 | G7: ='2025-10'!K482 | H7: ='2025-10'!L482 | I7: ='2025-10'!M482 | ... S7: ='2025-10'!W482
A8: 2025-11 | B8: ='2025-11'!F460 | C8: ='2025-11'!G460 | D8: ='2025-11'!H460 | E8: ='2025-11'!I460 | F8: ='2025-11'!J460 | G8: ='2025-11'!K460 | H8: ='2025-11'!L460 | I8: ='2025-11'!M460 | ... S8: ='2025-11'!W460
A9: 2025-12 | B9: ='2025-12'!F498 | C9: ='2025-12'!G498 | D9: ='2025-12'!H498 | E9: ='2025-12'!I498 | F9: ='2025-12'!J498 | G9: ='2025-12'!K498 | H9: ='2025-12'!L498 | I9: ='2025-12'!M498 | ... S9: ='2025-12'!W498
A10: 2026-01 | B10: ='2026-01'!F504 | C10: ='2026-01'!G504 | D10: ='2026-01'!H504 | E10: ='2026-01'!I504 | F10: ='2026-01'!J504 | G10: ='2026-01'!K504 | H10: ='2026-01'!L504 | I10: ='2026-01'!M504 | ... S10: ='2026-01'!W504
A11: 2026-02 | B11: ='2026-02'!F505 | C11: ='2026-02'!G505 | D11: ='2026-02'!H505 | E11: ='2026-02'!I505 | F11: ='2026-02'!J505 | G11: ='2026-02'!K505 | H11: ='2026-02'!L505 | I11: ='2026-02'!M505 | ... S11: ='2026-02'!W505
A12: 2026-03 | B12: ='2026-03'!F589 | C12: ='2026-03'!G589 | D12: ='2026-03'!H589 | E12: ='2026-03'!I589 | F12: ='2026-03'!J589 | G12: ='2026-03'!K589 | H12: ='2026-03'!L589 | I12: ='2026-03'!M589 | ... S12: ='2026-03'!W589
A13: 2026-04 | B13: ='2026-04'!F551 | C13: ='2026-04'!G551 | D13: ='2026-04'!H551 | E13: ='2026-04'!I551 | F13: ='2026-04'!J551 | G13: ='2026-04'!K551 | H13: ='2026-04'!L551 | I13: ='2026-04'!M551 | ... S13: ='2026-04'!W551
A14: 2026-05 | B14: ='2026-05'!F551 | C14: ='2026-05'!G551 | D14: ='2026-05'!H551 | E14: ='2026-05'!I551 | F14: ='2026-05'!J551 | G14: ='2026-05'!K551 | H14: ='2026-05'!L551 | I14: ='2026-05'!M551 | ... S14: ='2026-05'!W551
A15: 2026-06 | B15: ='2026-06'!F656 | C15: ='2026-06'!G656 | D15: ='2026-06'!H656 | E15: ='2026-06'!I656 | F15: ='2026-06'!J656 | G15: ='2026-06'!K656 | H15: ='2026-06'!L656 | I15: ='2026-06'!M656 | ... S15: ='2026-06'!W656
A16: 2026-07 | B16: ='2026-07'!F559 | C16: ='2026-07'!G559 | D16: ='2026-07'!H559 | E16: ='2026-07'!I559 | F16: ='2026-07'!J559 | G16: ='2026-07'!K559 | H16: ='2026-07'!L559 | I16: ='2026-07'!M559 | ... S16: ='2026-07'!W559
A17: GRAND TOTAL | B17: =SUM(B5:B16) | C17: =SUM(C5:C16) | D17: =SUM(D5:D16) | E17: =SUM(E5:E16) | F17: =SUM(F5:F16) | G17: =SUM(G5:G16) | H17: =SUM(H5:H16) | I17: =SUM(I5:I16) | ... S17: =SUM(S5:S16)
A19: RECONCILIATION
A20: Annual bound premium (grand total) | C20: =B17
A21: Artifact GWP (bound) | D21: 56932079
A22: Δ premium vs GWP (must be 0) | C22: =B17-56932078.7
A23: Broker+Torque+Markets+Residual | C23: =C17+D17+E17+F17
A24: Δ split vs premium (must be 0) | C24: =(C17+D17+E17+F17)-B17
A25: Σ ten syndicate columns | C25: =SUM(G17:P17)
A26: Markets 75% (grand total) | C26: =E17
A27: Δ syndicates vs markets (must be 0) | C27: =SUM(G17:P17)-E17
A28: Per-syndicate total (each, from tabs) | C28: =G17
A29: memo: theoretical 0.075 × GWP | D29: 4269905.9
A30: Fee income (grand total) | C30: =S17
A31: artifact fee_income_total | D31: 2439650

Sheet 2025-08
A1: Underwriting BDX — 2025-08 (Bound book only)
A2: Indicative/declined premium excluded. Markets 75% = SUM of the ten syndicate columns (7.5% each). Residual = Premium − (Broker+Torque+Markets) so the row foots exactly.
A4: Policy Number | B4: Effective Date | C4: Insured | D4: State | E4: Agreed Value | F4: Bound Premium | G4: Broker 12.5% | H4: Torque 12.5% | I4: Markets 75% | J4: Rounding Residual | K4: Beazley | L4: Hiscox | M4: Chaucer | N4: Ark | O4: Brit | P4: Canopius | Q4: Apollo | R4: Antares | S4: MS Amlin | T4: Ascot | U4: Policy Fee | V4: Inspection Fee | W4: Fee Total
A5: CANON-202508-000003 | B5: 2025-08-20 | C5: Everett Delacroix | D5: KS | E5: 190000 | F5: 3199.17 | G5: 399.9 | H5: 399.9 | I5: =SUM(K5:T5) | J5: =F5-(G5+H5+I5) | K5: 239.94 | L5: 239.94 | M5: 239.94 | N5: 239.94 | O5: 239.94 | P5: 239.94 | Q5: 239.94 | R5: 239.94 | S5: 239.94 | T5: 239.94 | U5: 350 | V5: 0 | W5: =U5+V5
A6: CANON-202508-000004 | B6: 2025-08-16 | C6: Desmond Underwood | D6: NV | E6: 570000 | F6: 11953.87 | G6: 1494.23 | H6: 1494.23 | I6: =SUM(K6:T6) | J6: =F6-(G6+H6+I6) | K6: 896.54 | L6: 896.54 | M6: 896.54 | N6: 896.54 | O6: 896.54 | P6: 896.54 | Q6: 896.54 | R6: 896.54 | S6: 896.54 | T6: 896.54 | U6: 350 | V6: 0 | W6: =U6+V6
A7: CANON-202508-000008 | B7: 2025-08-10 | C7: Callum Rourke | D7: AL | E7: 750000 | F7: 17073.11 | G7: 2134.14 | H7: 2134.14 | I7: =SUM(K7:T7) | J7: =F7-(G7+H7+I7) | K7: 1280.48 | L7: 1280.48 | M7: 1280.48 | N7: 1280.48 | O7: 1280.48 | P7: 1280.48 | Q7: 1280.48 | R7: 1280.48 | S7: 1280.48 | T7: 1280.48 | U7: 350 | V7: 0 | W7: =U7+V7
A8: CANON-202508-000009 | B8: 2025-08-01 | C8: Ottilie Vandermeer | D8: NM | E8: 605000 | F8: 13880.75 | G8: 1735.09 | H8: 1735.09 | I8: =SUM(K8:T8) | J8: =F8-(G8+H8+I8) | K8: 1041.06 | L8: 1041.06 | M8: 1041.06 | N8: 1041.06 | O8: 1041.06 | P8: 1041.06 | Q8: 1041.06 | R8: 1041.06 | S8: 1041.06 | T8: 1041.06 | U8: 350 | V8: 0 | W8: =U8+V8
A9: CANON-202508-000011 | B9: 2025-08-05 | C9: Desmond Thistlewood | D9: OH | E9: 1950000 | F9: 40913.21 | G9: 5114.15 | H9: 5114.15 | I9: =SUM(K9:T9) | J9: =F9-(G9+H9+I9) | K9: 3068.49 | L9: 3068.49 | M9: 3068.49 | N9: 3068.49 | O9: 3068.49 | P9: 3068.49 | Q9: 3068.49 | R9: 3068.49 | S9: 3068.49 | T9: 3068.49 | U9: 350 | V9: 250 | W9: =U9+V9
A10: CANON-202508-000012 | B10: 2025-08-30 | C10: Callum Thistlewood | D10: CA | E10: 1415000 | F10: 19823.35 | G10: 2477.92 | H10: 2477.92 | I10: =SUM(K10:T10) | J10: =F10-(G10+H10+I10) | K10: 1486.75 | L10: 1486.75 | M10: 1486.75 | N10: 1486.75 | O10: 1486.75 | P10: 1486.75 | Q10: 1486.75 | R10: 1486.75 | S10: 1486.75 | T10: 1486.75 | U10: 350 | V10: 250 | W10: =U10+V10
A11: CANON-202508-000013 | B11: 2025-08-15 | C11: Leopold Fairweather | D11: NY | E11: 380000 | F11: 6883.02 | G11: 860.38 | H11: 860.38 | I11: =SUM(K11:T11) | J11: =F11-(G11+H11+I11) | K11: 516.23 | L11: 516.23 | M11: 516.23 | N11: 516.23 | O11: 516.23 | P11: 516.23 | Q11: 516.23 | R11: 516.23 | S11: 516.23 | T11: 516.23 | U11: 350 | V11: 0 | W11: =U11+V11
A12: CANON-202508-000014 | B12: 2025-08-07 | C12: Callum Montoya | D12: NV | E12: 1565000 | F12: 27638.49 | G12: 3454.81 | H12: 3454.81 | I12: =SUM(K12:T12) | J12: =F12-(G12+H12+I12) | K12: 2072.89 | L12: 2072.89 | M12: 2072.89 | N12: 2072.89 | O12: 2072.89 | P12: 2072.89 | Q12: 2072.89 | R12: 2072.89 | S12: 2072.89 | T12: 2072.89 | U12: 350 | V12: 250 | W12: =U12+V12
A13: CANON-202508-000018 | B13: 2025-08-15 | C13: Sunniva Blackwood | D13: IL | E13: 520000 | F13: 8673.21 | G13: 1084.15 | H13: 1084.15 | I13: =SUM(K13:T13) | J13: =F13-(G13+H13+I13) | K13: 650.49 | L13: 650.49 | M13: 650.49 | N13: 650.49 | O13: 650.49 | P13: 650.49 | Q13: 650.49 | R13: 650.49 | S13: 650.49 | T13: 650.49 | U13: 350 | V13: 0 | W13: =U13+V13
A14: CANON-202508-000020 | B14: 2025-08-15 | C14: Anouk Bellandi | D14: NC | E14: 1085000 | F14: 18833.96 | G14: 2354.24 | H14: 2354.24 | I14: =SUM(K14:T14) | J14: =F14-(G14+H14+I14) | K14: 1412.55 | L14: 1412.55 | M14: 1412.55 | N14: 1412.55 | O14: 1412.55 | P14: 1412.55 | Q14: 1412.55 | R14: 1412.55 | S14: 1412.55 | T14: 1412.55 | U14: 350 | V14: 250 | W14: =U14+V14
A15: CANON-202508-000021 | B15: 2025-08-27 | C15: Beatrix Castellanos | D15: AL | E15: 360000 | F15: 9920.38 | G15: 1240.05 | H15: 1240.05 | I15: =SUM(K15:T15) | J15: =F15-(G15+H15+I15) | K15: 744.03 | L15: 744.03 | M15: 744.03 | N15: 744.03 | O15: 744.03 | P15: 744.03 | Q15: 744.03 | R15: 744.03 | S15: 744.03 | T15: 744.03 | U15: 350 | V15: 0 | W15: =U15+V15
A16: CANON-202508-000023 | B16: 2025-08-13 | C16: Thaddeus Chattopadhyay | D16: DE | E16: 495000 | F16: 8755.9 | G16: 1094.49 | H16: 1094.49 | I16: =SUM(K16:T16) | J16: =F16-(G16+H16+I16) | K16: 656.69 | L16: 656.69 | M16: 656.69 | N16: 656.69 | O16: 656.69 | P16: 656.69 | Q16: 656.69 | R16: 656.69 | S16: 656.69 | T16: 656.69 | U16: 350 | V16: 0 | W16: =U16+V16
... A411: CANON-202508-000564 | B411: 2025-08-17 | C411: Horace Larsson | D411: MA | E411: 585000 | F411: 8968.16 | G411: 1121.02 | H411: 1121.02 | I411: =SUM(K411:T411) | J411: =F411-(G411+H411+I411) | K411: 672.61 | L411: 672.61 | M411: 672.61 | N411: 672.61 | O411: 672.61 | P411: 672.61 | Q411: 672.61 | R411: 672.61 | S411: 672.61 | T411: 672.61 | U411: 350 | V411: 0 | W411: =U411+V411
A412: TOTAL | E412: =SUM(E5:E411) | F412: =SUM(F5:F411) | G412: =SUM(G5:G411) | H412: =SUM(H5:H411) | I412: =SUM(I5:I411) | J412: =SUM(J5:J411) | K412: =SUM(K5:K411) | L412: =SUM(L5:L411) | ... W412: =SUM(W5:W411)
A413: Foot check: Premium − (B+T+M+Resid) | F413: =F412-(G412+H412+I412+J412)
A414: Foot check: Markets − Σ(10 syndicates) | I414: =I412-SUM(K412:T412)

Sheet 2025-09
A1: Underwriting BDX — 2025-09 (Bound book only)
A2: Indicative/declined premium excluded. Markets 75% = SUM of the ten syndicate columns (7.5% each). Residual = Premium − (Broker+Torque+Markets) so the row foots exactly.
A4: Policy Number | B4: Effective Date | C4: Insured | D4: State | E4: Agreed Value | F4: Bound Premium | G4: Broker 12.5% | H4: Torque 12.5% | I4: Markets 75% | J4: Rounding Residual | K4: Beazley | L4: Hiscox | M4: Chaucer | N4: Ark | O4: Brit | P4: Canopius | Q4: Apollo | R4: Antares | S4: MS Amlin | T4: Ascot | U4: Policy Fee | V4: Inspection Fee | W4: Fee Total
A5: CANON-202509-000565 | B5: 2025-09-11 | C5: Emiliano Vasquez | D5: ME | E5: 875000 | F5: 16245.89 | G5: 2030.74 | H5: 2030.74 | I5: =SUM(K5:T5) | J5: =F5-(G5+H5+I5) | K5: 1218.44 | L5: 1218.44 | M5: 1218.44 | N5: 1218.44 | O5: 1218.44 | P5: 1218.44 | Q5: 1218.44 | R5: 1218.44 | S5: 1218.44 | T5: 1218.44 | U5: 350 | V5: 0 | W5: =U5+V5
A6: CANON-202509-000566 | B6: 2025-09-14 | C6: Thaddeus Nakashima | D6: NC | E6: 345000 | F6: 5384.76 | G6: 673.1 | H6: 673.1 | I6: =SUM(K6:T6) | J6: =F6-(G6+H6+I6) | K6: 403.86 | L6: 403.86 | M6: 403.86 | N6: 403.86 | O6: 403.86 | P6: 403.86 | Q6: 403.86 | R6: 403.86 | S6: 403.86 | T6: 403.86 | U6: 350 | V6: 0 | W6: =U6+V6
A7: CANON-202509-000567 | B7: 2025-09-15 | C7: Leopold Okonkwo | D7: PA | E7: 925000 | F7: 15902.06 | G7: 1987.76 | H7: 1987.76 | I7: =SUM(K7:T7) | J7: =F7-(G7+H7+I7) | K7: 1192.65 | L7: 1192.65 | M7: 1192.65 | N7: 1192.65 | O7: 1192.65 | P7: 1192.65 | Q7: 1192.65 | R7: 1192.65 | S7: 1192.65 | T7: 1192.65 | U7: 350 | V7: 0 | W7: =U7+V7
A8: CANON-202509-000568 | B8: 2025-09-12 | C8: Mireille Vasquez | D8: IN | E8: 800000 | F8: 11574.34 | G8: 1446.79 | H8: 1446.79 | I8: =SUM(K8:T8) | J8: =F8-(G8+H8+I8) | K8: 868.08 | L8: 868.08 | M8: 868.08 | N8: 868.08 | O8: 868.08 | P8: 868.08 | Q8: 868.08 | R8: 868.08 | S8: 868.08 | T8: 868.08 | U8: 350 | V8: 0 | W8: =U8+V8
A9: CANON-202509-000569 | B9: 2025-09-09 | C9: Everett Merriweather | D9: KS | E9: 1145000 | F9: 11054.21 | G9: 1381.78 | H9: 1381.78 | I9: =SUM(K9:T9) | J9: =F9-(G9+H9+I9) | K9: 829.07 | L9: 829.07 | M9: 829.07 | N9: 829.07 | O9: 829.07 | P9: 829.07 | Q9: 829.07 | R9: 829.07 | S9: 829.07 | T9: 829.07 | U9: 350 | V9: 250 | W9: =U9+V9
A10: CANON-202509-000570 | B10: 2025-09-16 | C10: Everett Fairweather | D10: NC | E10: 270000 | F10: 4214.16 | G10: 526.77 | H10: 526.77 | I10: =SUM(K10:T10) | J10: =F10-(G10+H10+I10) | K10: 316.06 | L10: 316.06 | M10: 316.06 | N10: 316.06 | O10: 316.06 | P10: 316.06 | Q10: 316.06 | R10: 316.06 | S10: 316.06 | T10: 316.06 | U10: 350 | V10: 0 | W10: =U10+V10
A11: CANON-202509-000571 | B11: 2025-09-21 | C11: Lorenzo Fairweather | D11: MI | E11: 415000 | F11: 10243.55 | G11: 1280.44 | H11: 1280.44 | I11: =SUM(K11:T11) | J11: =F11-(G11+H11+I11) | K11: 768.27 | L11: 768.27 | M11: 768.27 | N11: 768.27 | O11: 768.27 | P11: 768.27 | Q11: 768.27 | R11: 768.27 | S11: 768.27 | T11: 768.27 | U11: 350 | V11: 0 | W11: =U11+V11
A12: CANON-202509-000572 | B12: 2025-09-08 | C12: Desmond Thistlewood | D12: DE | E12: 1050000 | F12: 19001.04 | G12: 2375.13 | H12: 2375.13 | I12: =SUM(K12:T12) | J12: =F12-(G12+H12+I12) | K12: 1425.08 | L12: 1425.08 | M12: 1425.08 | N12: 1425.08 | O12: 1425.08 | P12: 1425.08 | Q12: 1425.08 | R12: 1425.08 | S12: 1425.08 | T12: 1425.08 | U12: 350 | V12: 250 | W12: =U12+V12
A13: CANON-202509-000573 | B13: 2025-09-29 | C13: Mireille Delacroix | D13: IL | E13: 1145000 | F13: 10708.19 | G13: 1338.52 | H13: 1338.52 | I13: =SUM(K13:T13) | J13: =F13-(G13+H13+I13) | K13: 803.11 | L13: 803.11 | M13: 803.11 | N13: 803.11 | O13: 803.11 | P13: 803.11 | Q13: 803.11 | R13: 803.11 | S13: 803.11 | T13: 803.11 | U13: 350 | V13: 250 | W13: =U13+V13
A14: CANON-202509-000575 | B14: 2025-09-17 | C14: Saoirse Delacroix | D14: ID | E14: 1130000 | F14: 11134.34 | G14: 1391.79 | H14: 1391.79 | I14: =SUM(K14:T14) | J14: =F14-(G14+H14+I14) | K14: 835.08 | L14: 835.08 | M14: 835.08 | N14: 835.08 | O14: 835.08 | P14: 835.08 | Q14: 835.08 | R14: 835.08 | S14: 835.08 | T14: 835.08 | U14: 350 | V14: 250 | W14: =U14+V14
A15: CANON-202509-000576 | B15: 2025-09-15 | C15: Cassius Delacroix | D15: AR | E15: 500000 | F15: 8116.15 | G15: 1014.52 | H15: 1014.52 | I15: =SUM(K15:T15) | J15: =F15-(G15+H15+I15) | K15: 608.71 | L15: 608.71 | M15: 608.71 | N15: 608.71 | O15: 608.71 | P15: 608.71 | Q15: 608.71 | R15: 608.71 | S15: 608.71 | T15: 608.71 | U15: 350 | V15: 0 | W15: =U15+V15
A16: CANON-202509-000579 | B16: 2025-09-23 | C16: Fitzgerald Bellandi | D16: MT | E16: 605000 | F16: 9672.75 | G16: 1209.09 | H16: 1209.09 | I16: =SUM(K16:T16) | J16: =F16-(G16+H16+I16) | K16: 725.46 | L16: 725.46 | M16: 725.46 | N16: 725.46 | O16: 725.46 | P16: 725.46 | Q16: 725.46 | R16: 725.46 | S16: 725.46 | T16: 725.46 | U16: 350 | V16: 0 | W16: =U16+V16
... A381: CANON-202509-001091 | B381: 2025-09-05 | C381: Ingrid Harrington | D381: VA | E381: 480000 | F381: 7100.96 | G381: 887.62 | H381: 887.62 | I381: =SUM(K381:T381) | J381: =F381-(G381+H381+I381) | K381: 532.57 | L381: 532.57 | M381: 532.57 | N381: 532.57 | O381: 532.57 | P381: 532.57 | Q381: 532.57 | R381: 532.57 | S381: 532.57 | T381: 532.57 | U381: 350 | V381: 0 | W381: =U381+V381
A382: TOTAL | E382: =SUM(E5:E381) | F382: =SUM(F5:F381) | G382: =SUM(G5:G381) | H382: =SUM(H5:H381) | I382: =SUM(I5:I381) | J382: =SUM(J5:J381) | K382: =SUM(K5:K381) | L382: =SUM(L5:L381) | ... W382: =SUM(W5:W381)
A383: Foot check: Premium − (B+T+M+Resid) | F383: =F382-(G382+H382+I382+J382)
A384: Foot check: Markets − Σ(10 syndicates) | I384: =I382-SUM(K382:T382)

Sheet 2025-10
A1: Underwriting BDX — 2025-10 (Bound book only)
A2: Indicative/declined premium excluded. Markets 75% = SUM of the ten syndicate columns (7.5% each). Residual = Premium − (Broker+Torque+Markets) so the row foots exactly.
A4: Policy Number | B4: Effective Date | C4: Insured | D4: State | E4: Agreed Value | F4: Bound Premium | G4: Broker 12.5% | H4: Torque 12.5% | I4: Markets 75% | J4: Rounding Residual | K4: Beazley | L4: Hiscox | M4: Chaucer | N4: Ark | O4: Brit | P4: Canopius | Q4: Apollo | R4: Antares | S4: MS Amlin | T4: Ascot | U4: Policy Fee | V4: Inspection Fee | W4: Fee Total
A5: CANON-202510-001092 | B5: 2025-10-17 | C5: Lorenzo Thistlewood | D5: MA | E5: 355000 | F5: 7140.25 | G5: 892.53 | H5: 892.53 | I5: =SUM(K5:T5) | J5: =F5-(G5+H5+I5) | K5: 535.52 | L5: 535.52 | M5: 535.52 | N5: 535.52 | O5: 535.52 | P5: 535.52 | Q5: 535.52 | R5: 535.52 | S5: 535.52 | T5: 535.52 | U5: 350 | V5: 0 | W5: =U5+V5
A6: CANON-202510-001093 | B6: 2025-10-27 | C6: Beatrix Castellanos | D6: AK | E6: 465000 | F6: 7269.63 | G6: 908.7 | H6: 908.7 | I6: =SUM(K6:T6) | J6: =F6-(G6+H6+I6) | K6: 545.22 | L6: 545.22 | M6: 545.22 | N6: 545.22 | O6: 545.22 | P6: 545.22 | Q6: 545.22 | R6: 545.22 | S6: 545.22 | T6: 545.22 | U6: 350 | V6: 0 | W6: =U6+V6
A7: CANON-202510-001095 | B7: 2025-10-02 | C7: Wilhelmina Harrington | D7: CO | E7: 720000 | F7: 9413.07 | G7: 1176.63 | H7: 1176.63 | I7: =SUM(K7:T7) | J7: =F7-(G7+H7+I7) | K7: 705.98 | L7: 705.98 | M7: 705.98 | N7: 705.98 | O7: 705.98 | P7: 705.98 | Q7: 705.98 | R7: 705.98 | S7: 705.98 | T7: 705.98 | U7: 350 | V7: 0 | W7: =U7+V7
A8: CANON-202510-001096 | B8: 2025-10-02 | C8: Saoirse Rourke | D8: KY | E8: 325000 | F8: 5972.31 | G8: 746.54 | H8: 746.54 | I8: =SUM(K8:T8) | J8: =F8-(G8+H8+I8) | K8: 447.92 | L8: 447.92 | M8: 447.92 | N8: 447.92 | O8: 447.92 | P8: 447.92 | Q8: 447.92 | R8: 447.92 | S8: 447.92 | T8: 447.92 | U8: 350 | V8: 0 | W8: =U8+V8
A9: CANON-202510-001097 | B9: 2025-10-27 | C9: Cassius Bellandi | D9: CO | E9: 1140000 | F9: 12611.1 | G9: 1576.39 | H9: 1576.39 | I9: =SUM(K9:T9) | J9: =F9-(G9+H9+I9) | K9: 945.83 | L9: 945.83 | M9: 945.83 | N9: 945.83 | O9: 945.83 | P9: 945.83 | Q9: 945.83 | R9: 945.83 | S9: 945.83 | T9: 945.83 | U9: 350 | V9: 250 | W9: =U9+V9
A10: CANON-202510-001099 | B10: 2025-10-09 | C10: Emiliano Kingsford | D10: IN | E10: 1805000 | F10: 32476.19 | G10: 4059.52 | H10: 4059.52 | I10: =SUM(K10:T10) | J10: =F10-(G10+H10+I10) | K10: 2435.71 | L10: 2435.71 | M10: 2435.71 | N10: 2435.71 | O10: 2435.71 | P10: 2435.71 | Q10: 2435.71 | R10: 2435.71 | S10: 2435.71 | T10: 2435.71 | U10: 350 | V10: 250 | W10: =U10+V10
A11: CANON-202510-001100 | B11: 2025-10-05 | C11: Mireille Rourke | D11: IA | E11: 275000 | F11: 4148.39 | G11: 518.55 | H11: 518.55 | I11: =SUM(K11:T11) | J11: =F11-(G11+H11+I11) | K11: 311.13 | L11: 311.13 | M11: 311.13 | N11: 311.13 | O11: 311.13 | P11: 311.13 | Q11: 311.13 | R11: 311.13 | S11: 311.13 | T11: 311.13 | U11: 350 | V11: 0 | W11: =U11+V11
A12: CANON-202510-001101 | B12: 2025-10-24 | C12: Aurelio Fairweather | D12: MT | E12: 200000 | F12: 3128.91 | G12: 391.11 | H12: 391.11 | I12: =SUM(K12:T12) | J12: =F12-(G12+H12+I12) | K12: 234.67 | L12: 234.67 | M12: 234.67 | N12: 234.67 | O12: 234.67 | P12: 234.67 | Q12: 234.67 | R12: 234.67 | S12: 234.67 | T12: 234.67 | U12: 350 | V12: 0 | W12: =U12+V12
A13: CANON-202510-001103 | B13: 2025-10-18 | C13: Mireille Ashcombe | D13: NJ | E13: 900000 | F13: 14226.57 | G13: 1778.32 | H13: 1778.32 | I13: =SUM(K13:T13) | J13: =F13-(G13+H13+I13) | K13: 1066.99 | L13: 1066.99 | M13: 1066.99 | N13: 1066.99 | O13: 1066.99 | P13: 1066.99 | Q13: 1066.99 | R13: 1066.99 | S13: 1066.99 | T13: 1066.99 | U13: 350 | V13: 0 | W13: =U13+V13
A14: CANON-202510-001104 | B14: 2025-10-08 | C14: Marisol Whitlock | D14: KS | E14: 360000 | F14: 4788.82 | G14: 598.6 | H14: 598.6 | I14: =SUM(K14:T14) | J14: =F14-(G14+H14+I14) | K14: 359.16 | L14: 359.16 | M14: 359.16 | N14: 359.16 | O14: 359.16 | P14: 359.16 | Q14: 359.16 | R14: 359.16 | S14: 359.16 | T14: 359.16 | U14: 350 | V14: 0 | W14: =U14+V14
A15: CANON-202510-001106 | B15: 2025-10-10 | C15: Anouk Castellanos | D15: DE | E15: 1480000 | F15: 23002.41 | G15: 2875.3 | H15: 2875.3 | I15: =SUM(K15:T15) | J15: =F15-(G15+H15+I15) | K15: 1725.18 | L15: 1725.18 | M15: 1725.18 | N15: 1725.18 | O15: 1725.18 | P15: 1725.18 | Q15: 1725.18 | R15: 1725.18 | S15: 1725.18 | T15: 1725.18 | U15: 350 | V15: 250 | W15: =U15+V15
A16: CANON-202510-001107 | B16: 2025-10-22 | C16: Desmond Castellanos | D16: NM | E16: 705000 | F16: 10725.19 | G16: 1340.65 | H16: 1340.65 | I16: =SUM(K16:T16) | J16: =F16-(G16+H16+I16) | K16: 804.39 | L16: 804.39 | M16: 804.39 | N16: 804.39 | O16: 804.39 | P16: 804.39 | Q16: 804.39 | R16: 804.39 | S16: 804.39 | T16: 804.39 | U16: 350 | V16: 0 | W16: =U16+V16
... A481: CANON-202510-001733 | B481: 2025-10-02 | C481: Noor Pennington | D481: OR | E481: 1415000 | F481: 9940.47 | G481: 1242.56 | H481: 1242.56 | I481: =SUM(K481:T481) | J481: =F481-(G481+H481+I481) | K481: 745.54 | L481: 745.54 | M481: 745.54 | N481: 745.54 | O481: 745.54 | P481: 745.54 | Q481: 745.54 | R481: 745.54 | S481: 745.54 | T481: 745.54 | U481: 350 | V481: 250 | W481: =U481+V481
A482: TOTAL | E482: =SUM(E5:E481) | F482: =SUM(F5:F481) | G482: =SUM(G5:G481) | H482: =SUM(H5:H481) | I482: =SUM(I5:I481) | J482: =SUM(J5:J481) | K482: =SUM(K5:K481) | L482: =SUM(L5:L481) | ... W482: =SUM(W5:W481)
A483: Foot check: Premium − (B+T+M+Resid) | F483: =F482-(G482+H482+I482+J482)
A484: Foot check: Markets − Σ(10 syndicates) | I484: =I482-SUM(K482:T482)

Sheet 2025-11
A1: Underwriting BDX — 2025-11 (Bound book only)
A2: Indicative/declined premium excluded. Markets 75% = SUM of the ten syndicate columns (7.5% each). Residual = Premium − (Broker+Torque+Markets) so the row foots exactly.
A4: Policy Number | B4: Effective Date | C4: Insured | D4: State | E4: Agreed Value | F4: Bound Premium | G4: Broker 12.5% | H4: Torque 12.5% | I4: Markets 75% | J4: Rounding Residual | K4: Beazley | L4: Hiscox | M4: Chaucer | N4: Ark | O4: Brit | P4: Canopius | Q4: Apollo | R4: Antares | S4: MS Amlin | T4: Ascot | U4: Policy Fee | V4: Inspection Fee | W4: Fee Total
A5: CANON-202511-001734 | B5: 2025-11-12 | C5: Leopold Ashcombe | D5: NE | E5: 230000 | F5: 4771.86 | G5: 596.48 | H5: 596.48 | I5: =SUM(K5:T5) | J5: =F5-(G5+H5+I5) | K5: 357.89 | L5: 357.89 | M5: 357.89 | N5: 357.89 | O5: 357.89 | P5: 357.89 | Q5: 357.89 | R5: 357.89 | S5: 357.89 | T5: 357.89 | U5: 350 | V5: 0 | W5: =U5+V5
A6: CANON-202511-001736 | B6: 2025-11-08 | C6: Beatrix Delacroix | D6: NE | E6: 175000 | F6: 3630.77 | G6: 453.85 | H6: 453.85 | I6: =SUM(K6:T6) | J6: =F6-(G6+H6+I6) | K6: 272.31 | L6: 272.31 | M6: 272.31 | N6: 272.31 | O6: 272.31 | P6: 272.31 | Q6: 272.31 | R6: 272.31 | S6: 272.31 | T6: 272.31 | U6: 350 | V6: 0 | W6: =U6+V6
A7: CANON-202511-001738 | B7: 2025-11-20 | C7: Thaddeus Whitlock | D7: MI | E7: 670000 | F7: 11709.77 | G7: 1463.72 | H7: 1463.72 | I7: =SUM(K7:T7) | J7: =F7-(G7+H7+I7) | K7: 878.23 | L7: 878.23 | M7: 878.23 | N7: 878.23 | O7: 878.23 | P7: 878.23 | Q7: 878.23 | R7: 878.23 | S7: 878.23 | T7: 878.23 | U7: 350 | V7: 0 | W7: =U7+V7
A8: CANON-202511-001739 | B8: 2025-11-23 | C8: Fitzgerald Thistlewood | D8: NY | E8: 555000 | F8: 8010.23 | G8: 1001.28 | H8: 1001.28 | I8: =SUM(K8:T8) | J8: =F8-(G8+H8+I8) | K8: 600.77 | L8: 600.77 | M8: 600.77 | N8: 600.77 | O8: 600.77 | P8: 600.77 | Q8: 600.77 | R8: 600.77 | S8: 600.77 | T8: 600.77 | U8: 350 | V8: 0 | W8: =U8+V8
A9: CANON-202511-001740 | B9: 2025-11-12 | C9: Callum Thistlewood | D9: RI | E9: 645000 | F9: 9963.74 | G9: 1245.47 | H9: 1245.47 | I9: =SUM(K9:T9) | J9: =F9-(G9+H9+I9) | K9: 747.28 | L9: 747.28 | M9: 747.28 | N9: 747.28 | O9: 747.28 | P9: 747.28 | Q9: 747.28 | R9: 747.28 | S9: 747.28 | T9: 747.28 | U9: 350 | V9: 0 | W9: =U9+V9
A10: CANON-202511-001741 | B10: 2025-11-11 | C10: Ottilie Montoya | D10: AL | E10: 415000 | F10: 6857.12 | G10: 857.14 | H10: 857.14 | I10: =SUM(K10:T10) | J10: =F10-(G10+H10+I10) | K10: 514.28 | L10: 514.28 | M10: 514.28 | N10: 514.28 | O10: 514.28 | P10: 514.28 | Q10: 514.28 | R10: 514.28 | S10: 514.28 | T10: 514.28 | U10: 350 | V10: 0 | W10: =U10+V10
A11: CANON-202511-001742 | B11: 2025-11-30 | C11: Saoirse Larsson | D11: NC | E11: 1050000 | F11: 16757.37 | G11: 2094.67 | H11: 2094.67 | I11: =SUM(K11:T11) | J11: =F11-(G11+H11+I11) | K11: 1256.8 | L11: 1256.8 | M11: 1256.8 | N11: 1256.8 | O11: 1256.8 | P11: 1256.8 | Q11: 1256.8 | R11: 1256.8 | S11: 1256.8 | T11: 1256.8 | U11: 350 | V11: 250 | W11: =U11+V11
A12: CANON-202511-001744 | B12: 2025-11-11 | C12: Wilhelmina Delacroix | D12: IL | E12: 115000 | F12: 1546.47 | G12: 193.31 | H12: 193.31 | I12: =SUM(K12:T12) | J12: =F12-(G12+H12+I12) | K12: 115.99 | L12: 115.99 | M12: 115.99 | N12: 115.99 | O12: 115.99 | P12: 115.99 | Q12: 115.99 | R12: 115.99 | S12: 115.99 | T12: 115.99 | U12: 350 | V12: 0 | W12: =U12+V12
A13: CANON-202511-001745 | B13: 2025-11-12 | C13: Noor Pennington | D13: NY | E13: 140000 | F13: 3264.04 | G13: 408 | H13: 408 | I13: =SUM(K13:T13) | J13: =F13-(G13+H13+I13) | K13: 244.8 | L13: 244.8 | M13: 244.8 | N13: 244.8 | O13: 244.8 | P13: 244.8 | Q13: 244.8 | R13: 244.8 | S13: 244.8 | T13: 244.8 | U13: 350 | V13: 0 | W13: =U13+V13
A14: CANON-202511-001746 | B14: 2025-11-24 | C14: Marisol Chattopadhyay | D14: PA | E14: 665000 | F14: 10959.07 | G14: 1369.88 | H14: 1369.88 | I14: =SUM(K14:T14) | J14: =F14-(G14+H14+I14) | K14: 821.93 | L14: 821.93 | M14: 821.93 | N14: 821.93 | O14: 821.93 | P14: 821.93 | Q14: 821.93 | R14: 821.93 | S14: 821.93 | T14: 821.93 | U14: 350 | V14: 0 | W14: =U14+V14
A15: CANON-202511-001747 | B15: 2025-11-15 | C15: Anouk Bellandi | D15: TX | E15: 845000 | F15: 10957.12 | G15: 1369.64 | H15: 1369.64 | I15: =SUM(K15:T15) | J15: =F15-(G15+H15+I15) | K15: 821.78 | L15: 821.78 | M15: 821.78 | N15: 821.78 | O15: 821.78 | P15: 821.78 | Q15: 821.78 | R15: 821.78 | S15: 821.78 | T15: 821.78 | U15: 350 | V15: 0 | W15: =U15+V15
A16: CANON-202511-001748 | B16: 2025-11-17 | C16: Lorenzo Castellanos | D16: FL | E16: 420000 | F16: 7759.39 | G16: 969.92 | H16: 969.92 | I16: =SUM(K16:T16) | J16: =F16-(G16+H16+I16) | K16: 581.95 | L16: 581.95 | M16: 581.95 | N16: 581.95 | O16: 581.95 | P16: 581.95 | Q16: 581.95 | R16: 581.95 | S16: 581.95 | T16: 581.95 | U16: 350 | V16: 0 | W16: =U16+V16
... A459: CANON-202511-002365 | B459: 2025-11-17 | C459: Noor Merriweather | D459: TX | E459: 205000 | F459: 5807.22 | G459: 725.9 | H459: 725.9 | I459: =SUM(K459:T459) | J459: =F459-(G459+H459+I459) | K459: 435.54 | L459: 435.54 | M459: 435.54 | N459: 435.54 | O459: 435.54 | P459: 435.54 | Q459: 435.54 | R459: 435.54 | S459: 435.54 | T459: 435.54 | U459: 350 | V459: 0 | W459: =U459+V459
A460: TOTAL | E460: =SUM(E5:E459) | F460: =SUM(F5:F459) | G460: =SUM(G5:G459) | H460: =SUM(H5:H459) | I460: =SUM(I5:I459) | J460: =SUM(J5:J459) | K460: =SUM(K5:K459) | L460: =SUM(L5:L459) | ... W460: =SUM(W5:W459)
A461: Foot check: Premium − (B+T+M+Resid) | F461: =F460-(G460+H460+I460+J460)
A462: Foot check: Markets − Σ(10 syndicates) | I462: =I460-SUM(K460:T460)

Sheet 2025-12
A1: Underwriting BDX — 2025-12 (Bound book only)
A2: Indicative/declined premium excluded. Markets 75% = SUM of the ten syndicate columns (7.5% each). Residual = Premium − (Broker+Torque+Markets) so the row foots exactly.
A4: Policy Number | B4: Effective Date | C4: Insured | D4: State | E4: Agreed Value | F4: Bound Premium | G4: Broker 12.5% | H4: Torque 12.5% | I4: Markets 75% | J4: Rounding Residual | K4: Beazley | L4: Hiscox | M4: Chaucer | N4: Ark | O4: Brit | P4: Canopius | Q4: Apollo | R4: Antares | S4: MS Amlin | T4: Ascot | U4: Policy Fee | V4: Inspection Fee | W4: Fee Total
A5: CANON-202512-002366 | B5: 2025-12-12 | C5: Everett Whitlock | D5: RI | E5: 805000 | F5: 12398.84 | G5: 1549.86 | H5: 1549.86 | I5: =SUM(K5:T5) | J5: =F5-(G5+H5+I5) | K5: 929.91 | L5: 929.91 | M5: 929.91 | N5: 929.91 | O5: 929.91 | P5: 929.91 | Q5: 929.91 | R5: 929.91 | S5: 929.91 | T5: 929.91 | U5: 350 | V5: 0 | W5: =U5+V5
A6: CANON-202512-002368 | B6: 2025-12-19 | C6: Horace Farkas | D6: NE | E6: 910000 | F6: 8798.41 | G6: 1099.8 | H6: 1099.8 | I6: =SUM(K6:T6) | J6: =F6-(G6+H6+I6) | K6: 659.88 | L6: 659.88 | M6: 659.88 | N6: 659.88 | O6: 659.88 | P6: 659.88 | Q6: 659.88 | R6: 659.88 | S6: 659.88 | T6: 659.88 | U6: 350 | V6: 0 | W6: =U6+V6
A7: CANON-202512-002370 | B7: 2025-12-07 | C7: Ottilie Larsson | D7: AL | E7: 440000 | F7: 7248.85 | G7: 906.11 | H7: 906.11 | I7: =SUM(K7:T7) | J7: =F7-(G7+H7+I7) | K7: 543.66 | L7: 543.66 | M7: 543.66 | N7: 543.66 | O7: 543.66 | P7: 543.66 | Q7: 543.66 | R7: 543.66 | S7: 543.66 | T7: 543.66 | U7: 350 | V7: 0 | W7: =U7+V7
A8: CANON-202512-002373 | B8: 2025-12-03 | C8: Everett Chattopadhyay | D8: WA | E8: 445000 | F8: 5541.71 | G8: 692.71 | H8: 692.71 | I8: =SUM(K8:T8) | J8: =F8-(G8+H8+I8) | K8: 415.63 | L8: 415.63 | M8: 415.63 | N8: 415.63 | O8: 415.63 | P8: 415.63 | Q8: 415.63 | R8: 415.63 | S8: 415.63 | T8: 415.63 | U8: 350 | V8: 0 | W8: =U8+V8
A9: CANON-202512-002374 | B9: 2025-12-07 | C9: Priya Okonkwo | D9: SD | E9: 320000 | F9: 7065.16 | G9: 883.14 | H9: 883.14 | I9: =SUM(K9:T9) | J9: =F9-(G9+H9+I9) | K9: 529.89 | L9: 529.89 | M9: 529.89 | N9: 529.89 | O9: 529.89 | P9: 529.89 | Q9: 529.89 | R9: 529.89 | S9: 529.89 | T9: 529.89 | U9: 350 | V9: 0 | W9: =U9+V9
A10: CANON-202512-002380 | B10: 2025-12-25 | C10: Horace Chattopadhyay | D10: NM | E10: 600000 | F10: 8634.28 | G10: 1079.29 | H10: 1079.29 | I10: =SUM(K10:T10) | J10: =F10-(G10+H10+I10) | K10: 647.57 | L10: 647.57 | M10: 647.57 | N10: 647.57 | O10: 647.57 | P10: 647.57 | Q10: 647.57 | R10: 647.57 | S10: 647.57 | T10: 647.57 | U10: 350 | V10: 0 | W10: =U10+V10
A11: CANON-202512-002381 | B11: 2025-12-26 | C11: Aurelio Fairweather | D11: NY | E11: 600000 | F11: 5047.74 | G11: 630.97 | H11: 630.97 | I11: =SUM(K11:T11) | J11: =F11-(G11+H11+I11) | K11: 378.58 | L11: 378.58 | M11: 378.58 | N11: 378.58 | O11: 378.58 | P11: 378.58 | Q11: 378.58 | R11: 378.58 | S11: 378.58 | T11: 378.58 | U11: 350 | V11: 0 | W11: =U11+V11
A12: CANON-202512-002382 | B12: 2025-12-24 | C12: Mireille Blackwood | D12: WY | E12: 315000 | F12: 4372.27 | G12: 546.53 | H12: 546.53 | I12: =SUM(K12:T12) | J12: =F12-(G12+H12+I12) | K12: 327.92 | L12: 327.92 | M12: 327.92 | N12: 327.92 | O12: 327.92 | P12: 327.92 | Q12: 327.92 | R12: 327.92 | S12: 327.92 | T12: 327.92 | U12: 350 | V12: 0 | W12: =U12+V12
A13: CANON-202512-002383 | B13: 2025-12-18 | C13: Noor Vasquez | D13: WY | E13: 1090000 | F13: 11094.92 | G13: 1386.87 | H13: 1386.87 | I13: =SUM(K13:T13) | J13: =F13-(G13+H13+I13) | K13: 832.12 | L13: 832.12 | M13: 832.12 | N13: 832.12 | O13: 832.12 | P13: 832.12 | Q13: 832.12 | R13: 832.12 | S13: 832.12 | T13: 832.12 | U13: 350 | V13: 250 | W13: =U13+V13
A14: CANON-202512-002385 | B14: 2025-12-05 | C14: Fenwick Farkas | D14: AR | E14: 220000 | F14: 4831.05 | G14: 603.88 | H14: 603.88 | I14: =SUM(K14:T14) | J14: =F14-(G14+H14+I14) | K14: 362.33 | L14: 362.33 | M14: 362.33 | N14: 362.33 | O14: 362.33 | P14: 362.33 | Q14: 362.33 | R14: 362.33 | S14: 362.33 | T14: 362.33 | U14: 350 | V14: 0 | W14: =U14+V14
A15: CANON-202512-002387 | B15: 2025-12-04 | C15: Callum Underwood | D15: PA | E15: 480000 | F15: 7305.92 | G15: 913.24 | H15: 913.24 | I15: =SUM(K15:T15) | J15: =F15-(G15+H15+I15) | K15: 547.94 | L15: 547.94 | M15: 547.94 | N15: 547.94 | O15: 547.94 | P15: 547.94 | Q15: 547.94 | R15: 547.94 | S15: 547.94 | T15: 547.94 | U15: 350 | V15: 0 | W15: =U15+V15
A16: CANON-202512-002388 | B16: 2025-12-30 | C16: Everett Bellandi | D16: ND | E16: 1070000 | F16: 7173.3 | G16: 896.66 | H16: 896.66 | I16: =SUM(K16:T16) | J16: =F16-(G16+H16+I16) | K16: 538 | L16: 538 | M16: 538 | N16: 538 | O16: 538 | P16: 538 | Q16: 538 | R16: 538 | S16: 538 | T16: 538 | U16: 350 | V16: 250 | W16: =U16+V16
... A497: CANON-202512-003045 | B497: 2025-12-18 | C497: Ingrid Montoya | D497: ND | E497: 605000 | F497: 6937.78 | G497: 867.22 | H497: 867.22 | I497: =SUM(K497:T497) | J497: =F497-(G497+H497+I497) | K497: 520.33 | L497: 520.33 | M497: 520.33 | N497: 520.33 | O497: 520.33 | P497: 520.33 | Q497: 520.33 | R497: 520.33 | S497: 520.33 | T497: 520.33 | U497: 350 | V497: 0 | W497: =U497+V497
A498: TOTAL | E498: =SUM(E5:E497) | F498: =SUM(F5:F497) | G498: =SUM(G5:G497) | H498: =SUM(H5:H497) | I498: =SUM(I5:I497) | J498: =SUM(J5:J497) | K498: =SUM(K5:K497) | L498: =SUM(L5:L497) | ... W498: =SUM(W5:W497)
A499: Foot check: Premium − (B+T+M+Resid) | F499: =F498-(G498+H498+I498+J498)
A500: Foot check: Markets − Σ(10 syndicates) | I500: =I498-SUM(K498:T498)

Sheet 2026-01
A1: Underwriting BDX — 2026-01 (Bound book only)
A2: Indicative/declined premium excluded. Markets 75% = SUM of the ten syndicate columns (7.5% each). Residual = Premium − (Broker+Torque+Markets) so the row foots exactly.
A4: Policy Number | B4: Effective Date | C4: Insured | D4: State | E4: Agreed Value | F4: Bound Premium | G4: Broker 12.5% | H4: Torque 12.5% | I4: Markets 75% | J4: Rounding Residual | K4: Beazley | L4: Hiscox | M4: Chaucer | N4: Ark | O4: Brit | P4: Canopius | Q4: Apollo | R4: Antares | S4: MS Amlin | T4: Ascot | U4: Policy Fee | V4: Inspection Fee | W4: Fee Total
A5: CANON-202601-003048 | B5: 2026-01-31 | C5: Cassius Bellandi | D5: MN | E5: 280000 | F5: 4692.53 | G5: 586.57 | H5: 586.57 | I5: =SUM(K5:T5) | J5: =F5-(G5+H5+I5) | K5: 351.94 | L5: 351.94 | M5: 351.94 | N5: 351.94 | O5: 351.94 | P5: 351.94 | Q5: 351.94 | R5: 351.94 | S5: 351.94 | T5: 351.94 | U5: 350 | V5: 0 | W5: =U5+V5
A6: CANON-202601-003051 | B6: 2026-01-22 | C6: Ottilie Harrington | D6: WY | E6: 495000 | F6: 4303.72 | G6: 537.97 | H6: 537.97 | I6: =SUM(K6:T6) | J6: =F6-(G6+H6+I6) | K6: 322.78 | L6: 322.78 | M6: 322.78 | N6: 322.78 | O6: 322.78 | P6: 322.78 | Q6: 322.78 | R6: 322.78 | S6: 322.78 | T6: 322.78 | U6: 350 | V6: 0 | W6: =U6+V6
A7: CANON-202601-003053 | B7: 2026-01-19 | C7: Everett Underwood | D7: UT | E7: 455000 | F7: 7798.66 | G7: 974.83 | H7: 974.83 | I7: =SUM(K7:T7) | J7: =F7-(G7+H7+I7) | K7: 584.9 | L7: 584.9 | M7: 584.9 | N7: 584.9 | O7: 584.9 | P7: 584.9 | Q7: 584.9 | R7: 584.9 | S7: 584.9 | T7: 584.9 | U7: 350 | V7: 0 | W7: =U7+V7
A8: CANON-202601-003054 | B8: 2026-01-27 | C8: Callum Rourke | D8: ME | E8: 210000 | F8: 2188.42 | G8: 273.55 | H8: 273.55 | I8: =SUM(K8:T8) | J8: =F8-(G8+H8+I8) | K8: 164.13 | L8: 164.13 | M8: 164.13 | N8: 164.13 | O8: 164.13 | P8: 164.13 | Q8: 164.13 | R8: 164.13 | S8: 164.13 | T8: 164.13 | U8: 350 | V8: 0 | W8: =U8+V8
A9: CANON-202601-003055 | B9: 2026-01-13 | C9: Ramona Delacroix | D9: IL | E9: 625000 | F9: 9352.89 | G9: 1169.11 | H9: 1169.11 | I9: =SUM(K9:T9) | J9: =F9-(G9+H9+I9) | K9: 701.47 | L9: 701.47 | M9: 701.47 | N9: 701.47 | O9: 701.47 | P9: 701.47 | Q9: 701.47 | R9: 701.47 | S9: 701.47 | T9: 701.47 | U9: 350 | V9: 0 | W9: =U9+V9
A10: CANON-202601-003056 | B10: 2026-01-23 | C10: Priya Rourke | D10: NC | E10: 150000 | F10: 2686.52 | G10: 335.81 | H10: 335.81 | I10: =SUM(K10:T10) | J10: =F10-(G10+H10+I10) | K10: 201.49 | L10: 201.49 | M10: 201.49 | N10: 201.49 | O10: 201.49 | P10: 201.49 | Q10: 201.49 | R10: 201.49 | S10: 201.49 | T10: 201.49 | U10: 350 | V10: 0 | W10: =U10+V10
A11: CANON-202601-003057 | B11: 2026-01-16 | C11: Anouk Montoya | D11: GA | E11: 720000 | F11: 8873.14 | G11: 1109.14 | H11: 1109.14 | I11: =SUM(K11:T11) | J11: =F11-(G11+H11+I11) | K11: 665.49 | L11: 665.49 | M11: 665.49 | N11: 665.49 | O11: 665.49 | P11: 665.49 | Q11: 665.49 | R11: 665.49 | S11: 665.49 | T11: 665.49 | U11: 350 | V11: 0 | W11: =U11+V11
A12: CANON-202601-003058 | B12: 2026-01-01 | C12: Saoirse Vasquez | D12: VA | E12: 680000 | F12: 8155.72 | G12: 1019.47 | H12: 1019.47 | I12: =SUM(K12:T12) | J12: =F12-(G12+H12+I12) | K12: 611.68 | L12: 611.68 | M12: 611.68 | N12: 611.68 | O12: 611.68 | P12: 611.68 | Q12: 611.68 | R12: 611.68 | S12: 611.68 | T12: 611.68 | U12: 350 | V12: 0 | W12: =U12+V12
A13: CANON-202601-003061 | B13: 2026-01-21 | C13: Everett Castellanos | D13: MA | E13: 485000 | F13: 7697.09 | G13: 962.14 | H13: 962.14 | I13: =SUM(K13:T13) | J13: =F13-(G13+H13+I13) | K13: 577.28 | L13: 577.28 | M13: 577.28 | N13: 577.28 | O13: 577.28 | P13: 577.28 | Q13: 577.28 | R13: 577.28 | S13: 577.28 | T13: 577.28 | U13: 350 | V13: 0 | W13: =U13+V13
A14: CANON-202601-003062 | B14: 2026-01-22 | C14: Everett Ashcombe | D14: WY | E14: 495000 | F14: 3765.75 | G14: 470.72 | H14: 470.72 | I14: =SUM(K14:T14) | J14: =F14-(G14+H14+I14) | K14: 282.43 | L14: 282.43 | M14: 282.43 | N14: 282.43 | O14: 282.43 | P14: 282.43 | Q14: 282.43 | R14: 282.43 | S14: 282.43 | T14: 282.43 | U14: 350 | V14: 0 | W14: =U14+V14
A15: CANON-202601-003063 | B15: 2026-01-31 | C15: Fitzgerald Vandermeer | D15: SC | E15: 415000 | F15: 10018 | G15: 1252.25 | H15: 1252.25 | I15: =SUM(K15:T15) | J15: =F15-(G15+H15+I15) | K15: 751.35 | L15: 751.35 | M15: 751.35 | N15: 751.35 | O15: 751.35 | P15: 751.35 | Q15: 751.35 | R15: 751.35 | S15: 751.35 | T15: 751.35 | U15: 350 | V15: 0 | W15: =U15+V15
A16: CANON-202601-003064 | B16: 2026-01-14 | C16: Everett Rourke | D16: KY | E16: 445000 | F16: 7570.76 | G16: 946.35 | H16: 946.35 | I16: =SUM(K16:T16) | J16: =F16-(G16+H16+I16) | K16: 567.81 | L16: 567.81 | M16: 567.81 | N16: 567.81 | O16: 567.81 | P16: 567.81 | Q16: 567.81 | R16: 567.81 | S16: 567.81 | T16: 567.81 | U16: 350 | V16: 0 | W16: =U16+V16
... A503: CANON-202601-003732 | B503: 2026-01-06 | C503: Aurelio Larsson | D503: TX | E503: 340000 | F503: 4964.23 | G503: 620.53 | H503: 620.53 | I503: =SUM(K503:T503) | J503: =F503-(G503+H503+I503) | K503: 372.32 | L503: 372.32 | M503: 372.32 | N503: 372.32 | O503: 372.32 | P503: 372.32 | Q503: 372.32 | R503: 372.32 | S503: 372.32 | T503: 372.32 | U503: 350 | V503: 0 | W503: =U503+V503
A504: TOTAL | E504: =SUM(E5:E503) | F504: =SUM(F5:F503) | G504: =SUM(G5:G503) | H504: =SUM(H5:H503) | I504: =SUM(I5:I503) | J504: =SUM(J5:J503) | K504: =SUM(K5:K503) | L504: =SUM(L5:L503) | ... W504: =SUM(W5:W503)
A505: Foot check: Premium − (B+T+M+Resid) | F505: =F504-(G504+H504+I504+J504)
A506: Foot check: Markets − Σ(10 syndicates) | I506: =I504-SUM(K504:T504)

Sheet 2026-02
A1: Underwriting BDX — 2026-02 (Bound book only)
A2: Indicative/declined premium excluded. Markets 75% = SUM of the ten syndicate columns (7.5% each). Residual = Premium − (Broker+Torque+Markets) so the row foots exactly.
A4: Policy Number | B4: Effective Date | C4: Insured | D4: State | E4: Agreed Value | F4: Bound Premium | G4: Broker 12.5% | H4: Torque 12.5% | I4: Markets 75% | J4: Rounding Residual | K4: Beazley | L4: Hiscox | M4: Chaucer | N4: Ark | O4: Brit | P4: Canopius | Q4: Apollo | R4: Antares | S4: MS Amlin | T4: Ascot | U4: Policy Fee | V4: Inspection Fee | W4: Fee Total
A5: CANON-202602-003733 | B5: 2026-02-26 | C5: Fitzgerald Bellandi | D5: IA | E5: 550000 | F5: 9534.34 | G5: 1191.79 | H5: 1191.79 | I5: =SUM(K5:T5) | J5: =F5-(G5+H5+I5) | K5: 715.08 | L5: 715.08 | M5: 715.08 | N5: 715.08 | O5: 715.08 | P5: 715.08 | Q5: 715.08 | R5: 715.08 | S5: 715.08 | T5: 715.08 | U5: 350 | V5: 0 | W5: =U5+V5
A6: CANON-202602-003734 | B6: 2026-02-12 | C6: Everett Castellanos | D6: OH | E6: 205000 | F6: 4348.79 | G6: 543.6 | H6: 543.6 | I6: =SUM(K6:T6) | J6: =F6-(G6+H6+I6) | K6: 326.16 | L6: 326.16 | M6: 326.16 | N6: 326.16 | O6: 326.16 | P6: 326.16 | Q6: 326.16 | R6: 326.16 | S6: 326.16 | T6: 326.16 | U6: 350 | V6: 0 | W6: =U6+V6
A7: CANON-202602-003735 | B7: 2026-02-10 | C7: Thaddeus Larsson | D7: WI | E7: 635000 | F7: 8216.37 | G7: 1027.05 | H7: 1027.05 | I7: =SUM(K7:T7) | J7: =F7-(G7+H7+I7) | K7: 616.23 | L7: 616.23 | M7: 616.23 | N7: 616.23 | O7: 616.23 | P7: 616.23 | Q7: 616.23 | R7: 616.23 | S7: 616.23 | T7: 616.23 | U7: 350 | V7: 0 | W7: =U7+V7
A8: CANON-202602-003736 | B8: 2026-02-27 | C8: Desmond Farkas | D8: CA | E8: 415000 | F8: 6970.36 | G8: 871.29 | H8: 871.29 | I8: =SUM(K8:T8) | J8: =F8-(G8+H8+I8) | K8: 522.78 | L8: 522.78 | M8: 522.78 | N8: 522.78 | O8: 522.78 | P8: 522.78 | Q8: 522.78 | R8: 522.78 | S8: 522.78 | T8: 522.78 | U8: 350 | V8: 0 | W8: =U8+V8
A9: CANON-202602-003737 | B9: 2026-02-11 | C9: Emiliano Thistlewood | D9: FL | E9: 460000 | F9: 9535.43 | G9: 1191.93 | H9: 1191.93 | I9: =SUM(K9:T9) | J9: =F9-(G9+H9+I9) | K9: 715.16 | L9: 715.16 | M9: 715.16 | N9: 715.16 | O9: 715.16 | P9: 715.16 | Q9: 715.16 | R9: 715.16 | S9: 715.16 | T9: 715.16 | U9: 350 | V9: 0 | W9: =U9+V9
A10: CANON-202602-003738 | B10: 2026-02-05 | C10: Delphine Whitlock | D10: HI | E10: 910000 | F10: 8438.49 | G10: 1054.81 | H10: 1054.81 | I10: =SUM(K10:T10) | J10: =F10-(G10+H10+I10) | K10: 632.89 | L10: 632.89 | M10: 632.89 | N10: 632.89 | O10: 632.89 | P10: 632.89 | Q10: 632.89 | R10: 632.89 | S10: 632.89 | T10: 632.89 | U10: 350 | V10: 0 | W10: =U10+V10
A11: CANON-202602-003740 | B11: 2026-02-05 | C11: Anouk Montoya | D11: MO | E11: 800000 | F11: 9143.68 | G11: 1142.96 | H11: 1142.96 | I11: =SUM(K11:T11) | J11: =F11-(G11+H11+I11) | K11: 685.78 | L11: 685.78 | M11: 685.78 | N11: 685.78 | O11: 685.78 | P11: 685.78 | Q11: 685.78 | R11: 685.78 | S11: 685.78 | T11: 685.78 | U11: 350 | V11: 0 | W11: =U11+V11
A12: CANON-202602-003741 | B12: 2026-02-11 | C12: Priya Underwood | D12: KS | E12: 500000 | F12: 5229.58 | G12: 653.7 | H12: 653.7 | I12: =SUM(K12:T12) | J12: =F12-(G12+H12+I12) | K12: 392.22 | L12: 392.22 | M12: 392.22 | N12: 392.22 | O12: 392.22 | P12: 392.22 | Q12: 392.22 | R12: 392.22 | S12: 392.22 | T12: 392.22 | U12: 350 | V12: 0 | W12: =U12+V12
A13: CANON-202602-003744 | B13: 2026-02-01 | C13: Desmond Pennington | D13: TX | E13: 970000 | F13: 12028.04 | G13: 1503.51 | H13: 1503.51 | I13: =SUM(K13:T13) | J13: =F13-(G13+H13+I13) | K13: 902.1 | L13: 902.1 | M13: 902.1 | N13: 902.1 | O13: 902.1 | P13: 902.1 | Q13: 902.1 | R13: 902.1 | S13: 902.1 | T13: 902.1 | U13: 350 | V13: 0 | W13: =U13+V13
A14: CANON-202602-003746 | B14: 2026-02-06 | C14: Priya Underwood | D14: WA | E14: 785000 | F14: 5375.53 | G14: 671.94 | H14: 671.94 | I14: =SUM(K14:T14) | J14: =F14-(G14+H14+I14) | K14: 403.16 | L14: 403.16 | M14: 403.16 | N14: 403.16 | O14: 403.16 | P14: 403.16 | Q14: 403.16 | R14: 403.16 | S14: 403.16 | T14: 403.16 | U14: 350 | V14: 0 | W14: =U14+V14
A15: CANON-202602-003748 | B15: 2026-02-23 | C15: Everett Ashcombe | D15: MT | E15: 830000 | F15: 12164.56 | G15: 1520.57 | H15: 1520.57 | I15: =SUM(K15:T15) | J15: =F15-(G15+H15+I15) | K15: 912.34 | L15: 912.34 | M15: 912.34 | N15: 912.34 | O15: 912.34 | P15: 912.34 | Q15: 912.34 | R15: 912.34 | S15: 912.34 | T15: 912.34 | U15: 350 | V15: 0 | W15: =U15+V15
A16: CANON-202602-003749 | B16: 2026-02-22 | C16: Sunniva Harrington | D16: NJ | E16: 940000 | F16: 11068.17 | G16: 1383.52 | H16: 1383.52 | I16: =SUM(K16:T16) | J16: =F16-(G16+H16+I16) | K16: 830.11 | L16: 830.11 | M16: 830.11 | N16: 830.11 | O16: 830.11 | P16: 830.11 | Q16: 830.11 | R16: 830.11 | S16: 830.11 | T16: 830.11 | U16: 350 | V16: 0 | W16: =U16+V16
... A504: CANON-202602-004453 | B504: 2026-02-27 | C504: Desmond Ashcombe | D504: NY | E504: 455000 | F504: 7245.94 | G504: 905.74 | H504: 905.74 | I504: =SUM(K504:T504) | J504: =F504-(G504+H504+I504) | K504: 543.45 | L504: 543.45 | M504: 543.45 | N504: 543.45 | O504: 543.45 | P504: 543.45 | Q504: 543.45 | R504: 543.45 | S504: 543.45 | T504: 543.45 | U504: 350 | V504: 0 | W504: =U504+V504
A505: TOTAL | E505: =SUM(E5:E504) | F505: =SUM(F5:F504) | G505: =SUM(G5:G504) | H505: =SUM(H5:H504) | I505: =SUM(I5:I504) | J505: =SUM(J5:J504) | K505: =SUM(K5:K504) | L505: =SUM(L5:L504) | ... W505: =SUM(W5:W504)
A506: Foot check: Premium − (B+T+M+Resid) | F506: =F505-(G505+H505+I505+J505)
A507: Foot check: Markets − Σ(10 syndicates) | I507: =I505-SUM(K505:T505)

Sheet 2026-03
A1: Underwriting BDX — 2026-03 (Bound book only)
A2: Indicative/declined premium excluded. Markets 75% = SUM of the ten syndicate columns (7.5% each). Residual = Premium − (Broker+Torque+Markets) so the row foots exactly.
A4: Policy Number | B4: Effective Date | C4: Insured | D4: State | E4: Agreed Value | F4: Bound Premium | G4: Broker 12.5% | H4: Torque 12.5% | I4: Markets 75% | J4: Rounding Residual | K4: Beazley | L4: Hiscox | M4: Chaucer | N4: Ark | O4: Brit | P4: Canopius | Q4: Apollo | R4: Antares | S4: MS Amlin | T4: Ascot | U4: Policy Fee | V4: Inspection Fee | W4: Fee Total
A5: CANON-202603-004456 | B5: 2026-03-12 | C5: Ottilie Merriweather | D5: MD | E5: 560000 | F5: 8074 | G5: 1009.25 | H5: 1009.25 | I5: =SUM(K5:T5) | J5: =F5-(G5+H5+I5) | K5: 605.55 | L5: 605.55 | M5: 605.55 | N5: 605.55 | O5: 605.55 | P5: 605.55 | Q5: 605.55 | R5: 605.55 | S5: 605.55 | T5: 605.55 | U5: 350 | V5: 0 | W5: =U5+V5
A6: CANON-202603-004457 | B6: 2026-03-28 | C6: Mireille Bellandi | D6: AL | E6: 375000 | F6: 5706.24 | G6: 713.28 | H6: 713.28 | I6: =SUM(K6:T6) | J6: =F6-(G6+H6+I6) | K6: 427.97 | L6: 427.97 | M6: 427.97 | N6: 427.97 | O6: 427.97 | P6: 427.97 | Q6: 427.97 | R6: 427.97 | S6: 427.97 | T6: 427.97 | U6: 350 | V6: 0 | W6: =U6+V6
A7: CANON-202603-004459 | B7: 2026-03-18 | C7: Thaddeus Bellandi | D7: IN | E7: 1260000 | F7: 13617.33 | G7: 1702.17 | H7: 1702.17 | I7: =SUM(K7:T7) | J7: =F7-(G7+H7+I7) | K7: 1021.3 | L7: 1021.3 | M7: 1021.3 | N7: 1021.3 | O7: 1021.3 | P7: 1021.3 | Q7: 1021.3 | R7: 1021.3 | S7: 1021.3 | T7: 1021.3 | U7: 350 | V7: 250 | W7: =U7+V7
A8: CANON-202603-004460 | B8: 2026-03-01 | C8: Fenwick Ashcombe | D8: PA | E8: 575000 | F8: 5970.84 | G8: 746.36 | H8: 746.36 | I8: =SUM(K8:T8) | J8: =F8-(G8+H8+I8) | K8: 447.81 | L8: 447.81 | M8: 447.81 | N8: 447.81 | O8: 447.81 | P8: 447.81 | Q8: 447.81 | R8: 447.81 | S8: 447.81 | T8: 447.81 | U8: 350 | V8: 0 | W8: =U8+V8
A9: CANON-202603-004464 | B9: 2026-03-03 | C9: Marisol Okonkwo | D9: MD | E9: 695000 | F9: 4535.56 | G9: 566.95 | H9: 566.95 | I9: =SUM(K9:T9) | J9: =F9-(G9+H9+I9) | K9: 340.17 | L9: 340.17 | M9: 340.17 | N9: 340.17 | O9: 340.17 | P9: 340.17 | Q9: 340.17 | R9: 340.17 | S9: 340.17 | T9: 340.17 | U9: 350 | V9: 0 | W9: =U9+V9
A10: CANON-202603-004466 | B10: 2026-03-15 | C10: Cassius Vandermeer | D10: CA | E10: 1280000 | F10: 15183.09 | G10: 1897.89 | H10: 1897.89 | I10: =SUM(K10:T10) | J10: =F10-(G10+H10+I10) | K10: 1138.73 | L10: 1138.73 | M10: 1138.73 | N10: 1138.73 | O10: 1138.73 | P10: 1138.73 | Q10: 1138.73 | R10: 1138.73 | S10: 1138.73 | T10: 1138.73 | U10: 350 | V10: 250 | W10: =U10+V10
A11: CANON-202603-004468 | B11: 2026-03-18 | C11: Callum Okonkwo | D11: NY | E11: 365000 | F11: 5597.8 | G11: 699.73 | H11: 699.73 | I11: =SUM(K11:T11) | J11: =F11-(G11+H11+I11) | K11: 419.83 | L11: 419.83 | M11: 419.83 | N11: 419.83 | O11: 419.83 | P11: 419.83 | Q11: 419.83 | R11: 419.83 | S11: 419.83 | T11: 419.83 | U11: 350 | V11: 0 | W11: =U11+V11
A12: CANON-202603-004469 | B12: 2026-03-04 | C12: Marisol Farkas | D12: DE | E12: 1125000 | F12: 17972.41 | G12: 2246.55 | H12: 2246.55 | I12: =SUM(K12:T12) | J12: =F12-(G12+H12+I12) | K12: 1347.93 | L12: 1347.93 | M12: 1347.93 | N12: 1347.93 | O12: 1347.93 | P12: 1347.93 | Q12: 1347.93 | R12: 1347.93 | S12: 1347.93 | T12: 1347.93 | U12: 350 | V12: 250 | W12: =U12+V12
A13: CANON-202603-004470 | B13: 2026-03-21 | C13: Ottilie Fairweather | D13: NH | E13: 495000 | F13: 9457.8 | G13: 1182.22 | H13: 1182.22 | I13: =SUM(K13:T13) | J13: =F13-(G13+H13+I13) | K13: 709.33 | L13: 709.33 | M13: 709.33 | N13: 709.33 | O13: 709.33 | P13: 709.33 | Q13: 709.33 | R13: 709.33 | S13: 709.33 | T13: 709.33 | U13: 350 | V13: 0 | W13: =U13+V13
A14: CANON-202603-004471 | B14: 2026-03-01 | C14: Priya Montoya | D14: TN | E14: 1010000 | F14: 5376.26 | G14: 672.03 | H14: 672.03 | I14: =SUM(K14:T14) | J14: =F14-(G14+H14+I14) | K14: 403.22 | L14: 403.22 | M14: 403.22 | N14: 403.22 | O14: 403.22 | P14: 403.22 | Q14: 403.22 | R14: 403.22 | S14: 403.22 | T14: 403.22 | U14: 350 | V14: 250 | W14: =U14+V14
A15: CANON-202603-004472 | B15: 2026-03-22 | C15: Aurelio Chattopadhyay | D15: NY | E15: 505000 | F15: 8054.71 | G15: 1006.84 | H15: 1006.84 | I15: =SUM(K15:T15) | J15: =F15-(G15+H15+I15) | K15: 604.1 | L15: 604.1 | M15: 604.1 | N15: 604.1 | O15: 604.1 | P15: 604.1 | Q15: 604.1 | R15: 604.1 | S15: 604.1 | T15: 604.1 | U15: 350 | V15: 0 | W15: =U15+V15
A16: CANON-202603-004473 | B16: 2026-03-22 | C16: Saoirse Ashcombe | D16: IL | E16: 385000 | F16: 6273.56 | G16: 784.2 | H16: 784.2 | I16: =SUM(K16:T16) | J16: =F16-(G16+H16+I16) | K16: 470.52 | L16: 470.52 | M16: 470.52 | N16: 470.52 | O16: 470.52 | P16: 470.52 | Q16: 470.52 | R16: 470.52 | S16: 470.52 | T16: 470.52 | U16: 350 | V16: 0 | W16: =U16+V16
... A588: CANON-202603-005255 | B588: 2026-03-05 | C588: Horace Rourke | D588: CO | E588: 650000 | F588: 4911.66 | G588: 613.96 | H588: 613.96 | I588: =SUM(K588:T588) | J588: =F588-(G588+H588+I588) | K588: 368.37 | L588: 368.37 | M588: 368.37 | N588: 368.37 | O588: 368.37 | P588: 368.37 | Q588: 368.37 | R588: 368.37 | S588: 368.37 | T588: 368.37 | U588: 350 | V588: 0 | W588: =U588+V588
A589: TOTAL | E589: =SUM(E5:E588) | F589: =SUM(F5:F588) | G589: =SUM(G5:G588) | H589: =SUM(H5:H588) | I589: =SUM(I5:I588) | J589: =SUM(J5:J588) | K589: =SUM(K5:K588) | L589: =SUM(L5:L588) | ... W589: =SUM(W5:W588)
A590: Foot check: Premium − (B+T+M+Resid) | F590: =F589-(G589+H589+I589+J589)
A591: Foot check: Markets − Σ(10 syndicates) | I591: =I589-SUM(K589:T589)

Sheet 2026-04
A1: Underwriting BDX — 2026-04 (Bound book only)
A2: Indicative/declined premium excluded. Markets 75% = SUM of the ten syndicate columns (7.5% each). Residual = Premium − (Broker+Torque+Markets) so the row foots exactly.
A4: Policy Number | B4: Effective Date | C4: Insured | D4: State | E4: Agreed Value | F4: Bound Premium | G4: Broker 12.5% | H4: Torque 12.5% | I4: Markets 75% | J4: Rounding Residual | K4: Beazley | L4: Hiscox | M4: Chaucer | N4: Ark | O4: Brit | P4: Canopius | Q4: Apollo | R4: Antares | S4: MS Amlin | T4: Ascot | U4: Policy Fee | V4: Inspection Fee | W4: Fee Total
A5: CANON-202604-005256 | B5: 2026-04-22 | C5: Everett Fairweather | D5: NE | E5: 1485000 | F5: 11495.22 | G5: 1436.9 | H5: 1436.9 | I5: =SUM(K5:T5) | J5: =F5-(G5+H5+I5) | K5: 862.14 | L5: 862.14 | M5: 862.14 | N5: 862.14 | O5: 862.14 | P5: 862.14 | Q5: 862.14 | R5: 862.14 | S5: 862.14 | T5: 862.14 | U5: 350 | V5: 250 | W5: =U5+V5
A6: CANON-202604-005257 | B6: 2026-04-28 | C6: Fitzgerald Montoya | D6: CA | E6: 545000 | F6: 4381.05 | G6: 547.63 | H6: 547.63 | I6: =SUM(K6:T6) | J6: =F6-(G6+H6+I6) | K6: 328.58 | L6: 328.58 | M6: 328.58 | N6: 328.58 | O6: 328.58 | P6: 328.58 | Q6: 328.58 | R6: 328.58 | S6: 328.58 | T6: 328.58 | U6: 350 | V6: 0 | W6: =U6+V6
A7: CANON-202604-005260 | B7: 2026-04-01 | C7: Mireille Montoya | D7: AR | E7: 865000 | F7: 12158.29 | G7: 1519.79 | H7: 1519.79 | I7: =SUM(K7:T7) | J7: =F7-(G7+H7+I7) | K7: 911.87 | L7: 911.87 | M7: 911.87 | N7: 911.87 | O7: 911.87 | P7: 911.87 | Q7: 911.87 | R7: 911.87 | S7: 911.87 | T7: 911.87 | U7: 350 | V7: 0 | W7: =U7+V7
A8: CANON-202604-005261 | B8: 2026-04-14 | C8: Noor Chattopadhyay | D8: RI | E8: 470000 | F8: 7567.34 | G8: 945.92 | H8: 945.92 | I8: =SUM(K8:T8) | J8: =F8-(G8+H8+I8) | K8: 567.55 | L8: 567.55 | M8: 567.55 | N8: 567.55 | O8: 567.55 | P8: 567.55 | Q8: 567.55 | R8: 567.55 | S8: 567.55 | T8: 567.55 | U8: 350 | V8: 0 | W8: =U8+V8
A9: CANON-202604-005262 | B9: 2026-04-04 | C9: Saoirse Underwood | D9: IL | E9: 275000 | F9: 4395.38 | G9: 549.42 | H9: 549.42 | I9: =SUM(K9:T9) | J9: =F9-(G9+H9+I9) | K9: 329.65 | L9: 329.65 | M9: 329.65 | N9: 329.65 | O9: 329.65 | P9: 329.65 | Q9: 329.65 | R9: 329.65 | S9: 329.65 | T9: 329.65 | U9: 350 | V9: 0 | W9: =U9+V9
A10: CANON-202604-005263 | B10: 2026-04-10 | C10: Saoirse Castellanos | D10: OK | E10: 1325000 | F10: 9941.09 | G10: 1242.64 | H10: 1242.64 | I10: =SUM(K10:T10) | J10: =F10-(G10+H10+I10) | K10: 745.58 | L10: 745.58 | M10: 745.58 | N10: 745.58 | O10: 745.58 | P10: 745.58 | Q10: 745.58 | R10: 745.58 | S10: 745.58 | T10: 745.58 | U10: 350 | V10: 250 | W10: =U10+V10
A11: CANON-202604-005264 | B11: 2026-04-27 | C11: Cassius Underwood | D11: MI | E11: 285000 | F11: 5191.6 | G11: 648.95 | H11: 648.95 | I11: =SUM(K11:T11) | J11: =F11-(G11+H11+I11) | K11: 389.37 | L11: 389.37 | M11: 389.37 | N11: 389.37 | O11: 389.37 | P11: 389.37 | Q11: 389.37 | R11: 389.37 | S11: 389.37 | T11: 389.37 | U11: 350 | V11: 0 | W11: =U11+V11
A12: CANON-202604-005265 | B12: 2026-04-04 | C12: Horace Delacroix | D12: SC | E12: 1855000 | F12: 13696.61 | G12: 1712.08 | H12: 1712.08 | I12: =SUM(K12:T12) | J12: =F12-(G12+H12+I12) | K12: 1027.25 | L12: 1027.25 | M12: 1027.25 | N12: 1027.25 | O12: 1027.25 | P12: 1027.25 | Q12: 1027.25 | R12: 1027.25 | S12: 1027.25 | T12: 1027.25 | U12: 350 | V12: 250 | W12: =U12+V12
A13: CANON-202604-005267 | B13: 2026-04-07 | C13: Wilhelmina Castellanos | D13: MA | E13: 690000 | F13: 8784.89 | G13: 1098.11 | H13: 1098.11 | I13: =SUM(K13:T13) | J13: =F13-(G13+H13+I13) | K13: 658.87 | L13: 658.87 | M13: 658.87 | N13: 658.87 | O13: 658.87 | P13: 658.87 | Q13: 658.87 | R13: 658.87 | S13: 658.87 | T13: 658.87 | U13: 350 | V13: 0 | W13: =U13+V13
A14: CANON-202604-005268 | B14: 2026-04-10 | C14: Marisol Farkas | D14: OH | E14: 490000 | F14: 8004.53 | G14: 1000.57 | H14: 1000.57 | I14: =SUM(K14:T14) | J14: =F14-(G14+H14+I14) | K14: 600.34 | L14: 600.34 | M14: 600.34 | N14: 600.34 | O14: 600.34 | P14: 600.34 | Q14: 600.34 | R14: 600.34 | S14: 600.34 | T14: 600.34 | U14: 350 | V14: 0 | W14: =U14+V14
A15: CANON-202604-005269 | B15: 2026-04-05 | C15: Thaddeus Castellanos | D15: VT | E15: 825000 | F15: 6781.81 | G15: 847.73 | H15: 847.73 | I15: =SUM(K15:T15) | J15: =F15-(G15+H15+I15) | K15: 508.64 | L15: 508.64 | M15: 508.64 | N15: 508.64 | O15: 508.64 | P15: 508.64 | Q15: 508.64 | R15: 508.64 | S15: 508.64 | T15: 508.64 | U15: 350 | V15: 0 | W15: =U15+V15
A16: CANON-202604-005270 | B16: 2026-04-17 | C16: Priya Castellanos | D16: IA | E16: 415000 | F16: 5364.96 | G16: 670.62 | H16: 670.62 | I16: =SUM(K16:T16) | J16: =F16-(G16+H16+I16) | K16: 402.37 | L16: 402.37 | M16: 402.37 | N16: 402.37 | O16: 402.37 | P16: 402.37 | Q16: 402.37 | R16: 402.37 | S16: 402.37 | T16: 402.37 | U16: 350 | V16: 0 | W16: =U16+V16
... A550: CANON-202604-005981 | B550: 2026-04-05 | C550: Lorenzo Kingsford | D550: MO | E550: 1190000 | F550: 10871.25 | G550: 1358.91 | H550: 1358.91 | I550: =SUM(K550:T550) | J550: =F550-(G550+H550+I550) | K550: 815.34 | L550: 815.34 | M550: 815.34 | N550: 815.34 | O550: 815.34 | P550: 815.34 | Q550: 815.34 | R550: 815.34 | S550: 815.34 | T550: 815.34 | U550: 350 | V550: 250 | W550: =U550+V550
A551: TOTAL | E551: =SUM(E5:E550) | F551: =SUM(F5:F550) | G551: =SUM(G5:G550) | H551: =SUM(H5:H550) | I551: =SUM(I5:I550) | J551: =SUM(J5:J550) | K551: =SUM(K5:K550) | L551: =SUM(L5:L550) | ... W551: =SUM(W5:W550)
A552: Foot check: Premium − (B+T+M+Resid) | F552: =F551-(G551+H551+I551+J551)
A553: Foot check: Markets − Σ(10 syndicates) | I553: =I551-SUM(K551:T551)

Sheet 2026-05
A1: Underwriting BDX — 2026-05 (Bound book only)
A2: Indicative/declined premium excluded. Markets 75% = SUM of the ten syndicate columns (7.5% each). Residual = Premium − (Broker+Torque+Markets) so the row foots exactly.
A4: Policy Number | B4: Effective Date | C4: Insured | D4: State | E4: Agreed Value | F4: Bound Premium | G4: Broker 12.5% | H4: Torque 12.5% | I4: Markets 75% | J4: Rounding Residual | K4: Beazley | L4: Hiscox | M4: Chaucer | N4: Ark | O4: Brit | P4: Canopius | Q4: Apollo | R4: Antares | S4: MS Amlin | T4: Ascot | U4: Policy Fee | V4: Inspection Fee | W4: Fee Total
A5: CANON-202605-005982 | B5: 2026-05-18 | C5: Delphine Merriweather | D5: MI | E5: 705000 | F5: 10415.76 | G5: 1301.97 | H5: 1301.97 | I5: =SUM(K5:T5) | J5: =F5-(G5+H5+I5) | K5: 781.18 | L5: 781.18 | M5: 781.18 | N5: 781.18 | O5: 781.18 | P5: 781.18 | Q5: 781.18 | R5: 781.18 | S5: 781.18 | T5: 781.18 | U5: 350 | V5: 0 | W5: =U5+V5
A6: CANON-202605-005984 | B6: 2026-05-16 | C6: Noor Fairweather | D6: OH | E6: 1800000 | F6: 12474.5 | G6: 1559.31 | H6: 1559.31 | I6: =SUM(K6:T6) | J6: =F6-(G6+H6+I6) | K6: 935.59 | L6: 935.59 | M6: 935.59 | N6: 935.59 | O6: 935.59 | P6: 935.59 | Q6: 935.59 | R6: 935.59 | S6: 935.59 | T6: 935.59 | U6: 350 | V6: 250 | W6: =U6+V6
A7: CANON-202605-005985 | B7: 2026-05-31 | C7: Wilhelmina Ashcombe | D7: WA | E7: 710000 | F7: 6496.81 | G7: 812.1 | H7: 812.1 | I7: =SUM(K7:T7) | J7: =F7-(G7+H7+I7) | K7: 487.26 | L7: 487.26 | M7: 487.26 | N7: 487.26 | O7: 487.26 | P7: 487.26 | Q7: 487.26 | R7: 487.26 | S7: 487.26 | T7: 487.26 | U7: 350 | V7: 0 | W7: =U7+V7
A8: CANON-202605-005986 | B8: 2026-05-14 | C8: Mireille Pennington | D8: IL | E8: 1320000 | F8: 21060.07 | G8: 2632.51 | H8: 2632.51 | I8: =SUM(K8:T8) | J8: =F8-(G8+H8+I8) | K8: 1579.51 | L8: 1579.51 | M8: 1579.51 | N8: 1579.51 | O8: 1579.51 | P8: 1579.51 | Q8: 1579.51 | R8: 1579.51 | S8: 1579.51 | T8: 1579.51 | U8: 350 | V8: 250 | W8: =U8+V8
A9: CANON-202605-005987 | B9: 2026-05-08 | C9: Fitzgerald Okonkwo | D9: LA | E9: 585000 | F9: 4463.41 | G9: 557.93 | H9: 557.93 | I9: =SUM(K9:T9) | J9: =F9-(G9+H9+I9) | K9: 334.76 | L9: 334.76 | M9: 334.76 | N9: 334.76 | O9: 334.76 | P9: 334.76 | Q9: 334.76 | R9: 334.76 | S9: 334.76 | T9: 334.76 | U9: 350 | V9: 0 | W9: =U9+V9
A10: CANON-202605-005988 | B10: 2026-05-20 | C10: Wilhelmina Chattopadhyay | D10: OK | E10: 640000 | F10: 11233.91 | G10: 1404.24 | H10: 1404.24 | I10: =SUM(K10:T10) | J10: =F10-(G10+H10+I10) | K10: 842.54 | L10: 842.54 | M10: 842.54 | N10: 842.54 | O10: 842.54 | P10: 842.54 | Q10: 842.54 | R10: 842.54 | S10: 842.54 | T10: 842.54 | U10: 350 | V10: 0 | W10: =U10+V10
A11: CANON-202605-005989 | B11: 2026-05-10 | C11: Noor Whitlock | D11: IA | E11: 1150000 | F11: 10202.58 | G11: 1275.32 | H11: 1275.32 | I11: =SUM(K11:T11) | J11: =F11-(G11+H11+I11) | K11: 765.19 | L11: 765.19 | M11: 765.19 | N11: 765.19 | O11: 765.19 | P11: 765.19 | Q11: 765.19 | R11: 765.19 | S11: 765.19 | T11: 765.19 | U11: 350 | V11: 250 | W11: =U11+V11
A12: CANON-202605-005990 | B12: 2026-05-08 | C12: Marisol Rourke | D12: NJ | E12: 905000 | F12: 5192.96 | G12: 649.12 | H12: 649.12 | I12: =SUM(K12:T12) | J12: =F12-(G12+H12+I12) | K12: 389.47 | L12: 389.47 | M12: 389.47 | N12: 389.47 | O12: 389.47 | P12: 389.47 | Q12: 389.47 | R12: 389.47 | S12: 389.47 | T12: 389.47 | U12: 350 | V12: 0 | W12: =U12+V12
A13: CANON-202605-005992 | B13: 2026-05-18 | C13: Ottilie Pennington | D13: CT | E13: 790000 | F13: 12326.1 | G13: 1540.76 | H13: 1540.76 | I13: =SUM(K13:T13) | J13: =F13-(G13+H13+I13) | K13: 924.46 | L13: 924.46 | M13: 924.46 | N13: 924.46 | O13: 924.46 | P13: 924.46 | Q13: 924.46 | R13: 924.46 | S13: 924.46 | T13: 924.46 | U13: 350 | V13: 0 | W13: =U13+V13
A14: CANON-202605-005993 | B14: 2026-05-08 | C14: Fenwick Okonkwo | D14: WI | E14: 730000 | F14: 12203.51 | G14: 1525.44 | H14: 1525.44 | I14: =SUM(K14:T14) | J14: =F14-(G14+H14+I14) | K14: 915.26 | L14: 915.26 | M14: 915.26 | N14: 915.26 | O14: 915.26 | P14: 915.26 | Q14: 915.26 | R14: 915.26 | S14: 915.26 | T14: 915.26 | U14: 350 | V14: 0 | W14: =U14+V14
A15: CANON-202605-005994 | B15: 2026-05-09 | C15: Anouk Kingsford | D15: AK | E15: 580000 | F15: 6302.36 | G15: 787.79 | H15: 787.79 | I15: =SUM(K15:T15) | J15: =F15-(G15+H15+I15) | K15: 472.68 | L15: 472.68 | M15: 472.68 | N15: 472.68 | O15: 472.68 | P15: 472.68 | Q15: 472.68 | R15: 472.68 | S15: 472.68 | T15: 472.68 | U15: 350 | V15: 0 | W15: =U15+V15
A16: CANON-202605-005995 | B16: 2026-05-08 | C16: Cassius Okonkwo | D16: WA | E16: 675000 | F16: 9027.25 | G16: 1128.41 | H16: 1128.41 | I16: =SUM(K16:T16) | J16: =F16-(G16+H16+I16) | K16: 677.04 | L16: 677.04 | M16: 677.04 | N16: 677.04 | O16: 677.04 | P16: 677.04 | Q16: 677.04 | R16: 677.04 | S16: 677.04 | T16: 677.04 | U16: 350 | V16: 0 | W16: =U16+V16
... A550: CANON-202605-006732 | B550: 2026-05-20 | C550: Emiliano Bellandi | D550: CT | E550: 585000 | F550: 4131.42 | G550: 516.43 | H550: 516.43 | I550: =SUM(K550:T550) | J550: =F550-(G550+H550+I550) | K550: 309.86 | L550: 309.86 | M550: 309.86 | N550: 309.86 | O550: 309.86 | P550: 309.86 | Q550: 309.86 | R550: 309.86 | S550: 309.86 | T550: 309.86 | U550: 350 | V550: 0 | W550: =U550+V550
A551: TOTAL | E551: =SUM(E5:E550) | F551: =SUM(F5:F550) | G551: =SUM(G5:G550) | H551: =SUM(H5:H550) | I551: =SUM(I5:I550) | J551: =SUM(J5:J550) | K551: =SUM(K5:K550) | L551: =SUM(L5:L550) | ... W551: =SUM(W5:W550)
