Workbook

Sheet README
B1: EXOTIC, SUPERCAR & COLLECTOR AUTOMOBILE - MGA RATING MATRIX
B2: Delegated authority rating structure for high-value private and commercial motor risks with agreed values of USD 250,000 and above
B4: HOW TO USE THIS WORKBOOK
B6: Rating Engine | C6: Single-risk quotation. Fill only the blue-on-yellow input cells in Section 1 (each has a drop-down). Everything below calculates automatically: factor pick-up, technical premium, gross written premium, taxes and the full commission split.
B7: Scenario Tests | C7: Six worked risks side by side using the identical formula chain. Use it to sense-check rate adequacy and relativities across the portfolio, or as a template for a quote sheet.
B8: Rate Definitions | C8: Plain-language definitions of every rate concept in the workbook - base rate, loss cost, pure risk premium, technical premium, technical rate, charged rate, rate adequacy - plus a live rate hierarchy for the specimen risk.
B9: Base Rates | C9: Physical-damage base rate per USD 100 of agreed value, by vehicle class and agreed-value band. This is the single biggest lever in the model.
B10: Make Factors | C10: Make-level modifier built from parts & labour cost, theft attractiveness and repair-network scarcity. Combined factor feeds the engine.
B11: Driver Factors | C11: Age band, high-performance driving experience and MVR / violation record.
B12: Claims History | C12: At-fault and comprehensive claim relativities, plus loss-run and chargeable-period underwriting rules.
B13: Territory Factors | C13: All 50 states and DC: PD territory factor, liability base loss cost, catastrophe load, theft and litigation indices, no-fault status, surplus lines tax, and the named perils driving each state. Regional peril and coverage notes sit below the state table.
B14: City Accident Ratings | C14: Metro-level accident, theft and comprehensive relativities for 48 major US metros plus a rest-of-state default, blended by adjustable weights and applied on top of the statewide territory factor.
B15: Usage and Coverage | C15: Personal vs commercial usage, annual mileage, storage, security, deductible, valuation basis, collection size and liability increased-limit factors.
B16: Cat Zone by ZIP | C16: ZIP-3 prefix to catastrophe zone mapping with a state-default fallback. The Rating Engine reads the garaging ZIP and derives the zone automatically, disclosing how it was determined.
B17: Natural Catastrophe | C17: Catastrophe zone multipliers applied to the state cat load, catastrophe deductible options, peril-by-peril coverage treatment, a live aggregate and PML monitor, and the binding moratorium rules.
... B27: Lloyds Markets | C27: Ten Lloyd's syndicates with indicative line size, target share, binder type and commission terms, plus alternates and a placement checklist.
B29: CELL COLOUR LEGEND
B31: Blue text on yellow fill | C31: Input cell. Enter or select a value here. These are the only cells you should type into.
B32: Blue text | C32: Hardcoded assumption or scenario lever. Change deliberately - these drive the whole model.
B33: Black text | C33: Calculated on this sheet. Do not overwrite.
B34: Green text | C34: Linked from another sheet in this workbook.
B36: RATING ALGORITHM
B38: 1. PD base loss cost = Agreed Value / 100 x base rate (vehicle class x value band)
B39: 2. Rated PD loss cost = PD base loss cost x 14 core rating factors (make, age, experience, MVR, claims, state territory, city / metro accident territory, usage, mileage, storage, security, PD deductible, valuation basis, collection size) x 14 coverage factors (5 deductible selections and 9 sub-limit selections)
B40: 3. Rated liability loss cost = state liability base loss cost x increased limit factor x usage x age x MVR x claims x mileage
B41: 4. Expected loss = rated PD + rated liability
B42: 5. Loss & ALAE = expected loss x (1 + ALAE load)
B43: 6. Plus ULAE = Loss & ALAE x ULAE load
B44: 7. Plus catastrophe load = rated PD loss cost x state cat load x catastrophe zone multiplier (from ZIP) x catastrophe deductible credit
B45: 8. Plus risk margin = subtotal x volatility / risk margin
B46: 9. Pure risk premium = sum of steps 5 - 8
B47: 10. TECHNICAL PREMIUM = pure risk premium / (1 - acquisition - admin - reinsurance - target UW profit)
B48: 11. Gross written premium = technical premium x (1 + underwriter judgement adjustment)
... B58: - Nothing here is legal, tax or actuarial advice. Filing, licensing and compliance obligations differ in every state and must be confirmed with counsel and your compliance function.

Sheet Rate Definitions
B1: RATE DEFINITIONS AND RATE HIERARCHY
B2: What each rate in this workbook means, and how the specimen risk moves from base rate to charged rate.
B4: SECTION A - DEFINITIONS
B5: Term | C5: Definition | D5: Where it lives
B6: Base rate | C6: The starting physical damage rate per $100 of agreed value before any risk-specific adjustment. Set by vehicle class and agreed value band. | E6: Base Rates sheet
B7: Loss cost | C7: The expected dollar amount of claims for an exposure. Base PD loss cost = agreed value / 100 x base rate. | E7: Rating Engine, Section 2
B8: Rating factor | C8: A multiplicative relativity applied to the loss cost for a single risk characteristic (make, driver, territory, city, usage, etc.). 1.000 is neutral. | E8: Factor sheets
B9: Composite rating factor | C9: The product of all rating factors, subject to the maximum-factor cap. Applied to the base loss cost. | E9: Rating Engine, row 47
B10: ALAE | C10: Allocated loss adjustment expense: claim costs attributable to a specific claim (appraisers, specialists, defence counsel, salvage handling). | E10: Technical Premium, Section A
B11: ULAE | C11: Unallocated loss adjustment expense: claims-department overhead not attributable to individual claims. | E11: Technical Premium, Section A
B12: Catastrophe load | C12: Provision for low-frequency, high-severity events (hurricane, hail, wildfire) not credibly captured in base loss experience. Varies by state. | E12: Territory Factors, col G
B13: Risk margin | C13: Loading for volatility and parameter uncertainty in a low-frequency, very-high-severity class. | E13: Technical Premium, Section A
B14: Pure risk premium | C14: Expected loss plus ALAE, ULAE, catastrophe load and risk margin. No expense or profit content. | E14: Rating Engine, row 60
B15: Expense & profit ratio | C15: Acquisition commission + administration + reinsurance net cost + target underwriting profit, expressed as a share of premium. | E15: Technical Premium, Section A
B16: Gross-up divisor | C16: 1 minus the expense & profit ratio. The pure risk premium is divided by this to gross it up to a premium. | E16: Technical Premium, row 13
B17: TECHNICAL PREMIUM | C17: The rate-adequate premium: pure risk premium divided by the gross-up divisor. The price at which the account is expected to hit its target loss ratio and profit. Writing below it erodes results dollar for dollar. | E17: Rating Engine, row 62
... B23: Ceding commission / net rate | C23: Commission retained from GWP by the distribution chain; net rate is what reaches capacity. Net premium = GWP x (1 - total ceding commission). | E23: Commission Structure
B25: SECTION B - LIVE RATE HIERARCHY (specimen risk from the Rating Engine)
B26: Step | C26: What it is | E26: Rate per $100 of value | F26: Premium ($)
B27: 1. Base rate | C27: Vehicle class x agreed value band starting rate | E27: ='Rating Engine'!C56 -> 1.15
B28: 2. Rated PD loss cost | C28: Base loss cost x core factors x coverage factors | E28: ='Rating Engine'!C91/'Rating Engine'!C11*100 -> 1.6460711 | F28: ='Rating Engine'!C91 -> 6995.802
B29: 3. Pure risk premium | C29: Plus liability, ALAE, ULAE, catastrophe load and risk margin | E29: ='Rating Engine'!C103/'Rating Engine'!C11*100 -> 3.2722237 | F29: ='Rating Engine'!C103 -> 13906.951
B30: 4. TECHNICAL RATE / PREMIUM | C30: Grossed up for expense and profit - the rate-adequate price | E30: ='Rating Engine'!C106 -> 5.8958986 | F30: ='Rating Engine'!C105 -> 25057.569
B31: 5. Charged rate / GWP | C31: Technical premium plus underwriter judgement adjustment | E31: ='Rating Engine'!C109 -> 5.8958986 | F31: ='Rating Engine'!C108 -> 25057.569
B32: 6. Rate adequacy | C32: Charged rate / technical rate (below 100% = under-priced) | E32: ='Rating Engine'!C110 -> 1
B34: The hierarchy is live: change any input on the Rating Engine and this table follows. The two rates management should watch are step 4 (is the plan producing an adequate price?) and step 6 (are the underwriters charging it?). For the full component-by-component derivation of step 4, including the marginal dollar effect of every individual factor and an independent proof of the arithmetic, see the Premium Breakout sheet.

Sheet Rating Engine
B1: RATING ENGINE - SINGLE RISK QUOTATION
B2: Complete the yellow input cells in Section 1 - every one is a drop-down except the free-text and numeric fields. The catastrophe zone is derived from the garaging ZIP. Do not type over any calculated cell.
B4: SECTION 1 - RISK INPUTS (complete every yellow cell)
B5: Insured / risk reference | C5: CANON-202603-005559 - Horace Merriweather | D5: Free text.
B6: Policy effective date | C6: 46106 | D6: Enter as a date.
B7: Vehicle year | C7: 1999 | D7: Free text - drives class selection.
B8: Vehicle make | C8: Other / Bespoke | D8: Drop-down from the Make Factors sheet.
B9: Vehicle model | C9: M8 Competition | D9: Free text. Refer any model not represented by the make factor.
B10: Vehicle class | C10: 02 - Sports / GT | D10: Drop-down. Classic and collector eligibility rules are on the Endorsements sheet, Section B.
B11: Agreed value (USD) | C11: 465000 | D11: Appraised agreed value. Programme minimum is $100,000 - anything below is automatically declined. Independent appraisal required at or above $1m.
B12: Garaging state | C12: New York | D12: Drop-down - all 50 states and DC. GARAGING address governs.
B13: Garaging ZIP code | C13: 10022 | D13: ENTER THE 5-DIGIT GARAGING ZIP. This drives the catastrophe zone in Section 2A. Leading zeros are handled.
B14: Policy type | C14: Personal | D14: Personal or Commercial. Must be consistent with the usage category below.
B15: Usage category | C15: Personal - regular use | D15: Drop-down. Commercial classes carry their own liability structure - refer.
B16: Annual mileage band | C16: 2,500 - 5,000 | D16: Drop-down. Mileage cap is a policy condition, not just a rating item.
B17: Storage / garaging | C17: Locked private garage w/ monitored alarm | D17: Drop-down. Storage is the single most effective loss control on this class.
B18: Security specification | C18: GPS tracker w/ recovery service | D18: Drop-down. GPS with recovery service is mandatory above $500k agreed value.
B19: Principal driver age band | C19: 45 - 54 | D19: Drop-down. Rate the worst-rated permitted driver, not the policyholder.
B20: High-performance experience | C20: 5 - 10 years | D20: Drop-down. Accredited training certificate must be on file to take the credit.
B21: MVR record (3 yrs) | C21: Clean - no violations 3 yrs | D21: Drop-down. MVR ordered on every permitted driver at new business and renewal.
B22: Claims history (5 yrs) | C22: No at-fault claims - 5 yrs | D22: Drop-down. Five years of carrier loss runs required above $500k agreed value.
B23: Collection size | C23: 2 - 3 vehicles | D23: Drop-down.
... B30: Glass deductible | C30: $500 flat, OEM glass | D30: Risk inputs populated from demo submission; premium computed by this rater's own engine.
B31: Theft deductible | C31: Same as PD deductible
B32: Aggregate deductible (collections) | C32: Not applicable - per vehicle deductible
B33: Total loss deductible waiver | C33: Not purchased
B34: SUB-LIMIT SELECTIONS - Automatically acquired vehicle | C34: $500,000 / 30 days | D34: Drop-down. Options and factors on the Sublimits and Parts sheet, Section D.
B35: Spare parts, tools and automobilia | C35: $25,000
B36: Personal effects | C36: $5,000
B37: Loss of use / substitute vehicle | C37: $10,000
B38: Transit and transport | C38: Enclosed carrier only
B39: Worldwide territory extension | C39: Not required - US and Canada only
B40: Unobtainable parts fabrication | C40: $100,000
B41: Diminution in value | C41: 10% of agreed value
B42: Per-location all-perils aggregate | C42: $10,000,000
B43: Catastrophe zone override (optional) | D43: OPTIONAL. Leave blank to let the ZIP drive the zone. Enter a zone here only to override the ZIP lookup - the override is disclosed on row 49.
B44: Underwriter judgement adjustment | C44: 0 | D44: Manual market / judgement adjustment. The underwriter discount authority on the Technical Premium sheet (row 19) is a HARD LIMIT - anything beyond it forces a referral and cannot be bound alone.
B46: SECTION 2A - CATASTROPHE ZONE DETERMINATION (driven by the garaging ZIP)
B47: ZIP-3 prefix | C47: =IFERROR(LEFT(TEXT(VALUE(C13),"00000"),3),"---") | D47: First three digits of the garaging ZIP.
B48: CATASTROPHE ZONE (from ZIP) | C48: =IF(C43<>"",C43,IFERROR(INDEX('Cat Zone by ZIP'!$D$6:$D$856,MATCH(C47,'Cat Zone by ZIP'!$B$6:$B$856,0)),IFERROR(INDEX('Cat Zone by ZIP'!$C$860:$C$910,MATCH(C12,'Cat Zone by ZIP'!$B$860:$B$910,0)),"NOT FOUND - select an override"))) | D48: Derived. Manual override if entered, otherwise the ZIP-3 mapping, otherwise the state default.
...

Sheet Premium Breakout
B1: TECHNICAL PREMIUM BREAKOUT - FULL DERIVATION
B2: Every component of the technical premium for the risk currently on the Rating Engine, shown step by step so the arithmetic can be checked by hand.
B4: SECTION A - FACTOR-BY-FACTOR BUILD OF THE PHYSICAL DAMAGE LOSS COST
B5: # | C5: Rating factor | D5: Factor | E5: Running product | F5: Running loss cost ($) | G5: Marginal effect ($) | H5: Selection made
B6: 0 | C6: Base PD loss cost (agreed value / 100 x base rate) | D6: ='Rating Engine'!C56 -> 1.15 | E6: 1 | F6: ='Rating Engine'!C57 -> 4887.5 | H6: ='Rating Engine'!C10&" | "&'Rating Engine'!C55 -> 03 - Supercar | $250k - $500k
B7: 1 | C7: ='Rating Engine'!B58 -> Make / model factor | D7: ='Rating Engine'!C58 -> 1.087 | E7: =E6*D7 -> 1.087 | F7: =$F$6*E7 -> 5312.7125 | G7: =F7-F6 -> 425.2125 | H7: ='Rating Engine'!C8 -> Ferrari
B8: 2 | C8: ='Rating Engine'!B59 -> Driver age factor | D8: ='Rating Engine'!C59 -> 1 | E8: =E7*D8 -> 1.087 | F8: =$F$6*E8 -> 5312.7125 | G8: =F8-F7 -> 0 | H8: ='Rating Engine'!C19 -> 45 - 54
B9: 3 | C9: ='Rating Engine'!B60 -> Experience factor | D9: ='Rating Engine'!C60 -> 1 | E9: =E8*D9 -> 1.087 | F9: =$F$6*E9 -> 5312.7125 | G9: =F9-F8 -> 0 | H9: ='Rating Engine'!C20 -> 5 - 10 years
B10: 4 | C10: ='Rating Engine'!B61 -> MVR factor | D10: ='Rating Engine'!C61 -> 1 | E10: =E9*D10 -> 1.087 | F10: =$F$6*E10 -> 5312.7125 | G10: =F10-F9 -> 0 | H10: ='Rating Engine'!C21 -> Clean - no violations 3 yrs
B11: 5 | C11: ='Rating Engine'!B62 -> Claims history factor | D11: ='Rating Engine'!C62 -> 0.9 | E11: =E10*D11 -> 0.9783 | F11: =$F$6*E11 -> 4781.4412 | G11: =F11-F10 -> -531.27125 | H11: ='Rating Engine'!C22 -> No at-fault claims - 5 yrs
B12: 6 | C12: ='Rating Engine'!B63 -> State territory factor | D12: ='Rating Engine'!C63 -> 1.45 | E12: =E11*D12 -> 1.418535 | F12: =$F$6*E12 -> 6933.0898 | G12: =F12-F11 -> 2151.6486 | H12: ='Rating Engine'!C12 -> Florida
B13: 7 | C13: ='Rating Engine'!B64 -> City / metro accident factor | D13: ='Rating Engine'!C64 -> 1.395 | E13: =E12*D13 -> 1.9788563 | F13: =$F$6*E13 -> 9671.6603 | G13: =F13-F12 -> 2738.5705 | H13: ='Rating Engine'!C27 -> Miami - Fort Lauderdale, FL
B14: 8 | C14: ='Rating Engine'!B65 -> Usage factor | D14: ='Rating Engine'!C65 -> 1 | E14: =E13*D14 -> 1.9788563 | F14: =$F$6*E14 -> 9671.6603 | G14: =F14-F13 -> 0 | H14: ='Rating Engine'!C15 -> Personal - regular use
B15: 9 | C15: ='Rating Engine'!B66 -> Mileage factor | D15: ='Rating Engine'!C66 -> 1 | E15: =E14*D15 -> 1.9788563 | F15: =$F$6*E15 -> 9671.6603 | G15: =F15-F14 -> 0 | H15: ='Rating Engine'!C16 -> 2,500 - 5,000
B16: 10 | C16: ='Rating Engine'!B67 -> Storage factor | D16: ='Rating Engine'!C67 -> 0.9 | E16: =E15*D16 -> 1.7809707 | F16: =$F$6*E16 -> 8704.4943 | G16: =F16-F15 -> -967.16603 | H16: ='Rating Engine'!C17 -> Locked private garage w/ monitored alarm
B17: 11 | C17: ='Rating Engine'!B68 -> Security factor | D17: ='Rating Engine'!C68 -> 0.9 | E17: =E16*D17 -> 1.6028736 | F17: =$F$6*E17 -> 7834.0448 | G17: =F17-F16 -> -870.44943 | H17: ='Rating Engine'!C18 -> GPS tracker w/ recovery service
B18: 12 | C18: ='Rating Engine'!B69 -> PD deductible factor (value-banded) | D18: ='Rating Engine'!C69 -> 0.94 | E18: =E17*D18 -> 1.5067012 | F18: =$F$6*E18 -> 7364.0021 | G18: =F18-F17 -> -470.04269 | H18: ='Rating Engine'!C24 -> $5,000
B19: 13 | C19: ='Rating Engine'!B70 -> Valuation basis factor | D19: ='Rating Engine'!C70 -> 1 | E19: =E18*D19 -> 1.5067012 | F19: =$F$6*E19 -> 7364.0021 | G19: =F19-F18 -> 0 | H19: ='Rating Engine'!C25 -> Agreed Value
B20: 14 | C20: ='Rating Engine'!B71 -> Collection size credit | D20: ='Rating Engine'!C71 -> 0.95 | E20: =E19*D20 -> 1.4313661 | F20: =$F$6*E20 -> 6995.802 | G20: =F20-F19 -> -368.20011 | H20: ='Rating Engine'!C23 -> 2 - 3 vehicles
B21: 15 | C21: ='Rating Engine'!B72 -> Comprehensive deductible factor | D21: ='Rating Engine'!C72 -> 1 | E21: =E20*D21 -> 1.4313661 | F21: =$F$6*E21 -> 6995.802 | G21: =F21-F20 -> 0 | H21: ='Rating Engine'!C29 -> Same as physical damage deductible
B22: 16 | C22: ='Rating Engine'!B73 -> Glass deductible factor | D22: ='Rating Engine'!C73 -> 1 | E22: =E21*D22 -> 1.4313661 | F22: =$F$6*E22 -> 6995.802 | G22: =F22-F21 -> 0 | H22: ='Rating Engine'!C30 -> $500 flat, OEM glass
B23: 17 | C23: ='Rating Engine'!B74 -> Theft deductible factor | D23: ='Rating Engine'!C74 -> 1 | E23: =E22*D23 -> 1.4313661 | F23: =$F$6*E23 -> 6995.802 | G23: =F23-F22 -> 0 | H23: ='Rating Engine'!C31 -> Same as PD deductible
B24: 18 | C24: ='Rating Engine'!B75 -> Aggregate deductible factor | D24: ='Rating Engine'!C75 -> 1 | E24: =E23*D24 -> 1.4313661 | F24: =$F$6*E24 -> 6995.802 | G24: =F24-F23 -> 0 | H24: ='Rating Engine'!C32 -> Not applicable - per vehicle deductible
B25: 19 | C25: ='Rating Engine'!B76 -> Total loss waiver factor | D25: ='Rating Engine'!C76 -> 1 | E25: =E24*D25 -> 1.4313661 | F25: =$F$6*E25 -> 6995.802 | G25: =F25-F24 -> 0 | H25: ='Rating Engine'!C33 -> Not purchased
B26: 20 | C26: ='Rating Engine'!B77 -> Newly acquired vehicle factor | D26: ='Rating Engine'!C77 -> 1 | E26: =E25*D26 -> 1.4313661 | F26: =$F$6*E26 -> 6995.802 | G26: =F26-F25 -> 0 | H26: ='Rating Engine'!C34 -> $500,000 / 30 days
B27: 21 | C27: ='Rating Engine'!B78 -> Spare parts factor | D27: ='Rating Engine'!C78 -> 1 | E27: =E26*D27 -> 1.4313661 | F27: =$F$6*E27 -> 6995.802 | G27: =F27-F26 -> 0 | H27: ='Rating Engine'!C35 -> $25,000
B28: 22 | C28: ='Rating Engine'!B79 -> Personal effects factor | D28: ='Rating Engine'!C79 -> 1 | E28: =E27*D28 -> 1.4313661 | F28: =$F$6*E28 -> 6995.802 | G28: =F28-F27 -> 0 | H28: ='Rating Engine'!C36 -> $5,000
B29: 23 | C29: ='Rating Engine'!B80 -> Loss of use factor | D29: ='Rating Engine'!C80 -> 1 | E29: =E28*D29 -> 1.4313661 | F29: =$F$6*E29 -> 6995.802 | G29: =F29-F28 -> 0 | H29: ='Rating Engine'!C37 -> $10,000
B30: 24 | C30: ='Rating Engine'!B81 -> Transit factor | D30: ='Rating Engine'!C81 -> 1 | E30: =E29*D30 -> 1.4313661 | F30: =$F$6*E30 -> 6995.802 | G30: =F30-F29 -> 0 | H30: ='Rating Engine'!C38 -> Enclosed carrier only
B31: 25 | C31: ='Rating Engine'!B82 -> Worldwide territory factor | D31: ='Rating Engine'!C82 -> 1 | E31: =E30*D31 -> 1.4313661 | F31: =$F$6*E31 -> 6995.802 | G31: =F31-F30 -> 0 | H31: ='Rating Engine'!C39 -> Not required - US and Canada only
B32: 26 | C32: ='Rating Engine'!B83 -> Unobtainable parts factor | D32: ='Rating Engine'!C83 -> 1 | E32: =E31*D32 -> 1.4313661 | F32: =$F$6*E32 -> 6995.802 | G32: =F32-F31 -> 0 | H32: ='Rating Engine'!C40 -> $100,000
... B34: 28 | C34: ='Rating Engine'!B85 -> Per-location aggregate factor | D34: ='Rating Engine'!C85 -> 1 | E34: =E33*D34 -> 1.4313661 | F34: =$F$6*E34 -> 6995.802 | G34: =F34-F33 -> 0 | H34: ='Rating Engine'!C42 -> $10,000,000
C35: RATED PD LOSS COST (checks to Rating Engine row 91) | E35: =E34 -> 1.4313661 | F35: =F34 -> 6995.802 | H35: =IF(ROUND(F35-'Rating Engine'!C91,2)=0,"AGREES with Rating Engine row 91","VARIANCE - investigate") -> AGREES with Rating Engine row 91
B37: SECTION B - PREMIUM WATERFALL
C38: Component | E38: Amount ($) | F38: Running total ($) | G38: % of technical premium | H38: Per $100 of agreed value
C39: Rated physical damage loss cost | E39: ='Rating Engine'!C91 -> 6995.802 | F39: =E39 -> 6995.802 | G39: =E39/'Rating Engine'!C105 -> 0.27918918 | H39: =E39/'Rating Engine'!C11*100 -> 1.6460711
C40: Rated liability loss cost | E40: ='Rating Engine'!C94 -> 1747.1538 | F40: =F39+E40 -> 8742.9558 | G40: =E40/'Rating Engine'!C105 -> 0.069725591 | H40: =E40/'Rating Engine'!C11*100 -> 0.41109501
C41: Allocated loss adjustment expense (ALAE) | E41: ='Rating Engine'!C96 -> 699.43647 | F41: =F40+E41 -> 9442.3923 | G41: =E41/'Rating Engine'!C105 -> 0.027913181 | H41: =E41/'Rating Engine'!C11*100 -> 0.16457329
C42: Unallocated loss adjustment expense (ULAE) | E42: ='Rating Engine'!C98 -> 472.11962 | F42: =F41+E42 -> 9914.5119 | G42: =E42/'Rating Engine'!C105 -> 0.018841397 | H42: =E42/'Rating Engine'!C11*100 -> 0.11108697
C43: Catastrophe load | E43: ='Rating Engine'!C100 -> 3022.1865 | F43: =F42+E43 -> 12936.698 | G43: =E43/'Rating Engine'!C105 -> 0.12060972 | H43: =E43/'Rating Engine'!C11*100 -> 0.7111027
...

Sheet Portfolio Register
B1: PORTFOLIO REGISTER - ONE ROW PER VEHICLE
B2: The whole rating chain run across the book: add a vehicle by filling the blue columns on the next empty row. 300 rows are pre-built; grey columns calculate. To audit any single row in full detail, re-key it on the Rating Engine.
A3: VEHICLE / POLICY | N3: RISK INPUTS | AB3: DEDUCTIBLE SELECTIONS | AG3: SUB-LIMIT SELECTIONS | AR3: CAT DETERMINATION | AW3: BAND & FACTORS | CB3: PREMIUM BUILD | CU3: COMMISSION & OUTCOME | DA3: APPROVAL AND AUDIT
A4: Vehicle ref / certificate no. | B4: Named insured | C4: Effective date | D4: Expiry date | E4: Vehicle year | F4: Make | G4: Model | H4: VIN / chassis | I4: Vehicle class | J4: Agreed value (USD) | K4: Garaging state | L4: Garaging ZIP | M4: Policy type | N4: Usage category | O4: Annual mileage band | P4: Storage / garaging | Q4: Security | R4: Driver age band | S4: Performance experience | T4: MVR record | U4: Claims history | V4: Collection size | W4: PD deductible | X4: Valuation basis | Y4: Liability limit | Z4: Rating city / metro | AA4: Cat deductible | AB4: Comprehensive ded basis | AC4: Glass deductible | AD4: Theft deductible | AE4: Aggregate deductible | AF4: Total loss waiver | AG4: Newly acquired vehicle | AH4: Spare parts / automobilia | AI4: Personal effects | AJ4: Loss of use | AK4: Transit / transport | AL4: Worldwide territory | AM4: Unobtainable parts | AN4: Diminution in value | AO4: Per-location aggregate | AP4: Cat zone override (optional) | AQ4: UW judgement adj (%) | AR4: ZIP-3 | AS4: CAT ZONE | AT4: Zone source | AU4: Zone mult | AV4: Cat ded credit | AW4: Value band | AX4: Base rate /$100 | AY4: Base PD loss cost | AZ4: f Make | BA4: f Age | BB4: f Exp | BC4: f MVR | BD4: f Claims | BE4: f State | BF4: f Metro | BG4: f Usage | BH4: f Miles | BI4: f Storage | BJ4: f Security | BK4: f PD ded | BL4: f Valuation | BM4: f Collection | BN4: f Comprehensive de | BO4: f Glass deductible | BP4: f Theft deductible | BQ4: f Aggregate deduct | BR4: f Total loss deduc | BS4: f Automatically ac | BT4: f Spare parts, too | BU4: f Personal effects | BV4: f Loss of use / su | BW4: f Transit and tran | BX4: f Worldwide territ | BY4: f Unobtainable par | BZ4: f Diminution in va | CA4: f Per-location all | CB4: CORE FACTOR PRODUCT | CC4: COVERAGE FACTOR PRODUCT | CD4: COMPOSITE (capped) | CE4: Rated PD loss cost | CF4: Liab base | CG4: ILF | CH4: Rated liability | CI4: Expected loss | CJ4: Loss + ALAE + ULAE | CK4: Cat load $ | CL4: PURE RISK PREMIUM | CM4: TECHNICAL PREMIUM | CN4: Technical rate /$100 | CO4: GWP (charged) | CP4: Charged rate /$100 | CQ4: Rate adequacy | CR4: Fees | CS4: SL tax + stamping | CT4: TOTAL DUE | CU4: Broker commission | CV4: MGA net commission | CW4: Net to capacity | CX4: STATUS | CY4: Variance to technical | CZ4: Bind band | DA4: Referral reason (auto) | DB4: Approver name | DC4: Approver role | DD4: Approval date | DE4: Approval basis / rationale | DF4: Conditions imposed | DG4: BIND PERMITTED? | DH4: Ref seq | DI4: Notes
A5: V-0001 | B5: Carrera Holdings LLC | C5: 46082 | D5: 46631 | E5: 2024 | F5: Ferrari | G5: 296 GTB | H5: ZFF01SMA5P0290114 | I5: 03 - Supercar | J5: 425000 | K5: Florida | L5: 33139 | M5: Personal | N5: Personal - regular use | O5: 2,500 - 5,000 | P5: Locked private garage w/ monitored alarm | Q5: GPS tracker w/ recovery service | R5: 45 - 54 | S5: 5 - 10 years | T5: Clean - no violations 3 yrs | U5: No at-fault claims - 5 yrs | V5: 2 - 3 vehicles | W5: $5,000 | X5: Agreed Value | Y5: $1,000,000 CSL | Z5: Miami - Fort Lauderdale, FL | AA5: 2% of agreed value, minimum $10,000 | AQ5: 0 | AR5: =IF($A5="","",IFERROR(LEFT(TEXT(VALUE($L5),"00000"),3),"---")) -> 331 | AS5: =IF($A5="","",IF($AP5<>"",$AP5,IFERROR(INDEX('Cat Zone by ZIP'!$D$6:$D$856,MATCH($AR5,'Cat Zone by ZIP'!$B$6:$B$856,0)),IFERROR(INDEX('Cat Zone by ZIP'!$C$860:$C$910,MATCH($K5,'Cat Zone by ZIP'!$B$860:$B$910,0)),"NOT FOUND")))) -> Tier 1 - Coastal wind / surge (0-1 mile, FEMA V or Coastal A) | AT5: =IF($A5="","",IF($AP5<>"","Override",IF(ISNUMBER(MATCH($AR5,'Cat Zone by ZIP'!$B$6:$B$856,0)),"ZIP-3","State default"))) -> ZIP-3 | AU5: =IF($A5="","",IFERROR(INDEX('Natural Catastrophe'!$D$6:$D$17,MATCH($AS5,'Natural Catastrophe'!$B$6:$B$17,0)),"?")) -> 3 | AV5: =IF($A5="","",IFERROR(INDEX('Natural Catastrophe'!$C$21:$C$26,MATCH($AA5,'Natural Catastrophe'!$B$21:$B$26,0)),"?")) -> 0.8 | AW5: =IF($A5="","",IFERROR(INDEX('Base Rates'!$C$4:$I$4,MATCH(MAX($J5,'Technical Premium'!$C$18),'Base Rates'!$C$3:$I$3,1)),"?")) -> $250k - $500k | AX5: =IF($A5="","",IFERROR(INDEX('Base Rates'!$C$5:$I$16,MATCH($I5,'Base Rates'!$B$5:$B$16,0),MATCH(MAX($J5,'Technical Premium'!$C$18),'Base Rates'!$C$3:$I$3,1)),"?")) -> 1.15 | AY5: =IF(ISNUMBER($AX5),$J5/100*$AX5,"") -> 4887.5 | AZ5: =IF($A5="","",IFERROR(INDEX('Make Factors'!$G$5:$G$69,MATCH($F5,'Make Factors'!$B$5:$B$69,0)),"?")) -> 1.087 | BA5: =IF($A5="","",IFERROR(INDEX('Driver Factors'!$C$6:$C$15,MATCH($R5,'Driver Factors'!$B$6:$B$15,0)),"?")) -> 1 | BB5: =IF($A5="","",IFERROR(INDEX('Driver Factors'!$C$19:$C$24,MATCH($S5,'Driver Factors'!$B$19:$B$24,0)),"?")) -> 1 | BC5: =IF($A5="","",IFERROR(INDEX('Driver Factors'!$C$28:$C$36,MATCH($T5,'Driver Factors'!$B$28:$B$36,0)),"?")) -> 1 | BD5: =IF($A5="","",IFERROR(INDEX('Claims History'!$C$6:$C$15,MATCH($U5,'Claims History'!$B$6:$B$15,0)),"?")) -> 0.9 | BE5: =IF($A5="","",IFERROR(INDEX('Territory Factors'!$E$6:$E$56,MATCH($K5,'Territory Factors'!$B$6:$B$56,0)),"?")) -> 1.45 | BF5: =IF($A5="","",IFERROR(INDEX('City Accident Ratings'!$G$6:$G$54,MATCH($Z5,'City Accident Ratings'!$B$6:$B$54,0)),"?")) -> 1.395 | BG5: =IF($A5="","",IFERROR(INDEX('Usage and Coverage'!$D$6:$D$20,MATCH($N5,'Usage and Coverage'!$C$6:$C$20,0)),"?")) -> 1 | BH5: =IF($A5="","",IFERROR(INDEX('Usage and Coverage'!$C$24:$C$30,MATCH($O5,'Usage and Coverage'!$B$24:$B$30,0)),"?")) -> 1 | BI5: =IF($A5="","",IFERROR(INDEX('Usage and Coverage'!$C$34:$C$40,MATCH($P5,'Usage and Coverage'!$B$34:$B$40,0)),"?")) -> 0.9 | BJ5: =IF($A5="","",IFERROR(INDEX('Usage and Coverage'!$C$44:$C$49,MATCH($Q5,'Usage and Coverage'!$B$44:$B$49,0)),"?")) -> 0.9 | BK5: =IF($A5="","",IFERROR(INDEX(Deductibles!$C$6:$I$15,MATCH($W5,Deductibles!$B$6:$B$15,0),MATCH(MAX($J5,'Technical Premium'!$C$18),'Base Rates'!$C$3:$I$3,1)),"?")) -> 0.94 | BL5: =IF($A5="","",IFERROR(INDEX('Usage and Coverage'!$C$63:$C$66,MATCH($X5,'Usage and Coverage'!$B$63:$B$66,0)),"?")) -> 1 | BM5: =IF($A5="","",IFERROR(INDEX('Usage and Coverage'!$C$70:$C$75,MATCH($V5,'Usage and Coverage'!$B$70:$B$75,0)),"?")) -> 0.95 | BN5: =IF($A5="","",IF($AB5="",1,IFERROR(INDEX(Deductibles!$C$48:$C$51,MATCH($AB5,Deductibles!$B$48:$B$51,0)),"?"))) -> 1 | BO5: =IF($A5="","",IF($AC5="",1,IFERROR(INDEX(Deductibles!$C$55:$C$57,MATCH($AC5,Deductibles!$B$55:$B$57,0)),"?"))) -> 1 | BP5: =IF($A5="","",IF($AD5="",1,IFERROR(INDEX(Deductibles!$C$61:$C$63,MATCH($AD5,Deductibles!$B$61:$B$63,0)),"?"))) -> 1 | BQ5: =IF($A5="","",IF($AE5="",1,IFERROR(INDEX(Deductibles!$C$67:$C$69,MATCH($AE5,Deductibles!$B$67:$B$69,0)),"?"))) -> 1 | BR5: =IF($A5="","",IF($AF5="",1,IFERROR(INDEX(Deductibles!$C$73:$C$74,MATCH($AF5,Deductibles!$B$73:$B$74,0)),"?"))) -> 1 | BS5: =IF($A5="","",IF($AG5="",1,IFERROR(INDEX('Sublimits and Parts'!$C$49:$C$52,MATCH($AG5,'Sublimits and Parts'!$B$49:$B$52,0)),"?"))) -> 1 | BT5: =IF($A5="","",IF($AH5="",1,IFERROR(INDEX('Sublimits and Parts'!$C$56:$C$60,MATCH($AH5,'Sublimits and Parts'!$B$56:$B$60,0)),"?"))) -> 1 | BU5: =IF($A5="","",IF($AI5="",1,IFERROR(INDEX('Sublimits and Parts'!$C$64:$C$67,MATCH($AI5,'Sublimits and Parts'!$B$64:$B$67,0)),"?"))) -> 1 | BV5: =IF($A5="","",IF($AJ5="",1,IFERROR(INDEX('Sublimits and Parts'!$C$71:$C$74,MATCH($AJ5,'Sublimits and Parts'!$B$71:$B$74,0)),"?"))) -> 1 | BW5: =IF($A5="","",IF($AK5="",1,IFERROR(INDEX('Sublimits and Parts'!$C$78:$C$80,MATCH($AK5,'Sublimits and Parts'!$B$78:$B$80,0)),"?"))) -> 1 | BX5: =IF($A5="","",IF($AL5="",1,IFERROR(INDEX('Sublimits and Parts'!$C$84:$C$87,MATCH($AL5,'Sublimits and Parts'!$B$84:$B$87,0)),"?"))) -> 1 | BY5: =IF($A5="","",IF($AM5="",1,IFERROR(INDEX('Sublimits and Parts'!$C$91:$C$94,MATCH($AM5,'Sublimits and Parts'!$B$91:$B$94,0)),"?"))) -> 1 | BZ5: =IF($A5="","",IF($AN5="",1,IFERROR(INDEX('Sublimits and Parts'!$C$98:$C$101,MATCH($AN5,'Sublimits and Parts'!$B$98:$B$101,0)),"?"))) -> 1 | CA5: =IF($A5="","",IF($AO5="",1,IFERROR(INDEX('Sublimits and Parts'!$C$105:$C$109,MATCH($AO5,'Sublimits and Parts'!$B$105:$B$109,0)),"?"))) -> 1 | CB5: =IF($A5="","",IF(SUMPRODUCT(--ISTEXT($AZ5:$BM5))>0,"?",PRODUCT($AZ5:$BM5))) -> 1.4313661 | CC5: =IF($A5="","",IF(SUMPRODUCT(--ISTEXT($BN5:$CA5))>0,"?",PRODUCT($BN5:$CA5))) -> 1 | CD5: =IF($A5="","",IF(OR($CB5="?",$CC5="?"),"?",MIN($CB5*$CC5,'Technical Premium'!$C$17))) -> 1.4313661 | CE5: =IF(ISNUMBER($CD5),$AY5*$CD5,"") -> 6995.802 | CF5: =IF($A5="","",IFERROR(INDEX('Territory Factors'!$F$6:$F$56,MATCH($K5,'Territory Factors'!$B$6:$B$56,0)),"?")) -> 980 | CG5: =IF($A5="","",IFERROR(INDEX('Usage and Coverage'!$C$79:$C$84,MATCH($Y5,'Usage and Coverage'!$B$79:$B$84,0)),"?")) -> 1.42 | CH5: =IFERROR(IF(ISNUMBER($CD5),$CF5*$CG5*MIN($BG5*$BA5*$BC5*$BD5*$BH5*$BF5,'Technical Premium'!$C$17),""),"") -> 1747.1538 | CI5: =IFERROR($CE5+$CH5,"") -> 8742.9558 | CJ5: =IFERROR($CI5*(1+'Technical Premium'!$C$5)*(1+'Technical Premium'!$C$6),"") -> 9914.5119 | CK5: =IFERROR($CE5*INDEX('Territory Factors'!$G$6:$G$56,MATCH($K5,'Territory Factors'!$B$6:$B$56,0))*$AU5*$AV5,"") -> 3022.1865 | CL5: =IFERROR(($CJ5+$CK5)*(1+'Technical Premium'!$C$7),"") -> 13906.951 | CM5: =IFERROR($CL5/'Technical Premium'!$C$13,"") -> 25057.569 | CN5: =IFERROR($CM5/$J5*100,"") -> 5.8958986 | CO5: =IFERROR($CM5*(1+N($AQ5)),"") -> 25057.569 | CP5: =IFERROR($CO5/$J5*100,"") -> 5.8958986 | CQ5: =IFERROR($CP5/$CN5,"") -> 1 | CR5: =IF(ISNUMBER($CM5),'Technical Premium'!$C$14+IF($J5>=1000000,'Technical Premium'!$C$15,0),"") -> 350 | CS5: =IFERROR(($CO5+$CR5)*(INDEX('Territory Factors'!$K$6:$K$56,MATCH($K5,'Territory Factors'!$B$6:$B$56,0))+'Commission Structure'!$C$21),"") -> 1300.8675 | CT5: =IFERROR($CO5+$CR5+$CS5,"") -> 26708.437 | CU5: =IFERROR($CO5*('Commission Structure'!$C$6+'Commission Structure'!$C$7),"") -> 4385.0746 | CV5: =IFERROR($CO5*'Commission Structure'!$C$5-$CU5,"") -> 2505.7569 | CW5: =IFERROR($CO5*(1-'Commission Structure'!$C$5),"") -> 18166.738 | CX5: =IF($A5="","",IF(OR($CB5="?",$CC5="?",NOT(ISNUMBER($AU5))),"CHECK INPUTS",IF(OR($J5<'Technical Premium'!$C$18,LEFT(IFERROR(INDEX('Driver Factors'!$D$6:$D$15,MATCH($R5,'Driver Factors'!$B$6:$B$15,0)),""),7)="DECLINE",LEFT(IFERROR(INDEX('Driver Factors'!$D$28:$D$36,MATCH($T5,'Driver Factors'!$B$28:$B$36,0)),""),7)="DECLINE",LEFT(IFERROR(INDEX('Claims History'!$D$6:$D$15,MATCH($U5,'Claims History'!$B$6:$B$15,0)),""),7)="DECLINE",LEFT(IFERROR(INDEX('Usage and Coverage'!$E$6:$E$20,MATCH($N5,'Usage and Coverage'!$C$6:$C$20,0)),""),7)="DECLINE"),"DECLINE",IF(OR($CD5>2.5,$CD5>='Technical Premium'!$C$17,$J5>='Technical Premium'!$C$16,N($AQ5)<'Technical Premium'!$C$19,N($AQ5)>'Technical Premium'!$C$20,LEFT(IFERROR(INDEX('Driver Factors'!$D$6:$D$15,MATCH($R5,'Driver Factors'!$B$6:$B$15,0)),""),5)="Refer",LEFT(IFERROR(INDEX('Driver Factors'!$D$28:$D$36,MATCH($T5,'Driver Factors'!$B$28:$B$36,0)),""),5)="Refer",LEFT(IFERROR(INDEX('Claims History'!$D$6:$D$15,MATCH($U5,'Claims History'!$B$6:$B$15,0)),""),5)="Refer",LEFT(IFERROR(INDEX('Usage and Coverage'!$E$6:$E$20,MATCH($N5,'Usage and Coverage'!$C$6:$C$20,0)),""),5)="Refer"),"REFER","AUTO-BIND")))) -> AUTO-BIND | CY5: =IFERROR($CO5/$CM5-1,"") -> 0 | CZ5: =IF($CY5="","",IF($CY5<'Technical Premium'!$C$19,"BEYOND AUTHORITY",IF($CY5>0.005,"Above technical",IF($CY5<-0.005,"BELOW technical","At technical")))) -> At technical | DA5: =IF($A5="","",IF($CX5="AUTO-BIND","",TRIM(IF($J5<'Technical Premium'!$C$18,"Below programme minimum agreed value. ","")&IF(N($AQ5)<'Technical Premium'!$C$19,"DISCOUNT AUTHORITY BREACH. ","")&IF(N($AQ5)>'Technical Premium'!$C$20,"Load authority breach. ","")&IF($J5>='Technical Premium'!$C$16,"Agreed value at or above auto-bind limit. ","")&IF(AND(ISNUMBER($CD5),$CD5>='Technical Premium'!$C$17),"Composite factor at cap. ","")&IF(AND(ISNUMBER($CD5),$CD5>2.5),"Composite factor above 2.50. ","")&IF(LEFT(IFERROR(INDEX('Driver Factors'!$D$6:$D$15,MATCH($R5,'Driver Factors'!$B$6:$B$15,0)),""),7)="DECLINE","DECLINE - driver age. ",IF(LEFT(IFERROR(INDEX('Driver Factors'!$D$6:$D$15,MATCH($R5,'Driver Factors'!$B$6:$B$15,0)),""),5)="Refer","Driver age band. ",""))&IF(LEFT(IFERROR(INDEX('Driver Factors'!$D$28:$D$36,MATCH($T5,'Driver Factors'!$B$28:$B$36,0)),""),7)="DECLINE","DECLINE - MVR. ",IF(LEFT(IFERROR(INDEX('Driver Factors'!$D$28:$D$36,MATCH($T5,'Driver Factors'!$B$28:$B$36,0)),""),5)="Refer","MVR record. ",""))&IF(LEFT(IFERROR(INDEX('Claims History'!$D$6:$D$15,MATCH($U5,'Claims History'!$B$6:$B$15,0)),""),7)="DECLINE","DECLINE - claims. ",IF(LEFT(IFERROR(INDEX('Claims History'!$D$6:$D$15,MATCH($U5,'Claims History'!$B$6:$B$15,0)),""),5)="Refer","Claims history. ",""))&IF(LEFT(IFERROR(INDEX('Usage and Coverage'!$E$6:$E$20,MATCH($N5,'Usage and Coverage'!$C$6:$C$20,0)),""),7)="DECLINE","DECLINE - usage class. ",IF(LEFT(IFERROR(INDEX('Usage and Coverage'!$E$6:$E$20,MATCH($N5,'Usage and Coverage'!$C$6:$C$20,0)),""),5)="Refer","Usage class. ",""))&IF($CX5="CHECK INPUTS","Incomplete inputs. ","")))) | DG5: =IF($A5="","",IF($CX5="DECLINE","NO - DECLINED",IF($CX5="CHECK INPUTS","NO - INCOMPLETE INPUTS",IF($CX5="AUTO-BIND","YES - within authority",IF(AND($DB5<>"",$DD5<>""),"YES - approved "&TEXT($DD5,"dd-mmm-yy"),"NO - AWAITING APPROVAL"))))) -> YES - within authority | DH5: =IF($A5="","",IF(OR($CX5="REFER",$CX5="DECLINE"),COUNTIF($CX$5:$CX5,"REFER")+COUNTIF($CX$5:$CX5,"DECLINE"),""))
A6: V-0002 | B6: Sonoran Collection Trust | C6: 46113 | D6: 46631 | E6: 2021 | F6: Bugatti | G6: Chiron Pur Sport | H6: VF9SP3V33MM795112 | I6: 04 - Hypercar | J6: 3600000 | K6: Arizona | L6: 85253 | M6: Personal | N6: Collector - pleasure use only | O6: Under 1,000 | P6: Secure collection facility - climate controlled | Q6: Kill switch + GPS + monitored alarm | R6: 55 - 64 | S6: 10 + years | T6: Clean - no violations 3 yrs | U6: No claims + 3 yrs prior collector policy | V6: 11 - 20 vehicles | W6: $100,000 | X6: Agreed Value + Appreciation clause | Y6: $5,000,000 CSL | Z6: Phoenix - Scottsdale, AZ | AA6: 2% of agreed value, minimum $10,000 | AH6: $250,000 | AL6: $2,000,000 per vehicle / 90 days | AN6: 20% of agreed value (EX-05) | AO6: $25,000,000 | AQ6: 0 | AR6: =IF($A6="","",IFERROR(LEFT(TEXT(VALUE($L6),"00000"),3),"---")) -> 852 | AS6: =IF($A6="","",IF($AP6<>"",$AP6,IFERROR(INDEX('Cat Zone by ZIP'!$D$6:$D$856,MATCH($AR6,'Cat Zone by ZIP'!$B$6:$B$856,0)),IFERROR(INDEX('Cat Zone by ZIP'!$C$860:$C$910,MATCH($K6,'Cat Zone by ZIP'!$B$860:$B$910,0)),"NOT FOUND")))) -> Severe convective - hail / tornado (moderate) | AT6: =IF($A6="","",IF($AP6<>"","Override",IF(ISNUMBER(MATCH($AR6,'Cat Zone by ZIP'!$B$6:$B$856,0)),"ZIP-3","State default"))) -> ZIP-3 | AU6: =IF($A6="","",IFERROR(INDEX('Natural Catastrophe'!$D$6:$D$17,MATCH($AS6,'Natural Catastrophe'!$B$6:$B$17,0)),"?")) -> 1.5 | AV6: =IF($A6="","",IFERROR(INDEX('Natural Catastrophe'!$C$21:$C$26,MATCH($AA6,'Natural Catastrophe'!$B$21:$B$26,0)),"?")) -> 0.8 | AW6: =IF($A6="","",IFERROR(INDEX('Base Rates'!$C$4:$I$4,MATCH(MAX($J6,'Technical Premium'!$C$18),'Base Rates'!$C$3:$I$3,1)),"?")) -> $2.0M - $5.0M | AX6: =IF($A6="","",IFERROR(INDEX('Base Rates'!$C$5:$I$16,MATCH($I6,'Base Rates'!$B$5:$B$16,0),MATCH(MAX($J6,'Technical Premium'!$C$18),'Base Rates'!$C$3:$I$3,1)),"?")) -> 0.82 | AY6: =IF(ISNUMBER($AX6),$J6/100*$AX6,"") -> 29520 | AZ6: =IF($A6="","",IFERROR(INDEX('Make Factors'!$G$5:$G$69,MATCH($F6,'Make Factors'!$B$5:$B$69,0)),"?")) -> 1.607 | BA6: =IF($A6="","",IFERROR(INDEX('Driver Factors'!$C$6:$C$15,MATCH($R6,'Driver Factors'!$B$6:$B$15,0)),"?")) -> 1 | BB6: =IF($A6="","",IFERROR(INDEX('Driver Factors'!$C$19:$C$24,MATCH($S6,'Driver Factors'!$B$19:$B$24,0)),"?")) -> 0.95 | BC6: =IF($A6="","",IFERROR(INDEX('Driver Factors'!$C$28:$C$36,MATCH($T6,'Driver Factors'!$B$28:$B$36,0)),"?")) -> 1 | BD6: =IF($A6="","",IFERROR(INDEX('Claims History'!$C$6:$C$15,MATCH($U6,'Claims History'!$B$6:$B$15,0)),"?")) -> 0.85 | BE6: =IF($A6="","",IFERROR(INDEX('Territory Factors'!$E$6:$E$56,MATCH($K6,'Territory Factors'!$B$6:$B$56,0)),"?")) -> 1.1 | BF6: =IF($A6="","",IFERROR(INDEX('City Accident Ratings'!$G$6:$G$54,MATCH($Z6,'City Accident Ratings'!$B$6:$B$54,0)),"?")) -> 1.18 | BG6: =IF($A6="","",IFERROR(INDEX('Usage and Coverage'!$D$6:$D$20,MATCH($N6,'Usage and Coverage'!$C$6:$C$20,0)),"?")) -> 0.85 | BH6: =IF($A6="","",IFERROR(INDEX('Usage and Coverage'!$C$24:$C$30,MATCH($O6,'Usage and Coverage'!$B$24:$B$30,0)),"?")) -> 0.75 | BI6: =IF($A6="","",IFERROR(INDEX('Usage and Coverage'!$C$34:$C$40,MATCH($P6,'Usage and Coverage'!$B$34:$B$40,0)),"?")) -> 0.85 | BJ6: =IF($A6="","",IFERROR(INDEX('Usage and Coverage'!$C$44:$C$49,MATCH($Q6,'Usage and Coverage'!$B$44:$B$49,0)),"?")) -> 0.85 | BK6: =IF($A6="","",IFERROR(INDEX(Deductibles!$C$6:$I$15,MATCH($W6,Deductibles!$B$6:$B$15,0),MATCH(MAX($J6,'Technical Premium'!$C$18),'Base Rates'!$C$3:$I$3,1)),"?")) -> 0.78 | BL6: =IF($A6="","",IFERROR(INDEX('Usage and Coverage'!$C$63:$C$66,MATCH($X6,'Usage and Coverage'!$B$63:$B$66,0)),"?")) -> 1.06 | BM6: =IF($A6="","",IFERROR(INDEX('Usage and Coverage'!$C$70:$C$75,MATCH($V6,'Usage and Coverage'!$B$70:$B$75,0)),"?")) -> 0.82 | BN6: =IF($A6="","",IF($AB6="",1,IFERROR(INDEX(Deductibles!$C$48:$C$51,MATCH($AB6,Deductibles!$B$48:$B$51,0)),"?"))) -> 1 | BO6: =IF($A6="","",IF($AC6="",1,IFERROR(INDEX(Deductibles!$C$55:$C$57,MATCH($AC6,Deductibles!$B$55:$B$57,0)),"?"))) -> 1 | BP6: =IF($A6="","",IF($AD6="",1,IFERROR(INDEX(Deductibles!$C$61:$C$63,MATCH($AD6,Deductibles!$B$61:$B$63,0)),"?"))) -> 1 | BQ6: =IF($A6="","",IF($AE6="",1,IFERROR(INDEX(Deductibles!$C$67:$C$69,MATCH($AE6,Deductibles!$B$67:$B$69,0)),"?"))) -> 1 | BR6: =IF($A6="","",IF($AF6="",1,IFERROR(INDEX(Deductibles!$C$73:$C$74,MATCH($AF6,Deductibles!$B$73:$B$74,0)),"?"))) -> 1 | BS6: =IF($A6="","",IF($AG6="",1,IFERROR(INDEX('Sublimits and Parts'!$C$49:$C$52,MATCH($AG6,'Sublimits and Parts'!$B$49:$B$52,0)),"?"))) -> 1 | BT6: =IF($A6="","",IF($AH6="",1,IFERROR(INDEX('Sublimits and Parts'!$C$56:$C$60,MATCH($AH6,'Sublimits and Parts'!$B$56:$B$60,0)),"?"))) -> 1.035 | BU6: =IF($A6="","",IF($AI6="",1,IFERROR(INDEX('Sublimits and Parts'!$C$64:$C$67,MATCH($AI6,'Sublimits and Parts'!$B$64:$B$67,0)),"?"))) -> 1 | BV6: =IF($A6="","",IF($AJ6="",1,IFERROR(INDEX('Sublimits and Parts'!$C$71:$C$74,MATCH($AJ6,'Sublimits and Parts'!$B$71:$B$74,0)),"?"))) -> 1 | BW6: =IF($A6="","",IF($AK6="",1,IFERROR(INDEX('Sublimits and Parts'!$C$78:$C$80,MATCH($AK6,'Sublimits and Parts'!$B$78:$B$80,0)),"?"))) -> 1 | BX6: =IF($A6="","",IF($AL6="",1,IFERROR(INDEX('Sublimits and Parts'!$C$84:$C$87,MATCH($AL6,'Sublimits and Parts'!$B$84:$B$87,0)),"?"))) -> 1.1 | BY6: =IF($A6="","",IF($AM6="",1,IFERROR(INDEX('Sublimits and Parts'!$C$91:$C$94,MATCH($AM6,'Sublimits and Parts'!$B$91:$B$94,0)),"?"))) -> 1 | BZ6: =IF($A6="","",IF($AN6="",1,IFERROR(INDEX('Sublimits and Parts'!$C$98:$C$101,MATCH($AN6,'Sublimits and Parts'!$B$98:$B$101,0)),"?"))) -> 1.045 | CA6: =IF($A6="","",IF($AO6="",1,IFERROR(INDEX('Sublimits and Parts'!$C$105:$C$109,MATCH($AO6,'Sublimits and Parts'!$B$105:$B$109,0)),"?"))) -> 1.03 | CB6: =IF($A6="","",IF(SUMPRODUCT(--ISTEXT($AZ6:$BM6))>0,"?",PRODUCT($AZ6:$BM6))) -> 0.52597543 | CC6: =IF($A6="","",IF(SUMPRODUCT(--ISTEXT($BN6:$CA6))>0,"?",PRODUCT($BN6:$CA6))) -> 1.2254245 | CD6: =IF($A6="","",IF(OR($CB6="?",$CC6="?"),"?",MIN($CB6*$CC6,'Technical Premium'!$C$17))) -> 0.64454317 | CE6: =IF(ISNUMBER($CD6),$AY6*$CD6,"") -> 19026.914 | CF6: =IF($A6="","",IFERROR(INDEX('Territory Factors'!$F$6:$F$56,MATCH($K6,'Territory Factors'!$B$6:$B$56,0)),"?")) -> 520 | CG6: =IF($A6="","",IFERROR(INDEX('Usage and Coverage'!$C$79:$C$84,MATCH($Y6,'Usage and Coverage'!$B$79:$B$84,0)),"?")) -> 2.05 | CH6: =IFERROR(IF(ISNUMBER($CD6),$CF6*$CG6*MIN($BG6*$BA6*$BC6*$BD6*$BH6*$BF6,'Technical Premium'!$C$17),""),"") -> 681.61372 | CI6: =IFERROR($CE6+$CH6,"") -> 19708.528 | CJ6: =IFERROR($CI6*(1+'Technical Premium'!$C$5)*(1+'Technical Premium'!$C$6),"") -> 22349.471 | CK6: =IFERROR($CE6*INDEX('Territory Factors'!$G$6:$G$56,MATCH($K6,'Territory Factors'!$B$6:$B$56,0))*$AU6*$AV6,"") -> 1027.4534 | CL6: =IFERROR(($CJ6+$CK6)*(1+'Technical Premium'!$C$7),"") -> 25130.194 | CM6: =IFERROR($CL6/'Technical Premium'!$C$13,"") -> 45279.628 | CN6: =IFERROR($CM6/$J6*100,"") -> 1.2577674 | CO6: =IFERROR($CM6*(1+N($AQ6)),"") -> 45279.628 | CP6: =IFERROR($CO6/$J6*100,"") -> 1.2577674 | CQ6: =IFERROR($CP6/$CN6,"") -> 1 | CR6: =IF(ISNUMBER($CM6),'Technical Premium'!$C$14+IF($J6>=1000000,'Technical Premium'!$C$15,0),"") -> 600 | CS6: =IFERROR(($CO6+$CR6)*(INDEX('Territory Factors'!$K$6:$K$56,MATCH($K6,'Territory Factors'!$B$6:$B$56,0))+'Commission Structure'!$C$21),"") -> 1458.9722 | CT6: =IFERROR($CO6+$CR6+$CS6,"") -> 47338.6 | CU6: =IFERROR($CO6*('Commission Structure'!$C$6+'Commission Structure'!$C$7),"") -> 7923.9349 | CV6: =IFERROR($CO6*'Commission Structure'!$C$5-$CU6,"") -> 4527.9628 | CW6: =IFERROR($CO6*(1-'Commission Structure'!$C$5),"") -> 32827.73 | CX6: =IF($A6="","",IF(OR($CB6="?",$CC6="?",NOT(ISNUMBER($AU6))),"CHECK INPUTS",IF(OR($J6<'Technical Premium'!$C$18,LEFT(IFERROR(INDEX('Driver Factors'!$D$6:$D$15,MATCH($R6,'Driver Factors'!$B$6:$B$15,0)),""),7)="DECLINE",LEFT(IFERROR(INDEX('Driver Factors'!$D$28:$D$36,MATCH($T6,'Driver Factors'!$B$28:$B$36,0)),""),7)="DECLINE",LEFT(IFERROR(INDEX('Claims History'!$D$6:$D$15,MATCH($U6,'Claims History'!$B$6:$B$15,0)),""),7)="DECLINE",LEFT(IFERROR(INDEX('Usage and Coverage'!$E$6:$E$20,MATCH($N6,'Usage and Coverage'!$C$6:$C$20,0)),""),7)="DECLINE"),"DECLINE",IF(OR($CD6>2.5,$CD6>='Technical Premium'!$C$17,$J6>='Technical Premium'!$C$16,N($AQ6)<'Technical Premium'!$C$19,N($AQ6)>'Technical Premium'!$C$20,LEFT(IFERROR(INDEX('Driver Factors'!$D$6:$D$15,MATCH($R6,'Driver Factors'!$B$6:$B$15,0)),""),5)="Refer",LEFT(IFERROR(INDEX('Driver Factors'!$D$28:$D$36,MATCH($T6,'Driver Factors'!$B$28:$B$36,0)),""),5)="Refer",LEFT(IFERROR(INDEX('Claims History'!$D$6:$D$15,MATCH($U6,'Claims History'!$B$6:$B$15,0)),""),5)="Refer",LEFT(IFERROR(INDEX('Usage and Coverage'!$E$6:$E$20,MATCH($N6,'Usage and Coverage'!$C$6:$C$20,0)),""),5)="Refer"),"REFER","AUTO-BIND")))) -> REFER | CY6: =IFERROR($CO6/$CM6-1,"") -> 0 | CZ6: =IF($CY6="","",IF($CY6<'Technical Premium'!$C$19,"BEYOND AUTHORITY",IF($CY6>0.005,"Above technical",IF($CY6<-0.005,"BELOW technical","At technical")))) -> At technical | DA6: =IF($A6="","",IF($CX6="AUTO-BIND","",TRIM(IF($J6<'Technical Premium'!$C$18,"Below programme minimum agreed value. ","")&IF(N($AQ6)<'Technical Premium'!$C$19,"DISCOUNT AUTHORITY BREACH. ","")&IF(N($AQ6)>'Technical Premium'!$C$20,"Load authority breach. ","")&IF($J6>='Technical Premium'!$C$16,"Agreed value at or above auto-bind limit. ","")&IF(AND(ISNUMBER($CD6),$CD6>='Technical Premium'!$C$17),"Composite factor at cap. ","")&IF(AND(ISNUMBER($CD6),$CD6>2.5),"Composite factor above 2.50. ","")&IF(LEFT(IFERROR(INDEX('Driver Factors'!$D$6:$D$15,MATCH($R6,'Driver Factors'!$B$6:$B$15,0)),""),7)="DECLINE","DECLINE - driver age. ",IF(LEFT(IFERROR(INDEX('Driver Factors'!$D$6:$D$15,MATCH($R6,'Driver Factors'!$B$6:$B$15,0)),""),5)="Refer","Driver age band. ",""))&IF(LEFT(IFERROR(INDEX('Driver Factors'!$D$28:$D$36,MATCH($T6,'Driver Factors'!$B$28:$B$36,0)),""),7)="DECLINE","DECLINE - MVR. ",IF(LEFT(IFERROR(INDEX('Driver Factors'!$D$28:$D$36,MATCH($T6,'Driver Factors'!$B$28:$B$36,0)),""),5)="Refer","MVR record. ",""))&IF(LEFT(IFERROR(INDEX('Claims History'!$D$6:$D$15,MATCH($U6,'Claims History'!$B$6:$B$15,0)),""),7)="DECLINE","DECLINE - claims. ",IF(LEFT(IFERROR(INDEX('Claims History'!$D$6:$D$15,MATCH($U6,'Claims History'!$B$6:$B$15,0)),""),5)="Refer","Claims history. ",""))&IF(LEFT(IFERROR(INDEX('Usage and Coverage'!$E$6:$E$20,MATCH($N6,'Usage and Coverage'!$C$6:$C$20,0)),""),7)="DECLINE","DECLINE - usage class. ",IF(LEFT(IFERROR(INDEX('Usage and Coverage'!$E$6:$E$20,MATCH($N6,'Usage and Coverage'!$C$6:$C$20,0)),""),5)="Refer","Usage class. ",""))&IF($CX6="CHECK INPUTS","Incomplete inputs. ","")))) -> Agreed value at or above auto-bind limit. | DG6: =IF($A6="","",IF($CX6="DECLINE","NO - DECLINED",IF($CX6="CHECK INPUTS","NO - INCOMPLETE INPUTS",IF($CX6="AUTO-BIND","YES - within authority",IF(AND($DB6<>"",$DD6<>""),"YES - approved "&TEXT($DD6,"dd-mmm-yy"),"NO - AWAITING APPROVAL"))))) -> NO - AWAITING APPROVAL | DH6: =IF($A6="","",IF(OR($CX6="REFER",$CX6="DECLINE"),COUNTIF($CX$5:$CX6,"REFER")+COUNTIF($CX$5:$CX6,"DECLINE"),"")) -> 1
A7: V-0003 | B7: Sonoran Collection Trust | C7: 46143 | D7: 46631 | E7: 1965 | F7: Shelby | G7: Cobra 427 | H7: CSX3178 | I7: 07 - Post-War Classic (1946-1972) | J7: 1450000 | K7: Arizona | L7: 85253 | M7: Personal | N7: Club touring / rallies (non-timed) | O7: 1,000 - 2,500 | P7: Secure collection facility - climate controlled | Q7: GPS tracker w/ recovery service | R7: 55 - 64 | S7: 10 + years | T7: Clean - no violations 3 yrs | U7: No claims + 3 yrs prior collector policy | V7: 11 - 20 vehicles | W7: $25,000 | X7: Agreed Value + Appreciation clause | Y7: $2,000,000 CSL | Z7: Phoenix - Scottsdale, AZ | AA7: 1% of agreed value, minimum $5,000 | AQ7: -0.08 | AR7: =IF($A7="","",IFERROR(LEFT(TEXT(VALUE($L7),"00000"),3),"---")) -> 852 | AS7: =IF($A7="","",IF($AP7<>"",$AP7,IFERROR(INDEX('Cat Zone by ZIP'!$D$6:$D$856,MATCH($AR7,'Cat Zone by ZIP'!$B$6:$B$856,0)),IFERROR(INDEX('Cat Zone by ZIP'!$C$860:$C$910,MATCH($K7,'Cat Zone by ZIP'!$B$860:$B$910,0)),"NOT FOUND")))) -> Severe convective - hail / tornado (moderate) | AT7: =IF($A7="","",IF($AP7<>"","Override",IF(ISNUMBER(MATCH($AR7,'Cat Zone by ZIP'!$B$6:$B$856,0)),"ZIP-3","State default"))) -> ZIP-3 | AU7: =IF($A7="","",IFERROR(INDEX('Natural Catastrophe'!$D$6:$D$17,MATCH($AS7,'Natural Catastrophe'!$B$6:$B$17,0)),"?")) -> 1.5 | AV7: =IF($A7="","",IFERROR(INDEX('Natural Catastrophe'!$C$21:$C$26,MATCH($AA7,'Natural Catastrophe'!$B$21:$B$26,0)),"?")) -> 0.9 | AW7: =IF($A7="","",IFERROR(INDEX('Base Rates'!$C$4:$I$4,MATCH(MAX($J7,'Technical Premium'!$C$18),'Base Rates'!$C$3:$I$3,1)),"?")) -> $1.0M - $2.0M | AX7: =IF($A7="","",IFERROR(INDEX('Base Rates'!$C$5:$I$16,MATCH($I7,'Base Rates'!$B$5:$B$16,0),MATCH(MAX($J7,'Technical Premium'!$C$18),'Base Rates'!$C$3:$I$3,1)),"?")) -> 0.38 | AY7: =IF(ISNUMBER($AX7),$J7/100*$AX7,"") -> 5510 | AZ7: =IF($A7="","",IFERROR(INDEX('Make Factors'!$G$5:$G$69,MATCH($F7,'Make Factors'!$B$5:$B$69,0)),"?")) -> 1.187 | BA7: =IF($A7="","",IFERROR(INDEX('Driver Factors'!$C$6:$C$15,MATCH($R7,'Driver Factors'!$B$6:$B$15,0)),"?")) -> 1 | BB7: =IF($A7="","",IFERROR(INDEX('Driver Factors'!$C$19:$C$24,MATCH($S7,'Driver Factors'!$B$19:$B$24,0)),"?")) -> 0.95 | BC7: =IF($A7="","",IFERROR(INDEX('Driver Factors'!$C$28:$C$36,MATCH($T7,'Driver Factors'!$B$28:$B$36,0)),"?")) -> 1 | BD7: =IF($A7="","",IFERROR(INDEX('Claims History'!$C$6:$C$15,MATCH($U7,'Claims History'!$B$6:$B$15,0)),"?")) -> 0.85 | BE7: =IF($A7="","",IFERROR(INDEX('Territory Factors'!$E$6:$E$56,MATCH($K7,'Territory Factors'!$B$6:$B$56,0)),"?")) -> 1.1 | BF7: =IF($A7="","",IFERROR(INDEX('City Accident Ratings'!$G$6:$G$54,MATCH($Z7,'City Accident Ratings'!$B$6:$B$54,0)),"?")) -> 1.18 | BG7: =IF($A7="","",IFERROR(INDEX('Usage and Coverage'!$D$6:$D$20,MATCH($N7,'Usage and Coverage'!$C$6:$C$20,0)),"?")) -> 1.05 | BH7: =IF($A7="","",IFERROR(INDEX('Usage and Coverage'!$C$24:$C$30,MATCH($O7,'Usage and Coverage'!$B$24:$B$30,0)),"?")) -> 0.85 | BI7: =IF($A7="","",IFERROR(INDEX('Usage and Coverage'!$C$34:$C$40,MATCH($P7,'Usage and Coverage'!$B$34:$B$40,0)),"?")) -> 0.85 | BJ7: =IF($A7="","",IFERROR(INDEX('Usage and Coverage'!$C$44:$C$49,MATCH($Q7,'Usage and Coverage'!$B$44:$B$49,0)),"?")) -> 0.9 | BK7: =IF($A7="","",IFERROR(INDEX(Deductibles!$C$6:$I$15,MATCH($W7,Deductibles!$B$6:$B$15,0),MATCH(MAX($J7,'Technical Premium'!$C$18),'Base Rates'!$C$3:$I$3,1)),"?")) -> 0.87 | BL7: =IF($A7="","",IFERROR(INDEX('Usage and Coverage'!$C$63:$C$66,MATCH($X7,'Usage and Coverage'!$B$63:$B$66,0)),"?")) -> 1.06 | BM7: =IF($A7="","",IFERROR(INDEX('Usage and Coverage'!$C$70:$C$75,MATCH($V7,'Usage and Coverage'!$B$70:$B$75,0)),"?")) -> 0.82 | BN7: =IF($A7="","",IF($AB7="",1,IFERROR(INDEX(Deductibles!$C$48:$C$51,MATCH($AB7,Deductibles!$B$48:$B$51,0)),"?"))) -> 1 | BO7: =IF($A7="","",IF($AC7="",1,IFERROR(INDEX(Deductibles!$C$55:$C$57,MATCH($AC7,Deductibles!$B$55:$B$57,0)),"?"))) -> 1 | BP7: =IF($A7="","",IF($AD7="",1,IFERROR(INDEX(Deductibles!$C$61:$C$63,MATCH($AD7,Deductibles!$B$61:$B$63,0)),"?"))) -> 1 | BQ7: =IF($A7="","",IF($AE7="",1,IFERROR(INDEX(Deductibles!$C$67:$C$69,MATCH($AE7,Deductibles!$B$67:$B$69,0)),"?"))) -> 1 | BR7: =IF($A7="","",IF($AF7="",1,IFERROR(INDEX(Deductibles!$C$73:$C$74,MATCH($AF7,Deductibles!$B$73:$B$74,0)),"?"))) -> 1 | BS7: =IF($A7="","",IF($AG7="",1,IFERROR(INDEX('Sublimits and Parts'!$C$49:$C$52,MATCH($AG7,'Sublimits and Parts'!$B$49:$B$52,0)),"?"))) -> 1 | BT7: =IF($A7="","",IF($AH7="",1,IFERROR(INDEX('Sublimits and Parts'!$C$56:$C$60,MATCH($AH7,'Sublimits and Parts'!$B$56:$B$60,0)),"?"))) -> 1 | BU7: =IF($A7="","",IF($AI7="",1,IFERROR(INDEX('Sublimits and Parts'!$C$64:$C$67,MATCH($AI7,'Sublimits and Parts'!$B$64:$B$67,0)),"?"))) -> 1 | BV7: =IF($A7="","",IF($AJ7="",1,IFERROR(INDEX('Sublimits and Parts'!$C$71:$C$74,MATCH($AJ7,'Sublimits and Parts'!$B$71:$B$74,0)),"?"))) -> 1 | BW7: =IF($A7="","",IF($AK7="",1,IFERROR(INDEX('Sublimits and Parts'!$C$78:$C$80,MATCH($AK7,'Sublimits and Parts'!$B$78:$B$80,0)),"?"))) -> 1 | BX7: =IF($A7="","",IF($AL7="",1,IFERROR(INDEX('Sublimits and Parts'!$C$84:$C$87,MATCH($AL7,'Sublimits and Parts'!$B$84:$B$87,0)),"?"))) -> 1 | BY7: =IF($A7="","",IF($AM7="",1,IFERROR(INDEX('Sublimits and Parts'!$C$91:$C$94,MATCH($AM7,'Sublimits and Parts'!$B$91:$B$94,0)),"?"))) -> 1 | BZ7: =IF($A7="","",IF($AN7="",1,IFERROR(INDEX('Sublimits and Parts'!$C$98:$C$101,MATCH($AN7,'Sublimits and Parts'!$B$98:$B$101,0)),"?"))) -> 1 | CA7: =IF($A7="","",IF($AO7="",1,IFERROR(INDEX('Sublimits and Parts'!$C$105:$C$109,MATCH($AO7,'Sublimits and Parts'!$B$105:$B$109,0)),"?"))) -> 1 | CB7: =IF($A7="","",IF(SUMPRODUCT(--ISTEXT($AZ7:$BM7))>0,"?",PRODUCT($AZ7:$BM7))) -> 0.64235716 | CC7: =IF($A7="","",IF(SUMPRODUCT(--ISTEXT($BN7:$CA7))>0,"?",PRODUCT($BN7:$CA7))) -> 1 | CD7: =IF($A7="","",IF(OR($CB7="?",$CC7="?"),"?",MIN($CB7*$CC7,'Technical Premium'!$C$17))) -> 0.64235716 | CE7: =IF(ISNUMBER($CD7),$AY7*$CD7,"") -> 3539.388 | CF7: =IF($A7="","",IFERROR(INDEX('Territory Factors'!$F$6:$F$56,MATCH($K7,'Territory Factors'!$B$6:$B$56,0)),"?")) -> 520 | CG7: =IF($A7="","",IFERROR(INDEX('Usage and Coverage'!$C$79:$C$84,MATCH($Y7,'Usage and Coverage'!$B$79:$B$84,0)),"?")) -> 1.68 | CH7: =IFERROR(IF(ISNUMBER($CD7),$CF7*$CG7*MIN($BG7*$BA7*$BC7*$BD7*$BH7*$BF7,'Technical Premium'!$C$17),""),"") -> 782.02706 | CI7: =IFERROR($CE7+$CH7,"") -> 4321.415 | CJ7: =IFERROR($CI7*(1+'Technical Premium'!$C$5)*(1+'Technical Premium'!$C$6),"") -> 4900.4847 | CK7: =IFERROR($CE7*INDEX('Territory Factors'!$G$6:$G$56,MATCH($K7,'Territory Factors'!$B$6:$B$56,0))*$AU7*$AV7,"") -> 215.01782 | CL7: =IFERROR(($CJ7+$CK7)*(1+'Technical Premium'!$C$7),"") -> 5499.1652 | CM7: =IFERROR($CL7/'Technical Premium'!$C$13,"") -> 9908.4057 | CN7: =IFERROR($CM7/$J7*100,"") -> 0.68333832 | CO7: =IFERROR($CM7*(1+N($AQ7)),"") -> 9115.7332 | CP7: =IFERROR($CO7/$J7*100,"") -> 0.62867126 | CQ7: =IFERROR($CP7/$CN7,"") -> 0.92 | CR7: =IF(ISNUMBER($CM7),'Technical Premium'!$C$14+IF($J7>=1000000,'Technical Premium'!$C$15,0),"") -> 600 | CS7: =IFERROR(($CO7+$CR7)*(INDEX('Territory Factors'!$K$6:$K$56,MATCH($K7,'Territory Factors'!$B$6:$B$56,0))+'Commission Structure'!$C$21),"") -> 308.96032 | CT7: =IFERROR($CO7+$CR7+$CS7,"") -> 10024.694 | CU7: =IFERROR($CO7*('Commission Structure'!$C$6+'Commission Structure'!$C$7),"") -> 1595.2533 | CV7: =IFERROR($CO7*'Commission Structure'!$C$5-$CU7,"") -> 911.57332 | CW7: =IFERROR($CO7*(1-'Commission Structure'!$C$5),"") -> 6608.9066 | CX7: =IF($A7="","",IF(OR($CB7="?",$CC7="?",NOT(ISNUMBER($AU7))),"CHECK INPUTS",IF(OR($J7<'Technical Premium'!$C$18,LEFT(IFERROR(INDEX('Driver Factors'!$D$6:$D$15,MATCH($R7,'Driver Factors'!$B$6:$B$15,0)),""),7)="DECLINE",LEFT(IFERROR(INDEX('Driver Factors'!$D$28:$D$36,MATCH($T7,'Driver Factors'!$B$28:$B$36,0)),""),7)="DECLINE",LEFT(IFERROR(INDEX('Claims History'!$D$6:$D$15,MATCH($U7,'Claims History'!$B$6:$B$15,0)),""),7)="DECLINE",LEFT(IFERROR(INDEX('Usage and Coverage'!$E$6:$E$20,MATCH($N7,'Usage and Coverage'!$C$6:$C$20,0)),""),7)="DECLINE"),"DECLINE",IF(OR($CD7>2.5,$CD7>='Technical Premium'!$C$17,$J7>='Technical Premium'!$C$16,N($AQ7)<'Technical Premium'!$C$19,N($AQ7)>'Technical Premium'!$C$20,LEFT(IFERROR(INDEX('Driver Factors'!$D$6:$D$15,MATCH($R7,'Driver Factors'!$B$6:$B$15,0)),""),5)="Refer",LEFT(IFERROR(INDEX('Driver Factors'!$D$28:$D$36,MATCH($T7,'Driver Factors'!$B$28:$B$36,0)),""),5)="Refer",LEFT(IFERROR(INDEX('Claims History'!$D$6:$D$15,MATCH($U7,'Claims History'!$B$6:$B$15,0)),""),5)="Refer",LEFT(IFERROR(INDEX('Usage and Coverage'!$E$6:$E$20,MATCH($N7,'Usage and Coverage'!$C$6:$C$20,0)),""),5)="Refer"),"REFER","AUTO-BIND")))) -> AUTO-BIND | CY7: =IFERROR($CO7/$CM7-1,"") -> -0.08 | CZ7: =IF($CY7="","",IF($CY7<'Technical Premium'!$C$19,"BEYOND AUTHORITY",IF($CY7>0.005,"Above technical",IF($CY7<-0.005,"BELOW technical","At technical")))) -> BELOW technical | DA7: =IF($A7="","",IF($CX7="AUTO-BIND","",TRIM(IF($J7<'Technical Premium'!$C$18,"Below programme minimum agreed value. ","")&IF(N($AQ7)<'Technical Premium'!$C$19,"DISCOUNT AUTHORITY BREACH. ","")&IF(N($AQ7)>'Technical Premium'!$C$20,"Load authority breach. ","")&IF($J7>='Technical Premium'!$C$16,"Agreed value at or above auto-bind limit. ","")&IF(AND(ISNUMBER($CD7),$CD7>='Technical Premium'!$C$17),"Composite factor at cap. ","")&IF(AND(ISNUMBER($CD7),$CD7>2.5),"Composite factor above 2.50. ","")&IF(LEFT(IFERROR(INDEX('Driver Factors'!$D$6:$D$15,MATCH($R7,'Driver Factors'!$B$6:$B$15,0)),""),7)="DECLINE","DECLINE - driver age. ",IF(LEFT(IFERROR(INDEX('Driver Factors'!$D$6:$D$15,MATCH($R7,'Driver Factors'!$B$6:$B$15,0)),""),5)="Refer","Driver age band. ",""))&IF(LEFT(IFERROR(INDEX('Driver Factors'!$D$28:$D$36,MATCH($T7,'Driver Factors'!$B$28:$B$36,0)),""),7)="DECLINE","DECLINE - MVR. ",IF(LEFT(IFERROR(INDEX('Driver Factors'!$D$28:$D$36,MATCH($T7,'Driver Factors'!$B$28:$B$36,0)),""),5)="Refer","MVR record. ",""))&IF(LEFT(IFERROR(INDEX('Claims History'!$D$6:$D$15,MATCH($U7,'Claims History'!$B$6:$B$15,0)),""),7)="DECLINE","DECLINE - claims. ",IF(LEFT(IFERROR(INDEX('Claims History'!$D$6:$D$15,MATCH($U7,'Claims History'!$B$6:$B$15,0)),""),5)="Refer","Claims history. ",""))&IF(LEFT(IFERROR(INDEX('Usage and Coverage'!$E$6:$E$20,MATCH($N7,'Usage and Coverage'!$C$6:$C$20,0)),""),7)="DECLINE","DECLINE - usage class. ",IF(LEFT(IFERROR(INDEX('Usage and Coverage'!$E$6:$E$20,MATCH($N7,'Usage and Coverage'!$C$6:$C$20,0)),""),5)="Refer","Usage class. ",""))&IF($CX7="CHECK INPUTS","Incomplete inputs. ","")))) | DG7: =IF($A7="","",IF($CX7="DECLINE","NO - DECLINED",IF($CX7="CHECK INPUTS","NO - INCOMPLETE INPUTS",IF($CX7="AUTO-BIND","YES - within authority",IF(AND($DB7<>"",$DD7<>""),"YES - approved "&TEXT($DD7,"dd-mmm-yy"),"NO - AWAITING APPROVAL"))))) -> YES - within authority | DH7: =IF($A7="","",IF(OR($CX7="REFER",$CX7="DECLINE"),COUNTIF($CX$5:$CX7,"REFER")+COUNTIF($CX$5:$CX7,"DECLINE"),""))
