Workbook

Sheet README
A1: Submission Data Workbook — Full Funnel (all submissions)
A2: Source: canonical_dataset.json (ADR 0045), sha256 faa3c9b7f4d50478... — verified against canonical_manifest.json. All rows derive read-only from that frozen artifact; no new numbers generated. Styling follows the MGA Program Master conventions (Arial; navy title banners; blue section headers; semantic tab colours; 1-dp percentages).
A8: Source artifact | C8: sample-data/canonical/canonical_dataset.json
A9: Verified sha256 | C9: faa3c9b7f4d50478223133535cb16904b63533f656f3a522176ef0d756814095
A10: Manifest ADR | C10: 0045
A11: Generated (report date) | C11: 2026-08-30 01:07
A12: Read-only note | C12: Rendered read-only from the frozen canonical artifact; no DB, no re-rating.
A14: WHAT IS INCLUDED
A15: Population | C15: EVERY submission across the full 12-month timeline — one row each.
C16: Superset of the 12 monthly BDX (which are the bound-only subset).
A17: Total submissions | C17: 10,500
A18: Bound | C18: 7,655
A19: Declined | C19: 2,056
A20: Referred | C20: 789
A22: DISPOSITION DEFINITIONS
A23: Bound | C23: Application bound to a policy; carries policy number, effective date and GWP.
A24: Declined | C24: Application declined at underwriting (all: 3+ at-fault claims / 5 yrs). No policy.
A25: Referred | C25: Referred to an underwriter (prior non-renewal, large/multi claims, theft/total). No policy.
A27: COLUMN / FIELD NOTES
A28: Policy / Submission Ref | C28: Bound rows: policy_number (CANON-YYYYMM-######). Non-bound: submission_id (UUID),
C29: as the artifact holds no policy number for non-bound submissions.
A30: Submission Month | C30: Calendar month of submitted_at (== month_index label; ties to monthly_aggregates).
A31: Effective Date | C31: policy.effective_date — BOUND rows only; blank for non-bound (no policy).
A32: Vehicle Class | C32: vehicle_category -> Base Rates 'NN - Name' label (display only; does not drive premium).
A33: Indicative / Base Premium | C33: quote.base_premium — present for ALL submissions (the indicative technical premium).
A34: Gross Written Premium | C34: policy.bound_premium — BOUND rows only; BLANK (not 0) for non-bound.
A35: Decline / Referral Reason | C35: loss_run.pattern -> claims-history label; populated for declined/referred only.
A36: Garaging State | C36: garaging_state expanded to full state name.
A38: RECONCILIATION
A39: Bound count | C39: 7,655 (== summary.binds)
A40: Sum GWP bound | C40: $71,301,212.64 (== summary.gwp_bound == sum of the 12 BDX)

Sheet Submissions
A1: Submissions — Full Funnel (bound + declined + referred)
A2: One row per submission, all 12 months. Read-only from canonical_dataset.json (sha256 faa3c9b7f4d50478...). GWP is blank for non-bound rows.
A3: Policy / Submission Ref | B3: Submission Month | C3: Effective Date | D3: Disposition | E3: Named Insured | F3: Vehicle Year | G3: Make | H3: Model | I3: VIN | J3: Vehicle Class | K3: Agreed Value | L3: Garaging State | M3: Indicative / Base Premium | N3: Gross Written Premium | O3: Decline / Referral Reason
A4: 0209dcee-1aeb-5d41-8483-a7fbe8bb228f | B4: 2025-08 | D4: Declined | E4: Emiliano Larsson | F4: 1990 | G4: Lamborghini | H4: Huracan EVO | I4: 0FMJSXZ5U9JZV4G52 | J4: 03 - Supercar | K4: 670000 | L4: New York | M4: 15372.08 | O4: 3 + at-fault claims - 5 yrs
A5: 022e5d96-b7b9-557a-ab6f-6486a3159bcf | B5: 2025-08 | D5: Declined | E5: Thaddeus Harrington | F5: 1964 | G5: Bentley | H5: Continental GT | I5: GWJ99G3W358VCSXL2 | J5: 02 - Sports / GT | K5: 605000 | L5: Washington | M5: 7123.02 | O5: 3 + at-fault claims - 5 yrs
A6: 039e0ea1-44cf-5cac-9c79-c6e7e4482200 | B6: 2025-08 | D6: Declined | E6: Callum Kingsford | F6: 1965 | G6: Ferrari | H6: 275 GTB/4 | I6: ZZJ01UZUTXB7PY7J0 | J6: 07 - Post-War Classic (1946-1972) | K6: 325000 | L6: Florida | M6: 4179.62 | O6: 3 + at-fault claims - 5 yrs
A7: 03cfbd8e-04c1-5cd6-b935-fd5bb1aa6180 | B7: 2025-08 | D7: Declined | E7: Lorenzo Bellandi | F7: 2014 | G7: Ferrari | H7: 296 GTB | I7: TBG77XXHLPNA9ZCXF | J7: 03 - Supercar | K7: 1440000 | L7: Delaware | M7: 27169.81 | O7: 3 + at-fault claims - 5 yrs
A8: 04af9c0a-37da-5979-a76d-b4aefa4866b9 | B8: 2025-08 | D8: Declined | E8: Desmond Thistlewood | F8: 1973 | G8: Ringbrothers | H8: Mustang | I8: D2EXE4KUT9DHF2EVY | J8: 11 - Restomod / Coachbuilt / Bespoke | K8: 1110000 | L8: Minnesota | M8: 18798.79 | O8: 3 + at-fault claims - 5 yrs
A9: 062631de-bde4-5f97-82cc-7614dbf409a7 | B9: 2025-08 | D9: Declined | E9: Thaddeus Thistlewood | F9: 1955 | G9: Bentley | H9: Continental GT | I9: 48EGH6ZRWL215Z7XL | J9: 02 - Sports / GT | K9: 190000 | L9: Nebraska | M9: 4287.55 | O9: 3 + at-fault claims - 5 yrs
A10: 06406892-e99b-5a78-b4da-08f31a0bde06 | B10: 2025-08 | D10: Declined | E10: Anouk Whitlock | F10: 2015 | G10: Jaguar | H10: E-Type Series 1 | I10: KPR4VCD0YMWRNCMS3 | J10: 07 - Post-War Classic (1946-1972) | K10: 1230000 | L10: Michigan | M10: 13669.25 | O10: 3 + at-fault claims - 5 yrs
A11: 06d2d4f5-583d-5802-96b2-0bac5d867ad5 | B11: 2025-08 | D11: Referred | E11: Horace Farkas | F11: 1970 | G11: Jaguar | H11: E-Type Series 1 | I11: TH9CNKCBTS36YSPNK | J11: 07 - Post-War Classic (1946-1972) | K11: 770000 | L11: Minnesota | M11: 8246.26 | O11: 1 at-fault claim over $100k
A12: 080fff76-0832-5a68-aa90-243b016faaed | B12: 2025-08 | D12: Declined | E12: Callum Rourke | F12: 1969 | G12: Mercedes-Benz | H12: AMG GT | I12: UMMN806U88UK4PS5V | J12: 02 - Sports / GT | K12: 1540000 | L12: North Carolina | M12: 18378.3 | O12: 3 + at-fault claims - 5 yrs
A13: 0928084a-2f6e-520b-bf31-66db066cf608 | B13: 2025-08 | D13: Declined | E13: Thaddeus Vasquez | F13: 2021 | G13: Bentley | H13: Continental GT | I13: 7JY3717ZKLVU0URG1 | J13: 02 - Sports / GT | K13: 440000 | L13: Pennsylvania | M13: 6226.42 | O13: 3 + at-fault claims - 5 yrs
A14: 098beeaf-6177-5d28-9eb6-a126e8778286 | B14: 2025-08 | D14: Referred | E14: Desmond Thistlewood | F14: 2016 | G14: Ferrari | H14: 275 GTB/4 | I14: 82BSYHFFBLCGVBUL8 | J14: 07 - Post-War Classic (1946-1972) | K14: 915000 | L14: Washington | M14: 7126.64 | O14: Prior carrier non-renewal / cancellation
A15: 09d08907-4ab6-5a48-a68d-ec10085f1051 | B15: 2025-08 | D15: Declined | E15: Beatrix Underwood | F15: 2015 | G15: Maserati | H15: GranTurismo | I15: SRDCJX0J25VA1M46Y | J15: 02 - Sports / GT | K15: 265000 | L15: Georgia | M15: 4200 | O15: 3 + at-fault claims - 5 yrs
... A126: 9dff0b74-d913-5149-a345-2127f90b385d | B126: 2025-08 | D126: Declined | E126: Noor Blackwood | F126: 1986 | G126: Mercedes-Benz | H126: AMG GT | I126: 646WJLYT5YDGHUTKM | J126: 02 - Sports / GT | K126: 410000 | L126: New York | M126: 7426.42 | O126: 3 + at-fault claims - 5 yrs
A127: CANON-202508-000003 | B127: 2025-08 | C127: 45889 | D127: Bound | E127: Everett Delacroix | F127: 1984 | G127: Porsche | H127: 911 Turbo S | I127: H7E6FX0TRJ83PRTRW | J127: 02 - Sports / GT | K127: 190000 | L127: Kansas | M127: 3199.17 | N127: 3199.17
A128: CANON-202508-000004 | B128: 2025-08 | C128: 45885 | D128: Bound | E128: Desmond Underwood | F128: 1957 | G128: Ferrari | H128: 296 GTB | I128: 6NCW36EALANFZMAC9 | J128: 03 - Supercar | K128: 570000 | L128: Nevada | M128: 11953.87 | N128: 11953.87
A129: CANON-202508-000008 | B129: 2025-08 | C129: 45879 | D129: Bound | E129: Callum Rourke | F129: 1998 | G129: Ferrari | H129: 296 GTB | I129: HA9H172MS7HR73NDT | J129: 03 - Supercar | K129: 750000 | L129: Alabama | M129: 17073.11 | N129: 17073.11
A130: CANON-202508-000009 | B130: 2025-08 | C130: 45870 | D130: Bound | E130: Ottilie Vandermeer | F130: 2020 | G130: Ferrari | H130: 296 GTB | I130: M4PU85LNXR94D371W | J130: 03 - Supercar | K130: 605000 | L130: New Mexico | M130: 13880.75 | N130: 13880.75
A131: CANON-202508-000011 | B131: 2025-08 | C131: 45874 | D131: Bound | E131: Desmond Thistlewood | F131: 2004 | G131: Ferrari | H131: 296 GTB | I131: YX2B9J4X9TVWAE128 | J131: 03 - Supercar | K131: 1950000 | L131: Ohio | M131: 40913.21 | N131: 40913.21
A132: CANON-202508-000012 | B132: 2025-08 | C132: 45899 | D132: Bound | E132: Callum Thistlewood | F132: 2022 | G132: Maserati | H132: GranTurismo | I132: 1Y7NEJZ5550ZB203F | J132: 02 - Sports / GT | K132: 1415000 | L132: California | M132: 19823.35 | N132: 19823.35
A133: CANON-202508-000013 | B133: 2025-08 | C133: 45884 | D133: Bound | E133: Leopold Fairweather | F133: 1959 | G133: Aston Martin | H133: DB12 | I133: JL6LW9DCRZLFC8NWH | J133: 02 - Sports / GT | K133: 380000 | L133: New York | M133: 6883.02 | N133: 6883.02
A134: CANON-202508-000014 | B134: 2025-08 | C134: 45876 | D134: Bound | E134: Callum Montoya | F134: 1960 | G134: Ferrari | H134: 296 GTB | I134: 2H4D2CA7CMSBJA924 | J134: 03 - Supercar | K134: 1565000 | L134: Nevada | M134: 27638.49 | N134: 27638.49
A135: CANON-202508-000018 | B135: 2025-08 | C135: 45884 | D135: Bound | E135: Sunniva Blackwood | F135: 1999 | G135: Mercedes-Benz | H135: AMG GT | I135: FBX60A7UBL8LLV0SF | J135: 02 - Sports / GT | K135: 520000 | L135: Illinois | M135: 8673.21 | N135: 8673.21
A136: CANON-202508-000020 | B136: 2025-08 | C136: 45884 | D136: Bound | E136: Anouk Bellandi | F136: 2000 | G136: McLaren | H136: 750S | I136: 1SN1N49RJX4KMEA92 | J136: 03 - Supercar | K136: 1085000 | L136: North Carolina | M136: 18833.96 | N136: 18833.96
A137: CANON-202508-000021 | B137: 2025-08 | C137: 45896 | D137: Bound | E137: Beatrix Castellanos | F137: 1962 | G137: McLaren | H137: 750S | I137: VK1RJACR57CWNKWBP | J137: 03 - Supercar | K137: 360000 | L137: Alabama | M137: 9920.38 | N137: 9920.38
A138: CANON-202508-000023 | B138: 2025-08 | C138: 45882 | D138: Bound | E138: Thaddeus Chattopadhyay | F138: 1975 | G138: Mercedes-Benz | H138: AMG GT | I138: 9D17BP4D2T0DXC4D4 | J138: 02 - Sports / GT | K138: 495000 | L138: Delaware | M138: 8755.9 | N138: 8755.9
... A632: CANON-202508-000703 | B632: 2025-08 | C632: 45877 | D632: Bound | E632: Mireille Chattopadhyay | F632: 2021 | G632: Aston Martin | H632: DB12 | I632: 7XLR1Z4ZKXMMWMK2D | J632: 02 - Sports / GT | K632: 315000 | L632: Tennessee | M632: 4368.4 | N632: 4368.4
A633: a144440e-e492-5304-9a12-8912ab24228f | B633: 2025-08 | D633: Referred | E633: Lorenzo Fairweather | F633: 1998 | G633: Aston Martin | H633: DB5 | I633: 9RBY53HFYT0T4PNUT | J633: 07 - Post-War Classic (1946-1972) | K633: 935000 | L633: New Jersey | M633: 6903.12 | O633: 1 theft / total loss claim
A634: a2e072dc-2f6c-5fff-8749-6546b6e74393 | B634: 2025-08 | D634: Declined | E634: Sunniva Fairweather | F634: 2004 | G634: BMW | H634: M8 Competition | I634: D8SEV2JE16ZFC7VA3 | J634: 02 - Sports / GT | K634: 940000 | L634: Nebraska | M634: 14986.79 | O634: 3 + at-fault claims - 5 yrs
A635: a4bbcf9a-f11c-54e3-af4c-b40802131152 | B635: 2025-08 | D635: Declined | E635: Emiliano Harrington | F635: 2017 | G635: Bentley | H635: Continental GT | I635: LH3NRH3UJM4E3ADAE | J635: 02 - Sports / GT | K635: 740000 | L635: California | M635: 12251.89 | O635: 3 + at-fault claims - 5 yrs
A636: a5e19bea-5bca-55a9-9a12-2ad805270ca6 | B636: 2025-08 | D636: Referred | E636: Ottilie Harrington | F636: 1975 | G636: Aston Martin | H636: DB12 | I636: A4SJK7R0N43SXHMR0 | J636: 02 - Sports / GT | K636: 795000 | L636: Massachusetts | M636: 12187.5 | O636: 1 at-fault claim over $100k
A637: a62bbfa7-7367-5a01-804d-2f3cda290ba3 | B637: 2025-08 | D637: Declined | E637: Thaddeus Farkas | F637: 1971 | G637: Mercedes-Benz | H637: AMG GT | I637: RCH6P9N6AZ044VZU5 | J637: 02 - Sports / GT | K637: 1325000 | L637: Ohio | M637: 19112.5 | O637: 3 + at-fault claims - 5 yrs
A638: a70818ad-9bf5-54f9-8a40-7d4ce3b35a91 | B638: 2025-08 | D638: Referred | E638: Ingrid Okonkwo | F638: 1959 | G638: Aston Martin | H638: DB12 | I638: VDDDB824PUMHTXG3N | J638: 02 - Sports / GT | K638: 1190000 | L638: Arkansas | M638: 17041.7 | O638: 1 theft / total loss claim
A639: ac0376af-7ad6-5a3b-8df0-47039fc37b72 | B639: 2025-08 | D639: Declined | E639: Priya Fairweather | F639: 1993 | G639: Aston Martin | H639: DB5 | I639: S62P92JJ1HM0GRU4U | J639: 07 - Post-War Classic (1946-1972) | K639: 600000 | L639: Michigan | M639: 7545.28 | O639: 3 + at-fault claims - 5 yrs
A640: acc18e3d-5394-5016-bbc9-f8d390041e8e | B640: 2025-08 | D640: Declined | E640: Ingrid Rourke | F640: 1973 | G640: Porsche | H640: 911 Turbo S | I640: YJHTCWKPX8C7DASL5 | J640: 02 - Sports / GT | K640: 895000 | L640: California | M640: 14818.16 | O640: 3 + at-fault claims - 5 yrs
A641: acd62f01-73e9-558b-811e-af8a2b93793b | B641: 2025-08 | D641: Declined | E641: Noor Bellandi | F641: 2007 | G641: Porsche | H641: 911 Turbo S | I641: EVSMT9K71HE02AD3D | J641: 02 - Sports / GT | K641: 555000 | L641: Colorado | M641: 7487.26 | O641: 3 + at-fault claims - 5 yrs
A642: afd119ce-28ce-5216-af8c-c293c05b503d | B642: 2025-08 | D642: Referred | E642: Wilhelmina Nakashima | F642: 1966 | G642: Ferrari | H642: 296 GTB | I642: MZZPAVX8EUC03S4UP | J642: 03 - Supercar | K642: 600000 | L642: Nevada | M642: 12583.02 | O642: Prior carrier non-renewal / cancellation
A643: b0a249e7-5051-5889-88b2-36828a63c6f1 | B643: 2025-08 | D643: Declined | E643: Cassius Underwood | F643: 2017 | G643: Jaguar | H643: E-Type Series 1 | I643: UNXF98WLUMRRYU3YC | J643: 07 - Post-War Classic (1946-1972) | K643: 255000 | L643: New Jersey | M643: 2101.58 | O643: 3 + at-fault claims - 5 yrs
...

Sheet Summary
A1: Summary — Reconciliation to the canonical artifact
A2: Totals computed with COUNTIFS/SUMIFS over the Submissions sheet (not hardcoded).
A4: Funnel totals
A5: Total submissions | B5: =COUNTA('Submissions'!$A$4:$A$10503)
A6: Bound | B6: =COUNTIF('Submissions'!$D$4:$D$10503,"Bound")
A7: Declined | B7: =COUNTIF('Submissions'!$D$4:$D$10503,"Declined")
A8: Referred | B8: =COUNTIF('Submissions'!$D$4:$D$10503,"Referred")
A9: Bind ratio (bound / total) | B9: =COUNTIF('Submissions'!$D$4:$D$10503,"Bound")/COUNTA('Submissions'!$A$4:$A$10503)
A10: Sum GWP bound | B10: =SUM('Submissions'!$N$4:$N$10503)
A11: artifact summary.gwp_bound | B11: 71301213
A13: By submission month
A14: Month | B14: Submissions | C14: Bound | D14: GWP bound
A15: 2025-08 | B15: =COUNTIF('Submissions'!$B$4:$B$10503,"2025-08") | C15: =COUNTIFS('Submissions'!$B$4:$B$10503,"2025-08",'Submissions'!$D$4:$D$10503,"Bound") | D15: =SUMIFS('Submissions'!$N$4:$N$10503,'Submissions'!$B$4:$B$10503,"2025-08")
A16: 2025-09 | B16: =COUNTIF('Submissions'!$B$4:$B$10503,"2025-09") | C16: =COUNTIFS('Submissions'!$B$4:$B$10503,"2025-09",'Submissions'!$D$4:$D$10503,"Bound") | D16: =SUMIFS('Submissions'!$N$4:$N$10503,'Submissions'!$B$4:$B$10503,"2025-09")
A17: 2025-10 | B17: =COUNTIF('Submissions'!$B$4:$B$10503,"2025-10") | C17: =COUNTIFS('Submissions'!$B$4:$B$10503,"2025-10",'Submissions'!$D$4:$D$10503,"Bound") | D17: =SUMIFS('Submissions'!$N$4:$N$10503,'Submissions'!$B$4:$B$10503,"2025-10")
A18: 2025-11 | B18: =COUNTIF('Submissions'!$B$4:$B$10503,"2025-11") | C18: =COUNTIFS('Submissions'!$B$4:$B$10503,"2025-11",'Submissions'!$D$4:$D$10503,"Bound") | D18: =SUMIFS('Submissions'!$N$4:$N$10503,'Submissions'!$B$4:$B$10503,"2025-11")
A19: 2025-12 | B19: =COUNTIF('Submissions'!$B$4:$B$10503,"2025-12") | C19: =COUNTIFS('Submissions'!$B$4:$B$10503,"2025-12",'Submissions'!$D$4:$D$10503,"Bound") | D19: =SUMIFS('Submissions'!$N$4:$N$10503,'Submissions'!$B$4:$B$10503,"2025-12")
A20: 2026-01 | B20: =COUNTIF('Submissions'!$B$4:$B$10503,"2026-01") | C20: =COUNTIFS('Submissions'!$B$4:$B$10503,"2026-01",'Submissions'!$D$4:$D$10503,"Bound") | D20: =SUMIFS('Submissions'!$N$4:$N$10503,'Submissions'!$B$4:$B$10503,"2026-01")
A21: 2026-02 | B21: =COUNTIF('Submissions'!$B$4:$B$10503,"2026-02") | C21: =COUNTIFS('Submissions'!$B$4:$B$10503,"2026-02",'Submissions'!$D$4:$D$10503,"Bound") | D21: =SUMIFS('Submissions'!$N$4:$N$10503,'Submissions'!$B$4:$B$10503,"2026-02")
A22: 2026-03 | B22: =COUNTIF('Submissions'!$B$4:$B$10503,"2026-03") | C22: =COUNTIFS('Submissions'!$B$4:$B$10503,"2026-03",'Submissions'!$D$4:$D$10503,"Bound") | D22: =SUMIFS('Submissions'!$N$4:$N$10503,'Submissions'!$B$4:$B$10503,"2026-03")
A23: 2026-04 | B23: =COUNTIF('Submissions'!$B$4:$B$10503,"2026-04") | C23: =COUNTIFS('Submissions'!$B$4:$B$10503,"2026-04",'Submissions'!$D$4:$D$10503,"Bound") | D23: =SUMIFS('Submissions'!$N$4:$N$10503,'Submissions'!$B$4:$B$10503,"2026-04")
A24: 2026-05 | B24: =COUNTIF('Submissions'!$B$4:$B$10503,"2026-05") | C24: =COUNTIFS('Submissions'!$B$4:$B$10503,"2026-05",'Submissions'!$D$4:$D$10503,"Bound") | D24: =SUMIFS('Submissions'!$N$4:$N$10503,'Submissions'!$B$4:$B$10503,"2026-05")
A25: 2026-06 | B25: =COUNTIF('Submissions'!$B$4:$B$10503,"2026-06") | C25: =COUNTIFS('Submissions'!$B$4:$B$10503,"2026-06",'Submissions'!$D$4:$D$10503,"Bound") | D25: =SUMIFS('Submissions'!$N$4:$N$10503,'Submissions'!$B$4:$B$10503,"2026-06")
A26: 2026-07 | B26: =COUNTIF('Submissions'!$B$4:$B$10503,"2026-07") | C26: =COUNTIFS('Submissions'!$B$4:$B$10503,"2026-07",'Submissions'!$D$4:$D$10503,"Bound") | D26: =SUMIFS('Submissions'!$N$4:$N$10503,'Submissions'!$B$4:$B$10503,"2026-07")
A27: Total | B27: =SUM(B15:B26) | C27: =SUM(C15:C26) | D27: =SUM(D15:D26)
